Workbook
Name HERBICIDA: LISTA!$B$2:$B$1000
Name FUNGICIDA: LISTA!$A$2:$A$1000
Name TS: LISTA!$D$2:$D$1000
Name TL01_IMPRESSAO: 'TL01'!$A$1:$L$226
Name CORRETIVOS: LISTA!$I$2:$I$1000
Name FERTILIZANTES: LISTA!$H$2:$H$1000
Name INSETICIDA: LISTA!$C$2:$C$1000
Name SEMENTE: LISTA!$F$2:$F$1000

Sheet LISTA
A1: FUNGICIDA | B1: HERBICIDA | C1: INSETICIDA | D1: TS | E1: BIOLÓGICOS | F1: SEMENTE | G1: ADJUVANTE | H1: FERTILIZANTES | I1: CORRETIVOS | J1: NUTRIÇÃO | K1: MÁQUINAS | L1: EMPEENDIMENTO | M1: ÁREAS | N1: HECTARES
A2: =IFERROR(__xludf.DUMMYFUNCTION("UNIQUE(FILTER('PORTIFÓLIO'!C:C, 'PORTIFÓLIO'!B:B=""FUNGICIDA""))"),"ACROSS") -> ACROSS | B2: =IFERROR(__xludf.DUMMYFUNCTION("UNIQUE(FILTER('PORTIFÓLIO'!C:C, 'PORTIFÓLIO'!B:B=""HERBICIDA""))"),"AMINOL 806") -> AMINOL 806 | C2: =IFERROR(__xludf.DUMMYFUNCTION("UNIQUE(FILTER('PORTIFÓLIO'!C:C, 'PORTIFÓLIO'!B:B=""INSETICIDA""))"),"GALIL SC") -> GALIL SC | D2: =IFERROR(__xludf.DUMMYFUNCTION("UNIQUE(FILTER('PORTIFÓLIO'!C:C, 'PORTIFÓLIO'!B:B=""TS""))"),"ENDOFUSE") -> ENDOFUSE | E2: =IFERROR(__xludf.DUMMYFUNCTION("UNIQUE(FILTER('PORTIFÓLIO'!C:C, 'PORTIFÓLIO'!B:B=""biológicos""))"),"UTRISHA N") -> UTRISHA N | F2: =IFERROR(__xludf.DUMMYFUNCTION("UNIQUE(FILTER('PORTIFÓLIO'!C:C, 'PORTIFÓLIO'!B:B=""SEMENTE""))"),"FEIJÃO") -> FEIJÃO | G2: =IFERROR(__xludf.DUMMYFUNCTION("UNIQUE(FILTER('PORTIFÓLIO'!C:C, 'PORTIFÓLIO'!B:B=""ADJUVANTE""))"),"RUMBA") -> RUMBA | H2: =IFERROR(__xludf.DUMMYFUNCTION("UNIQUE(FILTER('PORTIFÓLIO'!C:C, 'PORTIFÓLIO'!B:B=""fertilizantes""))"),"I-ACTIVE") -> I-ACTIVE | I2: =IFERROR(__xludf.DUMMYFUNCTION("UNIQUE(FILTER('PORTIFÓLIO'!C:C, 'PORTIFÓLIO'!B:B=""corretivos""))"),"CALCÁRIO DOLOMITICO") -> CALCÁRIO DOLOMITICO | J2: =IFERROR(__xludf.DUMMYFUNCTION("UNIQUE(FILTER('PORTIFÓLIO'!C:C, 'PORTIFÓLIO'!B:B=""NUTRIÇÃO""))"),"RADIFARM") -> RADIFARM | K2: =IFERROR(__xludf.DUMMYFUNCTION("UNIQUE(FILTER('PORTIFÓLIO'!C:C, 'PORTIFÓLIO'!B:B=""MÁQUINAS""))"),"CASE STEIGER 420 + HORSCH MAESTRO DUO 36.50") -> CASE STEIGER 420 + HORSCH MAESTRO DUO 36.50 | L2: FA-SOJA SEQUEIRO-26/27 | M2: ÁREA 1 | N2: 273
A3: =IFERROR(__xludf.DUMMYFUNCTION("""COMPUTED_VALUE"""),"AZIMUT") -> AZIMUT | B3: =IFERROR(__xludf.DUMMYFUNCTION("""COMPUTED_VALUE"""),"APRESA") -> APRESA | C3: =IFERROR(__xludf.DUMMYFUNCTION("""COMPUTED_VALUE"""),"MAGNUM") -> MAGNUM | D3: =IFERROR(__xludf.DUMMYFUNCTION("""COMPUTED_VALUE"""),"ENDOMAXX") -> ENDOMAXX | E3: =IFERROR(__xludf.DUMMYFUNCTION("""COMPUTED_VALUE"""),"PRESENCE FULL") -> PRESENCE FULL | F3: =IFERROR(__xludf.DUMMYFUNCTION("""COMPUTED_VALUE"""),"SEMENTE TRIGO") -> SEMENTE TRIGO | G3: =IFERROR(__xludf.DUMMYFUNCTION("""COMPUTED_VALUE"""),"ASSIST") -> ASSIST | H3: =IFERROR(__xludf.DUMMYFUNCTION("""COMPUTED_VALUE"""),"MAP") -> MAP | I3: =IFERROR(__xludf.DUMMYFUNCTION("""COMPUTED_VALUE"""),"GESSO AGRICOLA") -> GESSO AGRICOLA | J3: =IFERROR(__xludf.DUMMYFUNCTION("""COMPUTED_VALUE"""),"MEGAFOL") -> MEGAFOL | K3: =IFERROR(__xludf.DUMMYFUNCTION("""COMPUTED_VALUE"""),"CASE MAGNUM 340 + - CASE ASM 1213") -> CASE MAGNUM 340 + - CASE ASM 1213 | L3: FA-SOJA-IRRIGADO-26/27 | M3: ESTEVÃO | N3: 103
A4: =IFERROR(__xludf.DUMMYFUNCTION("""COMPUTED_VALUE"""),"BLINDADO TOV") -> BLINDADO TOV | B4: =IFERROR(__xludf.DUMMYFUNCTION("""COMPUTED_VALUE"""),"ARADDO") -> ARADDO | C4: =IFERROR(__xludf.DUMMYFUNCTION("""COMPUTED_VALUE"""),"PLETHORA BR") -> PLETHORA BR | D4: =IFERROR(__xludf.DUMMYFUNCTION("""COMPUTED_VALUE"""),"RIZOLIQ LLI") -> RIZOLIQ LLI | E4: =IFERROR(__xludf.DUMMYFUNCTION("""COMPUTED_VALUE"""),"Now Lock") -> Now Lock | F4: =IFERROR(__xludf.DUMMYFUNCTION("""COMPUTED_VALUE"""),"SEMENTE MILHO") -> SEMENTE MILHO | G4: =IFERROR(__xludf.DUMMYFUNCTION("""COMPUTED_VALUE"""),"MEES") -> MEES | H4: =IFERROR(__xludf.DUMMYFUNCTION("""COMPUTED_VALUE"""),"KCL 60%") -> KCL 60% | J4: =IFERROR(__xludf.DUMMYFUNCTION("""COMPUTED_VALUE"""),"OCTABORATO") -> OCTABORATO | K4: =IFERROR(__xludf.DUMMYFUNCTION("""COMPUTED_VALUE"""),"CR 8.90 NEW HOLLAND + 880 CF45") -> CR 8.90 NEW HOLLAND + 880 CF45 | L4: FA-MILHO SEQUEIRO-26/27 | M4: ÁREA 2 | N4: 110
A5: =IFERROR(__xludf.DUMMYFUNCTION("""COMPUTED_VALUE"""),"ABACUS HC") -> ABACUS HC | B5: =IFERROR(__xludf.DUMMYFUNCTION("""COMPUTED_VALUE"""),"CHEVAL") -> CHEVAL | C5: =IFERROR(__xludf.DUMMYFUNCTION("""COMPUTED_VALUE"""),"RIMON SUPRA") -> RIMON SUPRA | D5: =IFERROR(__xludf.DUMMYFUNCTION("""COMPUTED_VALUE"""),"PROVILAR") -> PROVILAR | E5: =IFERROR(__xludf.DUMMYFUNCTION("""COMPUTED_VALUE"""),"Now Guard") -> Now Guard | F5: =IFERROR(__xludf.DUMMYFUNCTION("""COMPUTED_VALUE"""),"MG540PWU") -> MG540PWU | G5: =IFERROR(__xludf.DUMMYFUNCTION("""COMPUTED_VALUE"""),"AUREO") -> AUREO | H5: =IFERROR(__xludf.DUMMYFUNCTION("""COMPUTED_VALUE"""),"05-37-00") -> 05-37-00 | J5: =IFERROR(__xludf.DUMMYFUNCTION("""COMPUTED_VALUE"""),"BOP") -> BOP | K5: =IFERROR(__xludf.DUMMYFUNCTION("""COMPUTED_VALUE"""),"COLHETADEIRA - NH-CR9060 + 740 CF30 AGRIDREPER") -> COLHETADEIRA - NH-CR9060 + 740 CF30 AGRIDREPER | L5: FA-SORGO SEQUEIRO-27/27 | M5: ÁREA 2 B | N5: 47
A6: =IFERROR(__xludf.DUMMYFUNCTION("""COMPUTED_VALUE"""),"BELYAN") -> BELYAN | B6: =IFERROR(__xludf.DUMMYFUNCTION("""COMPUTED_VALUE"""),"POQUER") -> POQUER | C6: =IFERROR(__xludf.DUMMYFUNCTION("""COMPUTED_VALUE"""),"SQUAD") -> SQUAD | D6: =IFERROR(__xludf.DUMMYFUNCTION("""COMPUTED_VALUE"""),"REVERB") -> REVERB | E6: =IFERROR(__xludf.DUMMYFUNCTION("""COMPUTED_VALUE"""),"Now Force") -> Now Force | F6: =IFERROR(__xludf.DUMMYFUNCTION("""COMPUTED_VALUE"""),"MG711PWU") -> MG711PWU | G6: =IFERROR(__xludf.DUMMYFUNCTION("""COMPUTED_VALUE"""),"JOINT ULTRA") -> JOINT ULTRA | H6: =IFERROR(__xludf.DUMMYFUNCTION("""COMPUTED_VALUE"""),"10-46-00 + S") -> 10-46-00 + S | J6: =IFERROR(__xludf.DUMMYFUNCTION("""COMPUTED_VALUE"""),"METAL NUTRE") -> METAL NUTRE | K6: =IFERROR(__xludf.DUMMYFUNCTION("""COMPUTED_VALUE"""),"COLHETADEIRA CR7.80 + MACDON 35F") -> COLHETADEIRA CR7.80 + MACDON 35F | L6: FA-MILHO SEMENTE-27/27 | M6: ÁREA 3 | N6: 60
A7: =IFERROR(__xludf.DUMMYFUNCTION("""COMPUTED_VALUE"""),"BLAVITY") -> BLAVITY | B7: =IFERROR(__xludf.DUMMYFUNCTION("""COMPUTED_VALUE"""),"PREMERLIN 600 EC") -> PREMERLIN 600 EC | C7: =IFERROR(__xludf.DUMMYFUNCTION("""COMPUTED_VALUE"""),"TRIVOR") -> TRIVOR | D7: =IFERROR(__xludf.DUMMYFUNCTION("""COMPUTED_VALUE"""),"ARVATICO") -> ARVATICO | E7: =IFERROR(__xludf.DUMMYFUNCTION("""COMPUTED_VALUE"""),"Now Raze") -> Now Raze | F7: =IFERROR(__xludf.DUMMYFUNCTION("""COMPUTED_VALUE"""),"MG616PWU") -> MG616PWU | G7: =IFERROR(__xludf.DUMMYFUNCTION("""COMPUTED_VALUE"""),"ADGREEN") -> ADGREEN | H7: =IFERROR(__xludf.DUMMYFUNCTION("""COMPUTED_VALUE"""),"08-42-00") -> 08-42-00 | J7: =IFERROR(__xludf.DUMMYFUNCTION("""COMPUTED_VALUE"""),"MONIC") -> MONIC | K7: =IFERROR(__xludf.DUMMYFUNCTION("""COMPUTED_VALUE"""),"TRATOR-JD 7500 + BRUTUS 12000") -> TRATOR-JD 7500 + BRUTUS 12000 | L7: FE-SOJA IRRIGADO-26/27 | M7: CAPOEIRINHA | N7: 312
A8: =IFERROR(__xludf.DUMMYFUNCTION("""COMPUTED_VALUE"""),"CANTUS") -> CANTUS | B8: =IFERROR(__xludf.DUMMYFUNCTION("""COMPUTED_VALUE"""),"AMPLO") -> AMPLO | C8: =IFERROR(__xludf.DUMMYFUNCTION("""COMPUTED_VALUE"""),"EFFICON") -> EFFICON | D8: =IFERROR(__xludf.DUMMYFUNCTION("""COMPUTED_VALUE"""),"VERANGO PRIME") -> VERANGO PRIME | E8: =IFERROR(__xludf.DUMMYFUNCTION("""COMPUTED_VALUE"""),"Now Bolt") -> Now Bolt | F8: =IFERROR(__xludf.DUMMYFUNCTION("""COMPUTED_VALUE"""),"P3707PWU") -> P3707PWU | G8: =IFERROR(__xludf.DUMMYFUNCTION("""COMPUTED_VALUE"""),"ENERGIC") -> ENERGIC | H8: =IFERROR(__xludf.DUMMYFUNCTION("""COMPUTED_VALUE"""),"SSP 21") -> SSP 21 | J8: =IFERROR(__xludf.DUMMYFUNCTION("""COMPUTED_VALUE"""),"AP MAGNÉSIO") -> AP MAGNÉSIO | K8: =IFERROR(__xludf.DUMMYFUNCTION("""COMPUTED_VALUE"""),"TRATOR-JD 7500 + ADUBADORA HERCULES 10000") -> TRATOR-JD 7500 + ADUBADORA HERCULES 10000 | L8: FE-BRACHIARIA-26/27 | M8: RONCADOR | N8: 313
A9: =IFERROR(__xludf.DUMMYFUNCTION("""COMPUTED_VALUE"""),"KEYRA") -> KEYRA | B9: =IFERROR(__xludf.DUMMYFUNCTION("""COMPUTED_VALUE"""),"BASAGRAN 600") -> BASAGRAN 600 | C9: =IFERROR(__xludf.DUMMYFUNCTION("""COMPUTED_VALUE"""),"NOMOLT 150") -> NOMOLT 150 | D9: =IFERROR(__xludf.DUMMYFUNCTION("""COMPUTED_VALUE"""),"FIPRONIL NORTOX MAX") -> FIPRONIL NORTOX MAX | E9: =IFERROR(__xludf.DUMMYFUNCTION("""COMPUTED_VALUE"""),"Now Active") -> Now Active | F9: =IFERROR(__xludf.DUMMYFUNCTION("""COMPUTED_VALUE"""),"P39209PWU") -> P39209PWU | G9: =IFERROR(__xludf.DUMMYFUNCTION("""COMPUTED_VALUE"""),"EXTRAVON") -> EXTRAVON | H9: =IFERROR(__xludf.DUMMYFUNCTION("""COMPUTED_VALUE"""),"03-15-07 +14%CO") -> 03-15-07 +14%CO | J9: =IFERROR(__xludf.DUMMYFUNCTION("""COMPUTED_VALUE"""),"GRANO KMG") -> GRANO KMG | K9: =IFERROR(__xludf.DUMMYFUNCTION("""COMPUTED_VALUE"""),"VOLVO NH380 + CAÇAMBA 430SC") -> VOLVO NH380 + CAÇAMBA 430SC | L9: FE-SOJA SEQUEIRO-26/27 | M9: RONCADOR 2 | N9: 0
A10: =IFERROR(__xludf.DUMMYFUNCTION("""COMPUTED_VALUE"""),"MELYRA") -> MELYRA | B10: =IFERROR(__xludf.DUMMYFUNCTION("""COMPUTED_VALUE"""),"FINALE") -> FINALE | C10: =IFERROR(__xludf.DUMMYFUNCTION("""COMPUTED_VALUE"""),"PIRATE") -> PIRATE | D10: =IFERROR(__xludf.DUMMYFUNCTION("""COMPUTED_VALUE"""),"MAXIM ADVANCED") -> MAXIM ADVANCED | E10: =IFERROR(__xludf.DUMMYFUNCTION("""COMPUTED_VALUE"""),"Now React") -> Now React | F10: =IFERROR(__xludf.DUMMYFUNCTION("""COMPUTED_VALUE"""),"P40537PWU") -> P40537PWU | G10: =IFERROR(__xludf.DUMMYFUNCTION("""COMPUTED_VALUE"""),"OCHIMA") -> OCHIMA | H10: =IFERROR(__xludf.DUMMYFUNCTION("""COMPUTED_VALUE"""),"URÉIA") -> URÉIA | J10: =IFERROR(__xludf.DUMMYFUNCTION("""COMPUTED_VALUE"""),"AP MANGANÊS") -> AP MANGANÊS | K10: =IFERROR(__xludf.DUMMYFUNCTION("""COMPUTED_VALUE"""),"CASE MAGNUM 340 + SUBSOLADOR 11 ASTES") -> CASE MAGNUM 340 + SUBSOLADOR 11 ASTES | L10: FE-SORGO IRRIGADO-26/27 | M10: P200 | N10: 200
A11: =IFERROR(__xludf.DUMMYFUNCTION("""COMPUTED_VALUE"""),"ORKESTRA SC") -> ORKESTRA SC | B11: =IFERROR(__xludf.DUMMYFUNCTION("""COMPUTED_VALUE"""),"HEAT") -> HEAT | C11: =IFERROR(__xludf.DUMMYFUNCTION("""COMPUTED_VALUE"""),"BELT") -> BELT | D11: =IFERROR(__xludf.DUMMYFUNCTION("""COMPUTED_VALUE"""),"MAXIM XL") -> MAXIM XL | E11: =IFERROR(__xludf.DUMMYFUNCTION("""COMPUTED_VALUE"""),"Now Cover") -> Now Cover | F11: =IFERROR(__xludf.DUMMYFUNCTION("""COMPUTED_VALUE"""),"FS650PWU") -> FS650PWU | H11: =IFERROR(__xludf.DUMMYFUNCTION("""COMPUTED_VALUE"""),"SULFATO DE AMÔNIO") -> SULFATO DE AMÔNIO | J11: =IFERROR(__xludf.DUMMYFUNCTION("""COMPUTED_VALUE"""),"AMINOS Mn") -> AMINOS Mn | K11: =IFERROR(__xludf.DUMMYFUNCTION("""COMPUTED_VALUE"""),"PULVERIZADOR- JD4730 + PULVERIZADOR- JD4730") -> PULVERIZADOR- JD4730 + PULVERIZADOR- JD4730 | L11: FE-SORGO SEQUEIRO-26/27 | M11: P120 | N11: 120
A12: =IFERROR(__xludf.DUMMYFUNCTION("""COMPUTED_VALUE"""),"SPOT SC") -> SPOT SC | B12: =IFERROR(__xludf.DUMMYFUNCTION("""COMPUTED_VALUE"""),"LIBERTY") -> LIBERTY | C12: =IFERROR(__xludf.DUMMYFUNCTION("""COMPUTED_VALUE"""),"BULLDOCK 125 SC") -> BULLDOCK 125 SC | D12: =IFERROR(__xludf.DUMMYFUNCTION("""COMPUTED_VALUE"""),"VICTRATO") -> VICTRATO | E12: =IFERROR(__xludf.DUMMYFUNCTION("""COMPUTED_VALUE"""),"Now Pulse") -> Now Pulse | F12: =IFERROR(__xludf.DUMMYFUNCTION("""COMPUTED_VALUE"""),"SEMENTE SOJA CV") -> SEMENTE SOJA CV | H12: =IFERROR(__xludf.DUMMYFUNCTION("""COMPUTED_VALUE"""),"BOROGRAN") -> BOROGRAN | J12: =IFERROR(__xludf.DUMMYFUNCTION("""COMPUTED_VALUE"""),"MICROBOX") -> MICROBOX | K12: =IFERROR(__xludf.DUMMYFUNCTION("""COMPUTED_VALUE"""),"AIR TRATOR AT-502B + AIR TRATOR AT-502B") -> AIR TRATOR AT-502B + AIR TRATOR AT-502B | M12: BARRO BRANCO | N12: 220
A13: =IFERROR(__xludf.DUMMYFUNCTION("""COMPUTED_VALUE"""),"ATTILA") -> ATTILA | B13: =IFERROR(__xludf.DUMMYFUNCTION("""COMPUTED_VALUE"""),"PROWL H2O") -> PROWL H2O | C13: =IFERROR(__xludf.DUMMYFUNCTION("""COMPUTED_VALUE"""),"CERTERO") -> CERTERO | D13: =IFERROR(__xludf.DUMMYFUNCTION("""COMPUTED_VALUE"""),"SPECTRO") -> SPECTRO | E13: =IFERROR(__xludf.DUMMYFUNCTION("""COMPUTED_VALUE"""),"Now Sprint") -> Now Sprint | F13: =IFERROR(__xludf.DUMMYFUNCTION("""COMPUTED_VALUE"""),"OLIMPO") -> OLIMPO | H13: =IFERROR(__xludf.DUMMYFUNCTION("""COMPUTED_VALUE"""),"SUPER DUO") -> SUPER DUO | J13: =IFERROR(__xludf.DUMMYFUNCTION("""COMPUTED_VALUE"""),"ACRESECENT ALGA") -> ACRESECENT ALGA | K13: =IFERROR(__xludf.DUMMYFUNCTION("""COMPUTED_VALUE"""),"COLHETADEIRA - NH-CR9060 + MILHO BRAVA 11") -> COLHETADEIRA - NH-CR9060 + MILHO BRAVA 11 | M13: P 01 | N13: 60
A14: =IFERROR(__xludf.DUMMYFUNCTION("""COMPUTED_VALUE"""),"FOX SUPRA") -> FOX SUPRA | B14: =IFERROR(__xludf.DUMMYFUNCTION("""COMPUTED_VALUE"""),"ADENGO") -> ADENGO | C14: =IFERROR(__xludf.DUMMYFUNCTION("""COMPUTED_VALUE"""),"CONNECT") -> CONNECT | D14: =IFERROR(__xludf.DUMMYFUNCTION("""COMPUTED_VALUE"""),"STANDAK TOP") -> STANDAK TOP | E14: =IFERROR(__xludf.DUMMYFUNCTION("""COMPUTED_VALUE"""),"Bio Az") -> Bio Az | F14: =IFERROR(__xludf.DUMMYFUNCTION("""COMPUTED_VALUE"""),"M8349") -> M8349 | H14: =IFERROR(__xludf.DUMMYFUNCTION("""COMPUTED_VALUE"""),"08-40-00 - 100M") -> 08-40-00 - 100M | J14: =IFERROR(__xludf.DUMMYFUNCTION("""COMPUTED_VALUE"""),"RAIZ F") -> RAIZ F | K14: =IFERROR(__xludf.DUMMYFUNCTION("""COMPUTED_VALUE"""),"NH T7.260 + JAN 20000") -> NH T7.260 + JAN 20000 | M14: P 02 | N14: 80
A15: =IFERROR(__xludf.DUMMYFUNCTION("""COMPUTED_VALUE"""),"FOX XPRO") -> FOX XPRO | B15: =IFERROR(__xludf.DUMMYFUNCTION("""COMPUTED_VALUE"""),"ROUNDUP WG") -> ROUNDUP WG | C15: =IFERROR(__xludf.DUMMYFUNCTION("""COMPUTED_VALUE"""),"CURBIX 200 SC") -> CURBIX 200 SC | D15: =IFERROR(__xludf.DUMMYFUNCTION("""COMPUTED_VALUE"""),"CRUISER ADVANCED") -> CRUISER ADVANCED | E15: =IFERROR(__xludf.DUMMYFUNCTION("""COMPUTED_VALUE"""),"Bio ND") -> Bio ND | F15: =IFERROR(__xludf.DUMMYFUNCTION("""COMPUTED_VALUE"""),"CORDIUS C2795 CE") -> CORDIUS C2795 CE | H15: =IFERROR(__xludf.DUMMYFUNCTION("""COMPUTED_VALUE"""),"AURUS 500") -> AURUS 500 | J15: =IFERROR(__xludf.DUMMYFUNCTION("""COMPUTED_VALUE"""),"ACRESCENTE SOLUS F") -> ACRESCENTE SOLUS F | K15: =IFERROR(__xludf.DUMMYFUNCTION("""COMPUTED_VALUE"""),"NH T8.355 + - JD2122") -> NH T8.355 + - JD2122 | M15: P 03 | N15: 120
A16: =IFERROR(__xludf.DUMMYFUNCTION("""COMPUTED_VALUE"""),"NATIVO") -> NATIVO | B16: =IFERROR(__xludf.DUMMYFUNCTION("""COMPUTED_VALUE"""),"SOBERAN") -> SOBERAN | C16: =IFERROR(__xludf.DUMMYFUNCTION("""COMPUTED_VALUE"""),"OBERON") -> OBERON | D16: =IFERROR(__xludf.DUMMYFUNCTION("""COMPUTED_VALUE"""),"PLUST") -> PLUST | E16: =IFERROR(__xludf.DUMMYFUNCTION("""COMPUTED_VALUE"""),"Tec Catp Pro") -> Tec Catp Pro | F16: =IFERROR(__xludf.DUMMYFUNCTION("""COMPUTED_VALUE"""),"HERA I2X") -> HERA I2X | H16: =IFERROR(__xludf.DUMMYFUNCTION("""COMPUTED_VALUE"""),"00-01-00+Cu2 Mn8 Zn7 ") -> 00-01-00+Cu2 Mn8 Zn7 | J16: =IFERROR(__xludf.DUMMYFUNCTION("""COMPUTED_VALUE"""),"SALUT") -> SALUT | K16: =IFERROR(__xludf.DUMMYFUNCTION("""COMPUTED_VALUE"""),"COLHETADEIRA - CASE 2388 + CASE 30PES") -> COLHETADEIRA - CASE 2388 + CASE 30PES | M16: P 04 | N16: 130
A17: =IFERROR(__xludf.DUMMYFUNCTION("""COMPUTED_VALUE"""),"NATIVO PLUS") -> NATIVO PLUS | B17: =IFERROR(__xludf.DUMMYFUNCTION("""COMPUTED_VALUE"""),"2,4-D 806+PICLORAM 64") -> 2,4-D 806+PICLORAM 64 | C17: =IFERROR(__xludf.DUMMYFUNCTION("""COMPUTED_VALUE"""),"ACETAMIPRID CCAB 200 SP") -> ACETAMIPRID CCAB 200 SP | D17: =IFERROR(__xludf.DUMMYFUNCTION("""COMPUTED_VALUE"""),"SOMBRERO") -> SOMBRERO | E17: =IFERROR(__xludf.DUMMYFUNCTION("""COMPUTED_VALUE"""),"Bio Elipso") -> Bio Elipso | F17: =IFERROR(__xludf.DUMMYFUNCTION("""COMPUTED_VALUE"""),"SPARTA 8.0") -> SPARTA 8.0 | J17: =IFERROR(__xludf.DUMMYFUNCTION("""COMPUTED_VALUE"""),"MATRIZ D") -> MATRIZ D | K17: =IFERROR(__xludf.DUMMYFUNCTION("""COMPUTED_VALUE"""),"JACTO UNIPORT 2000 + JACTO UNIPORT 2000") -> JACTO UNIPORT 2000 + JACTO UNIPORT 2000 | M17: P 05 | N17: 120
A18: =IFERROR(__xludf.DUMMYFUNCTION("""COMPUTED_VALUE"""),"SPHERE MAX") -> SPHERE MAX | B18: =IFERROR(__xludf.DUMMYFUNCTION("""COMPUTED_VALUE"""),"FOMESAFEN CCAB 250 SL") -> FOMESAFEN CCAB 250 SL | C18: =IFERROR(__xludf.DUMMYFUNCTION("""COMPUTED_VALUE"""),"DIFLUBENZURON CCAB 480 SC") -> DIFLUBENZURON CCAB 480 SC | D18: =IFERROR(__xludf.DUMMYFUNCTION("""COMPUTED_VALUE"""),"CROPSTAR") -> CROPSTAR | E18: =IFERROR(__xludf.DUMMYFUNCTION("""COMPUTED_VALUE"""),"Tec Bug") -> Tec Bug | F18: =IFERROR(__xludf.DUMMYFUNCTION("""COMPUTED_VALUE"""),"CORDIUS C2795 CE 7.9") -> CORDIUS C2795 CE 7.9 | J18: =IFERROR(__xludf.DUMMYFUNCTION("""COMPUTED_VALUE"""),"BRAVERO") -> BRAVERO | K18: =IFERROR(__xludf.DUMMYFUNCTION("""COMPUTED_VALUE"""),"NH T7.260 + CASE 2213") -> NH T7.260 + CASE 2213 | M18: P 06 | N18: 40
A19: =IFERROR(__xludf.DUMMYFUNCTION("""COMPUTED_VALUE"""),"AZOXISTROBIN 200 + CIPROCONAZOL 80 SC CCAB") -> AZOXISTROBIN 200 + CIPROCONAZOL 80 SC CCAB | B19: =IFERROR(__xludf.DUMMYFUNCTION("""COMPUTED_VALUE"""),"GLUFOSINATO CCAB 200 SL") -> GLUFOSINATO CCAB 200 SL | C19: =IFERROR(__xludf.DUMMYFUNCTION("""COMPUTED_VALUE"""),"FIPRONIL 800 WG CCAB") -> FIPRONIL 800 WG CCAB | D19: =IFERROR(__xludf.DUMMYFUNCTION("""COMPUTED_VALUE"""),"DERMACOR") -> DERMACOR | E19: =IFERROR(__xludf.DUMMYFUNCTION("""COMPUTED_VALUE"""),"Solu Shield") -> Solu Shield | F19: =IFERROR(__xludf.DUMMYFUNCTION("""COMPUTED_VALUE"""),"IMPETO") -> IMPETO | J19: =IFERROR(__xludf.DUMMYFUNCTION("""COMPUTED_VALUE"""),"Glyfort") -> Glyfort | K19: =IFERROR(__xludf.DUMMYFUNCTION("""COMPUTED_VALUE""")," + ") -> + | M19: T01 | N19: 220
A20: =IFERROR(__xludf.DUMMYFUNCTION("""COMPUTED_VALUE"""),"MANCOZEB CCAB 750 WG") -> MANCOZEB CCAB 750 WG | B20: =IFERROR(__xludf.DUMMYFUNCTION("""COMPUTED_VALUE"""),"MESOTRIONA CCAB 480 SC") -> MESOTRIONA CCAB 480 SC | C20: =IFERROR(__xludf.DUMMYFUNCTION("""COMPUTED_VALUE"""),"INDOXACARB CCAB 150 SC") -> INDOXACARB CCAB 150 SC | D20: =IFERROR(__xludf.DUMMYFUNCTION("""COMPUTED_VALUE"""),"OPTERASEED") -> OPTERASEED | E20: =IFERROR(__xludf.DUMMYFUNCTION("""COMPUTED_VALUE"""),"Solu Strong") -> Solu Strong | F20: =IFERROR(__xludf.DUMMYFUNCTION("""COMPUTED_VALUE"""),"NEO 790") -> NEO 790 | J20: =IFERROR(__xludf.DUMMYFUNCTION("""COMPUTED_VALUE"""),"Fergsum") -> Fergsum | M20: T02 | N20: 220
A21: =IFERROR(__xludf.DUMMYFUNCTION("""COMPUTED_VALUE"""),"APROACH POWER") -> APROACH POWER | B21: =IFERROR(__xludf.DUMMYFUNCTION("""COMPUTED_VALUE"""),"TRICLOPIR CCAB 480 EC") -> TRICLOPIR CCAB 480 EC | C21: =IFERROR(__xludf.DUMMYFUNCTION("""COMPUTED_VALUE"""),"EXALT") -> EXALT | D21: =IFERROR(__xludf.DUMMYFUNCTION("""COMPUTED_VALUE"""),"AVICTA 500 FS") -> AVICTA 500 FS | E21: =IFERROR(__xludf.DUMMYFUNCTION("""COMPUTED_VALUE"""),"Solu Leaf") -> Solu Leaf | F21: =IFERROR(__xludf.DUMMYFUNCTION("""COMPUTED_VALUE"""),"APORÉ 7.3") -> APORÉ 7.3 | J21: =IFERROR(__xludf.DUMMYFUNCTION("""COMPUTED_VALUE"""),"Spander") -> Spander
A22: =IFERROR(__xludf.DUMMYFUNCTION("""COMPUTED_VALUE"""),"APROACH PREMIUM") -> APROACH PREMIUM | B22: =IFERROR(__xludf.DUMMYFUNCTION("""COMPUTED_VALUE"""),"ACCENT") -> ACCENT | C22: =IFERROR(__xludf.DUMMYFUNCTION("""COMPUTED_VALUE"""),"EXPEDITION") -> EXPEDITION | D22: =IFERROR(__xludf.DUMMYFUNCTION("""COMPUTED_VALUE"""),"CRUISER 350 FS") -> CRUISER 350 FS | E22: =IFERROR(__xludf.DUMMYFUNCTION("""COMPUTED_VALUE"""),"Bio Hidric") -> Bio Hidric | F22: =IFERROR(__xludf.DUMMYFUNCTION("""COMPUTED_VALUE"""),"GUAPÓ 7.7") -> GUAPÓ 7.7 | J22: =IFERROR(__xludf.DUMMYFUNCTION("""COMPUTED_VALUE"""),"Halattus") -> Halattus
A23: =IFERROR(__xludf.DUMMYFUNCTION("""COMPUTED_VALUE"""),"BIM 750 BR") -> BIM 750 BR | B23: =IFERROR(__xludf.DUMMYFUNCTION("""COMPUTED_VALUE"""),"CLASSIC") -> CLASSIC | C23: =IFERROR(__xludf.DUMMYFUNCTION("""COMPUTED_VALUE"""),"INTREPID 240 SC") -> INTREPID 240 SC | D23: =IFERROR(__xludf.DUMMYFUNCTION("""COMPUTED_VALUE"""),"FORTENZA 600 FS") -> FORTENZA 600 FS | E23: =IFERROR(__xludf.DUMMYFUNCTION("""COMPUTED_VALUE"""),"Bio Bokashi") -> Bio Bokashi | F23: =IFERROR(__xludf.DUMMYFUNCTION("""COMPUTED_VALUE"""),"MITICA 7.7") -> MITICA 7.7 | J23: =IFERROR(__xludf.DUMMYFUNCTION("""COMPUTED_VALUE"""),"Sallvare Complex") -> Sallvare Complex
A24: =IFERROR(__xludf.DUMMYFUNCTION("""COMPUTED_VALUE"""),"BIM MAX") -> BIM MAX | B24: =IFERROR(__xludf.DUMMYFUNCTION("""COMPUTED_VALUE"""),"CLINCHER") -> CLINCHER | C24: =IFERROR(__xludf.DUMMYFUNCTION("""COMPUTED_VALUE"""),"INTREPID EDGE") -> INTREPID EDGE | D24: =IFERROR(__xludf.DUMMYFUNCTION("""COMPUTED_VALUE"""),"ILEVO") -> ILEVO | E24: =IFERROR(__xludf.DUMMYFUNCTION("""COMPUTED_VALUE"""),"Bio Oil") -> Bio Oil | F24: =IFERROR(__xludf.DUMMYFUNCTION("""COMPUTED_VALUE"""),"TMG MURICI I2X 7.6") -> TMG MURICI I2X 7.6 | J24: =IFERROR(__xludf.DUMMYFUNCTION("""COMPUTED_VALUE"""),"Zinctaus Complex") -> Zinctaus Complex
A25: =IFERROR(__xludf.DUMMYFUNCTION("""COMPUTED_VALUE"""),"ORANIS") -> ORANIS | B25: =IFERROR(__xludf.DUMMYFUNCTION("""COMPUTED_VALUE"""),"ELEVORE") -> ELEVORE | C25: =IFERROR(__xludf.DUMMYFUNCTION("""COMPUTED_VALUE"""),"LANNATE BR") -> LANNATE BR | D25: =IFERROR(__xludf.DUMMYFUNCTION("""COMPUTED_VALUE"""),"PERMIT STAR") -> PERMIT STAR | E25: =IFERROR(__xludf.DUMMYFUNCTION("""COMPUTED_VALUE"""),"Carbon Pro") -> Carbon Pro | F25: =IFERROR(__xludf.DUMMYFUNCTION("""COMPUTED_VALUE"""),"DOMÍNIO 8.4") -> DOMÍNIO 8.4 | J25: =IFERROR(__xludf.DUMMYFUNCTION("""COMPUTED_VALUE"""),"Emezine Complex") -> Emezine Complex
A26: =IFERROR(__xludf.DUMMYFUNCTION("""COMPUTED_VALUE"""),"VESSARYA") -> VESSARYA | B26: =IFERROR(__xludf.DUMMYFUNCTION("""COMPUTED_VALUE"""),"ENLIST COLEX-D") -> ENLIST COLEX-D | C26: =IFERROR(__xludf.DUMMYFUNCTION("""COMPUTED_VALUE"""),"ACETAMIPRID 250 G/KG + BIFENTHRIN 250G/KG WG") -> ACETAMIPRID 250 G/KG + BIFENTHRIN 250G/KG WG | E26: =IFERROR(__xludf.DUMMYFUNCTION("""COMPUTED_VALUE"""),"Essencial Mg") -> Essencial Mg | F26: =IFERROR(__xludf.DUMMYFUNCTION("""COMPUTED_VALUE"""),"LENDA") -> LENDA | J26: =IFERROR(__xludf.DUMMYFUNCTION("""COMPUTED_VALUE"""),"Boratus Complex") -> Boratus Complex
A27: =IFERROR(__xludf.DUMMYFUNCTION("""COMPUTED_VALUE"""),"CHARRUA 430 SC") -> CHARRUA 430 SC | B27: =IFERROR(__xludf.DUMMYFUNCTION("""COMPUTED_VALUE"""),"GAPPER") -> GAPPER | C27: =IFERROR(__xludf.DUMMYFUNCTION("""COMPUTED_VALUE"""),"BAKANA 400 SC") -> BAKANA 400 SC | E27: =IFERROR(__xludf.DUMMYFUNCTION("""COMPUTED_VALUE"""),"Expelir") -> Expelir | F27: =IFERROR(__xludf.DUMMYFUNCTION("""COMPUTED_VALUE"""),"BRASMAX HERA") -> BRASMAX HERA | J27: =IFERROR(__xludf.DUMMYFUNCTION("""COMPUTED_VALUE"""),"Magmill Complex") -> Magmill Complex
A28: =IFERROR(__xludf.DUMMYFUNCTION("""COMPUTED_VALUE"""),"SEVARE 250 EC") -> SEVARE 250 EC | B28: =IFERROR(__xludf.DUMMYFUNCTION("""COMPUTED_VALUE"""),"PACTO") -> PACTO | C28: =IFERROR(__xludf.DUMMYFUNCTION("""COMPUTED_VALUE"""),"KRATON 100 EC") -> KRATON 100 EC | E28: =IFERROR(__xludf.DUMMYFUNCTION("""COMPUTED_VALUE"""),"Primafert") -> Primafert | F28: =IFERROR(__xludf.DUMMYFUNCTION("""COMPUTED_VALUE"""),"BRASMAX OLIMPO") -> BRASMAX OLIMPO | J28: =IFERROR(__xludf.DUMMYFUNCTION("""COMPUTED_VALUE"""),"Brave K") -> Brave K
A29: =IFERROR(__xludf.DUMMYFUNCTION("""COMPUTED_VALUE"""),"VENCER DUO") -> VENCER DUO | B29: =IFERROR(__xludf.DUMMYFUNCTION("""COMPUTED_VALUE"""),"PAXEO") -> PAXEO | C29: =IFERROR(__xludf.DUMMYFUNCTION("""COMPUTED_VALUE"""),"TAURA 200 EC") -> TAURA 200 EC | E29: =IFERROR(__xludf.DUMMYFUNCTION("""COMPUTED_VALUE"""),"Reserva") -> Reserva | F29: =IFERROR(__xludf.DUMMYFUNCTION("""COMPUTED_VALUE"""),"S6525 I2X") -> S6525 I2X | J29: =IFERROR(__xludf.DUMMYFUNCTION("""COMPUTED_VALUE"""),"Brave Max Up") -> Brave Max Up
A30: =IFERROR(__xludf.DUMMYFUNCTION("""COMPUTED_VALUE"""),"ONSUVA") -> ONSUVA | B30: =IFERROR(__xludf.DUMMYFUNCTION("""COMPUTED_VALUE"""),"SPIDER 840 WG") -> SPIDER 840 WG | C30: =IFERROR(__xludf.DUMMYFUNCTION("""COMPUTED_VALUE"""),"BENEVIA") -> BENEVIA | E30: =IFERROR(__xludf.DUMMYFUNCTION("""COMPUTED_VALUE"""),"Tec Catp Pro Kit On-farm") -> Tec Catp Pro Kit On-farm | F30: =IFERROR(__xludf.DUMMYFUNCTION("""COMPUTED_VALUE"""),"TMG ITAÚBA I2X") -> TMG ITAÚBA I2X | J30: =IFERROR(__xludf.DUMMYFUNCTION("""COMPUTED_VALUE"""),"MAX RAIZ") -> MAX RAIZ
A31: =IFERROR(__xludf.DUMMYFUNCTION("""COMPUTED_VALUE"""),"BOSCALID NORTOX 500 WG") -> BOSCALID NORTOX 500 WG | B31: =IFERROR(__xludf.DUMMYFUNCTION("""COMPUTED_VALUE"""),"VERDICT ULTRA") -> VERDICT ULTRA | C31: =IFERROR(__xludf.DUMMYFUNCTION("""COMPUTED_VALUE"""),"HERO") -> HERO | E31: =IFERROR(__xludf.DUMMYFUNCTION("""COMPUTED_VALUE"""),"Tec Bug Kit On-farm") -> Tec Bug Kit On-farm | J31: =IFERROR(__xludf.DUMMYFUNCTION("""COMPUTED_VALUE"""),"Polyamine") -> Polyamine
A32: =IFERROR(__xludf.DUMMYFUNCTION("""COMPUTED_VALUE"""),"DIFENOCONAZOL NORTOX 250 SC") -> DIFENOCONAZOL NORTOX 250 SC | B32: =IFERROR(__xludf.DUMMYFUNCTION("""COMPUTED_VALUE"""),"BLOWOUT") -> BLOWOUT | C32: =IFERROR(__xludf.DUMMYFUNCTION("""COMPUTED_VALUE"""),"MALATHION UL") -> MALATHION UL | E32: =IFERROR(__xludf.DUMMYFUNCTION("""COMPUTED_VALUE"""),"Solu Shield Kit On-farm") -> Solu Shield Kit On-farm | F32: =IFERROR(__xludf.DUMMYFUNCTION("""COMPUTED_VALUE"""),"SEMENTE SOJA RR") -> SEMENTE SOJA RR | J32: =IFERROR(__xludf.DUMMYFUNCTION("""COMPUTED_VALUE"""),"Sulfato de Magnésio") -> Sulfato de Magnésio
A33: =IFERROR(__xludf.DUMMYFUNCTION("""COMPUTED_VALUE"""),"FLUAZINAM NORTOX 500 SC") -> FLUAZINAM NORTOX 500 SC | B33: =IFERROR(__xludf.DUMMYFUNCTION("""COMPUTED_VALUE"""),"CLETODIM 240 EC BRILLIANCE") -> CLETODIM 240 EC BRILLIANCE | C33: =IFERROR(__xludf.DUMMYFUNCTION("""COMPUTED_VALUE"""),"MUSTANG 350 EC") -> MUSTANG 350 EC | E33: =IFERROR(__xludf.DUMMYFUNCTION("""COMPUTED_VALUE"""),"Solu Strong Kit On-farm") -> Solu Strong Kit On-farm | F33: =IFERROR(__xludf.DUMMYFUNCTION("""COMPUTED_VALUE"""),"BRACHIARIA RUZIZIENCES") -> BRACHIARIA RUZIZIENCES | J33: =IFERROR(__xludf.DUMMYFUNCTION("""COMPUTED_VALUE"""),"Map Purificado") -> Map Purificado
A34: =IFERROR(__xludf.DUMMYFUNCTION("""COMPUTED_VALUE"""),"FLUTRIAFOL NORTOX") -> FLUTRIAFOL NORTOX | B34: =IFERROR(__xludf.DUMMYFUNCTION("""COMPUTED_VALUE"""),"GLUFOS-WYN 880") -> GLUFOS-WYN 880 | C34: =IFERROR(__xludf.DUMMYFUNCTION("""COMPUTED_VALUE"""),"PREMIO") -> PREMIO | E34: =IFERROR(__xludf.DUMMYFUNCTION("""COMPUTED_VALUE"""),"Solu Leaf Kit On-farm") -> Solu Leaf Kit On-farm | F34: =IFERROR(__xludf.DUMMYFUNCTION("""COMPUTED_VALUE"""),"CAPIM MIAGE") -> CAPIM MIAGE | J34: =IFERROR(__xludf.DUMMYFUNCTION("""COMPUTED_VALUE"""),"MANGAN 10") -> MANGAN 10
A35: =IFERROR(__xludf.DUMMYFUNCTION("""COMPUTED_VALUE"""),"PROPICONAZOLE NORTOX 500 EC") -> PROPICONAZOLE NORTOX 500 EC | B35: =IFERROR(__xludf.DUMMYFUNCTION("""COMPUTED_VALUE"""),"GINETE 212 SL") -> GINETE 212 SL | C35: =IFERROR(__xludf.DUMMYFUNCTION("""COMPUTED_VALUE"""),"TALISMAN") -> TALISMAN | E35: =IFERROR(__xludf.DUMMYFUNCTION("""COMPUTED_VALUE"""),"Bio Hidric Kit On-farm") -> Bio Hidric Kit On-farm | F35: =IFERROR(__xludf.DUMMYFUNCTION("""COMPUTED_VALUE"""),"TMG INGÁ I2X 6.9") -> TMG INGÁ I2X 6.9 | J35: =IFERROR(__xludf.DUMMYFUNCTION("""COMPUTED_VALUE"""),"NHT ZINCO") -> NHT ZINCO
A36: =IFERROR(__xludf.DUMMYFUNCTION("""COMPUTED_VALUE"""),"PROTECTION NORTOX") -> PROTECTION NORTOX | B36: =IFERROR(__xludf.DUMMYFUNCTION("""COMPUTED_VALUE"""),"AURORA 400 EC") -> AURORA 400 EC | C36: =IFERROR(__xludf.DUMMYFUNCTION("""COMPUTED_VALUE"""),"TALSTAR 400") -> TALSTAR 400 | E36: =IFERROR(__xludf.DUMMYFUNCTION("""COMPUTED_VALUE"""),"Bio Bokashi Kit On-farm") -> Bio Bokashi Kit On-farm | F36: =IFERROR(__xludf.DUMMYFUNCTION("""COMPUTED_VALUE"""),"TMG 2383 IPRO 8.3") -> TMG 2383 IPRO 8.3 | J36: =IFERROR(__xludf.DUMMYFUNCTION("""COMPUTED_VALUE"""),"KELLUS CUPPER") -> KELLUS CUPPER
A37: =IFERROR(__xludf.DUMMYFUNCTION("""COMPUTED_VALUE"""),"TEBUCO 430 SC NORTOX") -> TEBUCO 430 SC NORTOX | B37: =IFERROR(__xludf.DUMMYFUNCTION("""COMPUTED_VALUE"""),"AZUGRO") -> AZUGRO | C37: =IFERROR(__xludf.DUMMYFUNCTION("""COMPUTED_VALUE"""),"VERIMARK") -> VERIMARK | E37: =IFERROR(__xludf.DUMMYFUNCTION("""COMPUTED_VALUE"""),"Tec White Kit On-farm") -> Tec White Kit On-farm | F37: =IFERROR(__xludf.DUMMYFUNCTION("""COMPUTED_VALUE"""),"BRACHIARIA BASICA") -> BRACHIARIA BASICA | J37: =IFERROR(__xludf.DUMMYFUNCTION("""COMPUTED_VALUE"""),"MOLIBIDENIO 16") -> MOLIBIDENIO 16
A38: =IFERROR(__xludf.DUMMYFUNCTION("""COMPUTED_VALUE"""),"TEBUCO A NORTOX") -> TEBUCO A NORTOX | B38: =IFERROR(__xludf.DUMMYFUNCTION("""COMPUTED_VALUE"""),"BORAL") -> BORAL | C38: =IFERROR(__xludf.DUMMYFUNCTION("""COMPUTED_VALUE"""),"ABAMECTIN 72 EC NORTOX") -> ABAMECTIN 72 EC NORTOX | E38: =IFERROR(__xludf.DUMMYFUNCTION("""COMPUTED_VALUE"""),"Bio Solubilize Kit On-farm") -> Bio Solubilize Kit On-farm | F38: =IFERROR(__xludf.DUMMYFUNCTION("""COMPUTED_VALUE"""),"GH 2478 IPRO 8.1") -> GH 2478 IPRO 8.1 | J38: =IFERROR(__xludf.DUMMYFUNCTION("""COMPUTED_VALUE"""),"ZINCO 10") -> ZINCO 10
A39: =IFERROR(__xludf.DUMMYFUNCTION("""COMPUTED_VALUE"""),"TIOFANATO NORTOX") -> TIOFANATO NORTOX | B39: =IFERROR(__xludf.DUMMYFUNCTION("""COMPUTED_VALUE"""),"REATOR 360 CS") -> REATOR 360 CS | C39: =IFERROR(__xludf.DUMMYFUNCTION("""COMPUTED_VALUE"""),"CIPERMETRINA NORTOX") -> CIPERMETRINA NORTOX | E39: =IFERROR(__xludf.DUMMYFUNCTION("""COMPUTED_VALUE"""),"Bio Release Kit On-farm") -> Bio Release Kit On-farm | F39: =IFERROR(__xludf.DUMMYFUNCTION("""COMPUTED_VALUE"""),"HO COCARI I2X 8.2") -> HO COCARI I2X 8.2 | J39: =IFERROR(__xludf.DUMMYFUNCTION("""COMPUTED_VALUE"""),"Potenza NiCoMo") -> Potenza NiCoMo
A40: =IFERROR(__xludf.DUMMYFUNCTION("""COMPUTED_VALUE"""),"ACADEMIC") -> ACADEMIC | B40: =IFERROR(__xludf.DUMMYFUNCTION("""COMPUTED_VALUE"""),"STONE") -> STONE | C40: =IFERROR(__xludf.DUMMYFUNCTION("""COMPUTED_VALUE"""),"CLORANTRANILIPROLE NORTOX 400 SC") -> CLORANTRANILIPROLE NORTOX 400 SC | E40: =IFERROR(__xludf.DUMMYFUNCTION("""COMPUTED_VALUE"""),"Bio Raiz Plus Kit On-farm") -> Bio Raiz Plus Kit On-farm | F40: =IFERROR(__xludf.DUMMYFUNCTION("""COMPUTED_VALUE"""),"SEMENTE DE SORGO") -> SEMENTE DE SORGO
...

Sheet CUSTO OPERAÇÃO
A1: Column 11 | B1: MÁQUINA | C1: IMPLEMENTO | D1: CONJUNTO | E1: LARGURA | F1: VELOCIDADE | G1: EFICIÊNCIA | H1: ha/h | I1: L/h | J1: HM/ha | K1: L/ha | L1: CUSTO HM/HA | M1: HORA MAQ./HA | O1: GRUPO | P1: MAQUINA | Q1: CONSUMO HORA | R1: LARGURA OPERAÇÃO | S1: VELOCIDADE
A2: MÁQUINAS | B2: TRATOR - CASE STEIGER 420 | C2: PLANTADEIRA HORSCH MAESTRO DUO 36.50 | D2: =IFERROR(__xludf.DUMMYFUNCTION("REGEXREPLACE(B2,""TRATOR - |COLHEITADEIRA |PULVERIZADOR |CAMINHAO-"","""")&"" + ""&REGEXREPLACE(C2,""PLANTADEIRA |PLATAFORMA |DISTRIBUIDOR |PULVERIZADOR "", """")"),"CASE STEIGER 420 + HORSCH MAESTRO DUO 36.50") -> CASE STEIGER 420 + HORSCH MAESTRO DUO 36.50 | E2: =VLOOKUP(C2,'CUSTO OPERAÇÃO'!$P$1:$S$125,3,0) -> 18 | F2: =VLOOKUP(C2,'CUSTO OPERAÇÃO'!$P$1:$S$125,4,0) -> 8 | G2: 85 | H2: =(E2*F2*(G2/100))/10 -> 12.24 | I2: =VLOOKUP(B2,'CUSTO OPERAÇÃO'!$P$1:$Q$125,2,0) -> 60 | J2: =1/H2 -> 0.081699346 | K2: =I2/H2 -> 4.9019608 | L2: =K2*7.5 -> 36.764706 | M2: =IFERROR(L2/J2,"") -> 450 | O2: AVIÃO AGRICOLA | P2: AIR TRATOR AT-502B | Q2: 120 | R2: 30 | S2: 200
A3: MÁQUINAS | B3: TRATOR - CASE MAGNUM 340 | C3: PLANTADEIRA - CASE ASM 1213 | D3: =IFERROR(__xludf.DUMMYFUNCTION("REGEXREPLACE(B3,""TRATOR - |COLHEITADEIRA |PULVERIZADOR |CAMINHAO-"","""")&"" + ""&REGEXREPLACE(C3,""PLANTADEIRA |PLATAFORMA |DISTRIBUIDOR |PULVERIZADOR "", """")"),"CASE MAGNUM 340 + - CASE ASM 1213") -> CASE MAGNUM 340 + - CASE ASM 1213 | E3: =VLOOKUP(C3,'CUSTO OPERAÇÃO'!$P$1:$S$125,3,0) -> 13 | F3: =VLOOKUP(C3,'CUSTO OPERAÇÃO'!$P$1:$S$125,4,0) -> 7 | G3: 85 | H3: =(E3*F3*(G3/100))/10 -> 7.735 | I3: =VLOOKUP(B3,'CUSTO OPERAÇÃO'!$P$1:$Q$125,2,0) -> 40 | J3: =1/H3 -> 0.12928248 | K3: =I3/H3 -> 5.1712993 | L3: =K3*7.5 -> 38.784745 | M3: =IFERROR(L3/J3,"") -> 300
A4: MÁQUINAS | B4: COLHEITADEIRA CR 8.90 NEW HOLLAND | C4: PLATAFORMA 880 CF45 | D4: =IFERROR(__xludf.DUMMYFUNCTION("REGEXREPLACE(B4,""TRATOR - |COLHEITADEIRA |PULVERIZADOR |CAMINHAO-"","""")&"" + ""&REGEXREPLACE(C4,""PLANTADEIRA |PLATAFORMA |DISTRIBUIDOR |PULVERIZADOR "", """")"),"CR 8.90 NEW HOLLAND + 880 CF45") -> CR 8.90 NEW HOLLAND + 880 CF45 | E4: =VLOOKUP(C4,'CUSTO OPERAÇÃO'!$P$1:$S$125,3,0) -> 13 | F4: =VLOOKUP(C4,'CUSTO OPERAÇÃO'!$P$1:$S$125,4,0) -> 6 | G4: 85 | H4: =(E4*F4*(G4/100))/10 -> 6.63 | I4: =VLOOKUP(B4,'CUSTO OPERAÇÃO'!$P$1:$Q$125,2,0) -> 50 | J4: =1/H4 -> 0.15082956 | K4: =I4/H4 -> 7.5414781 | L4: =K4*7.5 -> 56.561086 | M4: =IFERROR(L4/J4,"") -> 375
A5: MÁQUINAS | B5: COLHETADEIRA - NH-CR9060 | C5: PLATAFORMA 740 CF30 AGRIDREPER | D5: =IFERROR(__xludf.DUMMYFUNCTION("REGEXREPLACE(B5,""TRATOR - |COLHEITADEIRA |PULVERIZADOR |CAMINHAO-"","""")&"" + ""&REGEXREPLACE(C5,""PLANTADEIRA |PLATAFORMA |DISTRIBUIDOR |PULVERIZADOR "", """")"),"COLHETADEIRA - NH-CR9060 + 740 CF30 AGRIDREPER") -> COLHETADEIRA - NH-CR9060 + 740 CF30 AGRIDREPER | E5: =VLOOKUP(C5,'CUSTO OPERAÇÃO'!$P$1:$S$125,3,0) -> 9 | F5: =VLOOKUP(C5,'CUSTO OPERAÇÃO'!$P$1:$S$125,4,0) -> 6 | G5: 85 | H5: =(E5*F5*(G5/100))/10 -> 4.59 | I5: =VLOOKUP(B5,'CUSTO OPERAÇÃO'!$P$1:$Q$125,2,0) -> 40 | J5: =1/H5 -> 0.21786492 | K5: =I5/H5 -> 8.714597 | L5: =K5*7.5 -> 65.359477 | M5: =IFERROR(L5/J5,"") -> 300 | O5: CAMINHÕES | P5: CAMINHAO-VOLVO VM260 | Q5: 20 | R5: 1 | S5: 40
A6: MÁQUINAS | B6: COLHETADEIRA CR7.80 | C6: PLATAFORMA MACDON 35F | D6: =IFERROR(__xludf.DUMMYFUNCTION("REGEXREPLACE(B6,""TRATOR - |COLHEITADEIRA |PULVERIZADOR |CAMINHAO-"","""")&"" + ""&REGEXREPLACE(C6,""PLANTADEIRA |PLATAFORMA |DISTRIBUIDOR |PULVERIZADOR "", """")"),"COLHETADEIRA CR7.80 + MACDON 35F") -> COLHETADEIRA CR7.80 + MACDON 35F | E6: =VLOOKUP(C6,'CUSTO OPERAÇÃO'!$P$1:$S$125,3,0) -> 9 | F6: =VLOOKUP(C6,'CUSTO OPERAÇÃO'!$P$1:$S$125,4,0) -> 6 | G6: 85 | H6: =(E6*F6*(G6/100))/10 -> 4.59 | I6: =VLOOKUP(B6,'CUSTO OPERAÇÃO'!$P$1:$Q$125,2,0) -> 40 | J6: =1/H6 -> 0.21786492 | K6: =I6/H6 -> 8.714597 | L6: =K6*7.5 -> 65.359477 | M6: =IFERROR(L6/J6,"") -> 300 | O6: CAMINHÕES | P6: CAMINHAO-VOLVO NH380 | Q6: 20
A7: MÁQUINAS | B7: TRATOR-JD 7500 | C7: DISTRIBUIDOR BRUTUS 12000 | D7: =IFERROR(__xludf.DUMMYFUNCTION("REGEXREPLACE(B7,""TRATOR - |COLHEITADEIRA |PULVERIZADOR |CAMINHAO-"","""")&"" + ""&REGEXREPLACE(C7,""PLANTADEIRA |PLATAFORMA |DISTRIBUIDOR |PULVERIZADOR "", """")"),"TRATOR-JD 7500 + BRUTUS 12000") -> TRATOR-JD 7500 + BRUTUS 12000 | E7: =VLOOKUP(C7,'CUSTO OPERAÇÃO'!$P$1:$S$125,3,0) -> 6 | F7: =VLOOKUP(C7,'CUSTO OPERAÇÃO'!$P$1:$S$125,4,0) -> 6 | G7: 85 | H7: =(E7*F7*(G7/100))/10 -> 3.06 | I7: =VLOOKUP(B7,'CUSTO OPERAÇÃO'!$P$1:$Q$125,2,0) -> 15 | J7: =1/H7 -> 0.32679739 | K7: =I7/H7 -> 4.9019608 | L7: =K7*7.5 -> 36.764706 | M7: =IFERROR(L7/J7,"") -> 112.5 | O7: CAMINHÕES | P7: CAMINHAO-WV 7.100 | Q7: 20
A8: MÁQUINAS | B8: TRATOR-JD 7500 | C8: DISTRIBUIDOR ADUBADORA HERCULES 10000 | D8: =IFERROR(__xludf.DUMMYFUNCTION("REGEXREPLACE(B8,""TRATOR - |COLHEITADEIRA |PULVERIZADOR |CAMINHAO-"","""")&"" + ""&REGEXREPLACE(C8,""PLANTADEIRA |PLATAFORMA |DISTRIBUIDOR |PULVERIZADOR "", """")"),"TRATOR-JD 7500 + ADUBADORA HERCULES 10000") -> TRATOR-JD 7500 + ADUBADORA HERCULES 10000 | E8: =VLOOKUP(C8,'CUSTO OPERAÇÃO'!$P$1:$S$125,3,0) -> 30 | F8: =VLOOKUP(C8,'CUSTO OPERAÇÃO'!$P$1:$S$125,4,0) -> 8 | G8: 85 | H8: =(E8*F8*(G8/100))/10 -> 20.4 | I8: =VLOOKUP(B8,'CUSTO OPERAÇÃO'!$P$1:$Q$125,2,0) -> 15 | J8: =1/H8 -> 0.049019608 | K8: =I8/H8 -> 0.73529412 | L8: =K8*7.5 -> 5.5147059 | M8: =IFERROR(L8/J8,"") -> 112.5 | O8: CAMINHÕES | P8: CAMINHAO-MB 1313 | Q8: 20
A9: MÁQUINAS | B9: CAMINHAO-VOLVO NH380 | C9: CAÇAMBA 430SC | D9: =IFERROR(__xludf.DUMMYFUNCTION("REGEXREPLACE(B9,""TRATOR - |COLHEITADEIRA |PULVERIZADOR |CAMINHAO-"","""")&"" + ""&REGEXREPLACE(C9,""PLANTADEIRA |PLATAFORMA |DISTRIBUIDOR |PULVERIZADOR "", """")"),"VOLVO NH380 + CAÇAMBA 430SC") -> VOLVO NH380 + CAÇAMBA 430SC | E9: 430 | F9: =VLOOKUP(C9,'CUSTO OPERAÇÃO'!$P$1:$S$125,4,0) -> 20 | G9: 85 | H9: =(E9*F9*(G9/100))/10 -> 731 | I9: =VLOOKUP(B9,'CUSTO OPERAÇÃO'!$P$1:$Q$125,2,0) -> 20 | J9: =1/H9 -> 0.0013679891 | K9: =I9/H9 -> 0.027359781 | L9: =K9*7.5 -> 0.20519836 | M9: =IFERROR(L9/J9,"") -> 150 | O9: CAMINHÕES | P9: CAMINHÃO MB 1620 | Q9: 20
A10: MÁQUINAS | B10: TRATOR - CASE MAGNUM 340 | C10: SUBSOLADOR 11 ASTES | D10: =IFERROR(__xludf.DUMMYFUNCTION("REGEXREPLACE(B10,""TRATOR - |COLHEITADEIRA |PULVERIZADOR |CAMINHAO-"","""")&"" + ""&REGEXREPLACE(C10,""PLANTADEIRA |PLATAFORMA |DISTRIBUIDOR |PULVERIZADOR "", """")"),"CASE MAGNUM 340 + SUBSOLADOR 11 ASTES") -> CASE MAGNUM 340 + SUBSOLADOR 11 ASTES | E10: =VLOOKUP(C10,'CUSTO OPERAÇÃO'!$P$1:$S$125,3,0) -> 5.5 | F10: 4.5 | G10: 85 | H10: =(E10*F10*(G10/100))/10 -> 2.10375 | I10: =VLOOKUP(B10,'CUSTO OPERAÇÃO'!$P$1:$Q$125,2,0) -> 40 | J10: =1/H10 -> 0.47534165 | K10: =I10/H10 -> 19.013666 | L10: =K10*7.5 -> 142.6025 | M10: =IFERROR(L10/J10,"") -> 300 | O10: CARRETA AGRÍCOLA | P10: CAÇAMBA 430SC | R10: 400 | S10: 20
A11: MÁQUINAS | B11: PULVERIZADOR- JD4730 | C11: PULVERIZADOR- JD4730 | D11: =IFERROR(__xludf.DUMMYFUNCTION("REGEXREPLACE(B11,""TRATOR - |COLHEITADEIRA |PULVERIZADOR |CAMINHAO-"","""")&"" + ""&REGEXREPLACE(C11,""PLANTADEIRA |PLATAFORMA |DISTRIBUIDOR |PULVERIZADOR "", """")"),"PULVERIZADOR- JD4730 + PULVERIZADOR- JD4730") -> PULVERIZADOR- JD4730 + PULVERIZADOR- JD4730 | E11: =VLOOKUP(C11,'CUSTO OPERAÇÃO'!$P$1:$S$125,3,0) -> 30 | F11: =VLOOKUP(C11,'CUSTO OPERAÇÃO'!$P$1:$S$125,4,0) -> 20 | G11: 85 | H11: =(E11*F11*(G11/100))/10 -> 51 | I11: =VLOOKUP(B11,'CUSTO OPERAÇÃO'!$P$1:$Q$125,2,0) -> 17 | J11: =1/H11 -> 0.019607843 | K11: =I11/H11 -> 0.33333333 | L11: =K11*7.5 -> 2.5 | M11: =IFERROR(L11/J11,"") -> 127.5
A12: MÁQUINAS | B12: AIR TRATOR AT-502B | C12: AIR TRATOR AT-502B | D12: =IFERROR(__xludf.DUMMYFUNCTION("REGEXREPLACE(B12,""TRATOR - |COLHEITADEIRA |PULVERIZADOR |CAMINHAO-"","""")&"" + ""&REGEXREPLACE(C12,""PLANTADEIRA |PLATAFORMA |DISTRIBUIDOR |PULVERIZADOR "", """")"),"AIR TRATOR AT-502B + AIR TRATOR AT-502B") -> AIR TRATOR AT-502B + AIR TRATOR AT-502B | E12: =VLOOKUP(C12,'CUSTO OPERAÇÃO'!$P$1:$S$125,3,0) -> 30 | F12: =VLOOKUP(C12,'CUSTO OPERAÇÃO'!$P$1:$S$125,4,0) -> 200 | G12: 25 | H12: =(E12*F12*(G12/100))/10 -> 150 | I12: 135 | J12: =1/H12 -> 0.0066666667 | K12: =I12/H12 -> 0.9 | L12: =K12*7.5 -> 6.75 | M12: 5000 | O12: CAMINHÕES | P12: CAMINHÃO-VOLVO FH 540 | Q12: 20
A13: MÁQUINAS | B13: COLHETADEIRA - NH-CR9060 | C13: PLATAFORMA MILHO BRAVA 11 | D13: =IFERROR(__xludf.DUMMYFUNCTION("REGEXREPLACE(B13,""TRATOR - |COLHEITADEIRA |PULVERIZADOR |CAMINHAO-"","""")&"" + ""&REGEXREPLACE(C13,""PLANTADEIRA |PLATAFORMA |DISTRIBUIDOR |PULVERIZADOR "", """")"),"COLHETADEIRA - NH-CR9060 + MILHO BRAVA 11") -> COLHETADEIRA - NH-CR9060 + MILHO BRAVA 11 | E13: =VLOOKUP(C13,'CUSTO OPERAÇÃO'!$P$1:$S$125,3,0) -> 5.5 | F13: =VLOOKUP(C13,'CUSTO OPERAÇÃO'!$P$1:$S$125,4,0) -> 10 | G13: 85 | H13: =(E13*F13*(G13/100))/10 -> 4.675 | I13: =VLOOKUP(B13,'CUSTO OPERAÇÃO'!$P$1:$Q$125,2,0) -> 40 | J13: =1/H13 -> 0.21390374 | K13: =I13/H13 -> 8.5561497 | L13: =K13*7.5 -> 64.171123 | M13: =IFERROR(L13/J13,"") -> 300 | O13: CARRETA AGRÍCOLA | P13: TRANSBORDO SANTAL
A14: MÁQUINAS | B14: TRATOR - NH T7.260 | C14: DISTRIBUIDOR JAN 20000 | D14: =IFERROR(__xludf.DUMMYFUNCTION("REGEXREPLACE(B14,""TRATOR - |COLHEITADEIRA |PULVERIZADOR |CAMINHAO-"","""")&"" + ""&REGEXREPLACE(C14,""PLANTADEIRA |PLATAFORMA |DISTRIBUIDOR |PULVERIZADOR "", """")"),"NH T7.260 + JAN 20000") -> NH T7.260 + JAN 20000 | E14: =VLOOKUP(C14,'CUSTO OPERAÇÃO'!$P$1:$S$125,3,0) -> 15 | F14: =VLOOKUP(C14,'CUSTO OPERAÇÃO'!$P$1:$S$125,4,0) -> 8 | G14: 85 | H14: =(E14*F14*(G14/100))/10 -> 10.2 | I14: =VLOOKUP(B14,'CUSTO OPERAÇÃO'!$P$1:$Q$125,2,0) -> 25 | J14: =1/H14 -> 0.098039216 | K14: =I14/H14 -> 2.4509804 | L14: =K14*7.5 -> 18.382353 | M14: =IFERROR(L14/J14,"") -> 187.5 | O14: CARRETA AGRÍCOLA | P14: REBOQUE 3000 KG- FA
A15: MÁQUINAS | B15: TRATOR - NH T8.355 | C15: PLANTADEIRA - JD2122 | D15: =IFERROR(__xludf.DUMMYFUNCTION("REGEXREPLACE(B15,""TRATOR - |COLHEITADEIRA |PULVERIZADOR |CAMINHAO-"","""")&"" + ""&REGEXREPLACE(C15,""PLANTADEIRA |PLATAFORMA |DISTRIBUIDOR |PULVERIZADOR "", """")"),"NH T8.355 + - JD2122") -> NH T8.355 + - JD2122 | E15: =VLOOKUP(C15,'CUSTO OPERAÇÃO'!$P$1:$S$125,3,0) -> 10.5 | F15: =VLOOKUP(C15,'CUSTO OPERAÇÃO'!$P$1:$S$125,4,0) -> 7 | G15: 85 | H15: =(E15*F15*(G15/100))/10 -> 6.2475 | I15: =VLOOKUP(B15,'CUSTO OPERAÇÃO'!$P$1:$Q$125,2,0) -> 30 | J15: =1/H15 -> 0.16006403 | K15: =I15/H15 -> 4.8019208 | L15: =K15*7.5 -> 36.014406 | M15: =IFERROR(L15/J15,"") -> 225 | O15: CARRETA AGRÍCOLA | P15: CARRETO ADUBO 20000
A16: MÁQUINAS | B16: COLHETADEIRA - CASE 2388 | C16: PLATAFORMA CASE 30PES | D16: =IFERROR(__xludf.DUMMYFUNCTION("REGEXREPLACE(B16,""TRATOR - |COLHEITADEIRA |PULVERIZADOR |CAMINHAO-"","""")&"" + ""&REGEXREPLACE(C16,""PLANTADEIRA |PLATAFORMA |DISTRIBUIDOR |PULVERIZADOR "", """")"),"COLHETADEIRA - CASE 2388 + CASE 30PES") -> COLHETADEIRA - CASE 2388 + CASE 30PES | E16: =VLOOKUP(C16,'CUSTO OPERAÇÃO'!$P$1:$S$125,3,0) -> 9 | F16: =VLOOKUP(C16,'CUSTO OPERAÇÃO'!$P$1:$S$125,4,0) -> 5 | G16: 85 | H16: =(E16*F16*(G16/100))/10 -> 3.825 | I16: =VLOOKUP(B16,'CUSTO OPERAÇÃO'!$P$1:$Q$125,2,0) -> 30 | J16: =1/H16 -> 0.26143791 | K16: =I16/H16 -> 7.8431373 | L16: =K16*7.5 -> 58.823529 | M16: =IFERROR(L16/J16,"") -> 225 | O16: CARRETA AGRÍCOLA | P16: CARRETO ADUBO ESPORA
A17: MÁQUINAS | B17: JACTO UNIPORT 2000 | C17: JACTO UNIPORT 2000 | D17: =IFERROR(__xludf.DUMMYFUNCTION("REGEXREPLACE(B17,""TRATOR - |COLHEITADEIRA |PULVERIZADOR |CAMINHAO-"","""")&"" + ""&REGEXREPLACE(C17,""PLANTADEIRA |PLATAFORMA |DISTRIBUIDOR |PULVERIZADOR "", """")"),"JACTO UNIPORT 2000 + JACTO UNIPORT 2000") -> JACTO UNIPORT 2000 + JACTO UNIPORT 2000 | E17: =VLOOKUP(C17,'CUSTO OPERAÇÃO'!$P$1:$S$125,3,0) -> 24 | F17: =VLOOKUP(C17,'CUSTO OPERAÇÃO'!$P$1:$S$125,4,0) -> 16 | G17: 85 | H17: =(E17*F17*(G17/100))/10 -> 32.64 | I17: =VLOOKUP(B17,'CUSTO OPERAÇÃO'!$P$1:$Q$125,2,0) -> 7 | J17: =1/H17 -> 0.030637255 | K17: =I17/H17 -> 0.21446078 | L17: =K17*7.5 -> 1.6084559 | M17: =IFERROR(L17/J17,"") -> 52.5 | O17: CARRETA AGRÍCOLA | P17: CARRETA PLATAFORMACR7.8
A18: MÁQUINAS | B18: TRATOR - NH T7.260 | C18: PLANTADEIRA CASE 2213 | D18: =IFERROR(__xludf.DUMMYFUNCTION("REGEXREPLACE(B18,""TRATOR - |COLHEITADEIRA |PULVERIZADOR |CAMINHAO-"","""")&"" + ""&REGEXREPLACE(C18,""PLANTADEIRA |PLATAFORMA |DISTRIBUIDOR |PULVERIZADOR "", """")"),"NH T7.260 + CASE 2213") -> NH T7.260 + CASE 2213 | E18: =VLOOKUP(C18,'CUSTO OPERAÇÃO'!$P$1:$S$125,3,0) -> 6.5 | F18: =VLOOKUP(C18,'CUSTO OPERAÇÃO'!$P$1:$S$125,4,0) -> 7 | G18: 85 | H18: =(E18*F18*(G18/100))/10 -> 3.8675 | I18: =VLOOKUP(B18,'CUSTO OPERAÇÃO'!$P$1:$Q$125,2,0) -> 25 | J18: =1/H18 -> 0.25856496 | K18: =I18/H18 -> 6.4641241 | L18: =K18*7.5 -> 48.480931 | M18: =IFERROR(L18/J18,"") -> 187.5 | O18: COLHEDORAS | P18: COLHETADEIRA - NH-CR9060 | Q18: 40
D19: =IFERROR(__xludf.DUMMYFUNCTION("REGEXREPLACE(B19,""TRATOR - |COLHEITADEIRA |PULVERIZADOR |CAMINHAO-"","""")&"" + ""&REGEXREPLACE(C19,""PLANTADEIRA |PLATAFORMA |DISTRIBUIDOR |PULVERIZADOR "", """")")," + ") -> + | E19: =VLOOKUP(C19,'CUSTO OPERAÇÃO'!$P$1:$S$125,3,0) -> #N/A | F19: =VLOOKUP(C19,'CUSTO OPERAÇÃO'!$P$1:$S$125,4,0) -> #N/A | G19: 85 | H19: =(E19*F19*(G19/100))/10 -> #N/A | I19: =VLOOKUP(B19,'CUSTO OPERAÇÃO'!$P$1:$Q$125,2,0) -> #N/A | J19: =1/H19 -> #N/A | K19: =I19/H19 -> #N/A | L19: =K19*7.5 -> #N/A | M19: =IFERROR(L19/J19,"") | O19: COLHEDORAS | P19: COLHETADEIRA - CASE 2388 | Q19: 30
D20: =IFERROR(__xludf.DUMMYFUNCTION("REGEXREPLACE(B20,""TRATOR - |COLHEITADEIRA |PULVERIZADOR |CAMINHAO-"","""")&"" + ""&REGEXREPLACE(C20,""PLANTADEIRA |PLATAFORMA |DISTRIBUIDOR |PULVERIZADOR "", """")")," + ") -> + | E20: =VLOOKUP(C20,'CUSTO OPERAÇÃO'!$P$1:$S$125,3,0) -> #N/A | F20: =VLOOKUP(C20,'CUSTO OPERAÇÃO'!$P$1:$S$125,4,0) -> #N/A | G20: 85 | H20: =(E20*F20*(G20/100))/10 -> #N/A | I20: =VLOOKUP(B20,'CUSTO OPERAÇÃO'!$P$1:$Q$125,2,0) -> #N/A | J20: =1/H20 -> #N/A | K20: =I20/H20 -> #N/A | L20: =K20*7.5 -> #N/A | M20: =IFERROR(L20/J20,"") | O20: COLHEDORAS | P20: COLHEITADEIRA CR 8.90 NEW HOLLAND | Q20: 50
D21: =IFERROR(__xludf.DUMMYFUNCTION("REGEXREPLACE(B21,""TRATOR - |COLHEITADEIRA |PULVERIZADOR |CAMINHAO-"","""")&"" + ""&REGEXREPLACE(C21,""PLANTADEIRA |PLATAFORMA |DISTRIBUIDOR |PULVERIZADOR "", """")")," + ") -> + | E21: =VLOOKUP(C21,'CUSTO OPERAÇÃO'!$P$1:$S$125,3,0) -> #N/A | F21: =VLOOKUP(C21,'CUSTO OPERAÇÃO'!$P$1:$S$125,4,0) -> #N/A | G21: 85 | H21: =(E21*F21*(G21/100))/10 -> #N/A | I21: =VLOOKUP(B21,'CUSTO OPERAÇÃO'!$P$1:$Q$125,2,0) -> #N/A | J21: =1/H21 -> #N/A | K21: =I21/H21 -> #N/A | L21: =K21*7.5 -> #N/A | M21: =IFERROR(L21/J21,"") | O21: COLHEDORAS | P21: COLHETADEIRA CR7.80 | Q21: 40
D22: =IFERROR(__xludf.DUMMYFUNCTION("REGEXREPLACE(B22,""TRATOR - |COLHEITADEIRA |PULVERIZADOR |CAMINHAO-"","""")&"" + ""&REGEXREPLACE(C22,""PLANTADEIRA |PLATAFORMA |DISTRIBUIDOR |PULVERIZADOR "", """")")," + ") -> + | E22: =VLOOKUP(C22,'CUSTO OPERAÇÃO'!$P$1:$S$125,3,0) -> #N/A | F22: =VLOOKUP(C22,'CUSTO OPERAÇÃO'!$P$1:$S$125,4,0) -> #N/A | G22: 85 | H22: =(E22*F22*(G22/100))/10 -> #N/A | I22: =VLOOKUP(B22,'CUSTO OPERAÇÃO'!$P$1:$Q$125,2,0) -> #N/A | J22: =1/H22 -> #N/A | K22: =I22/H22 -> #N/A | L22: =K22*7.5 -> #N/A | M22: =IFERROR(L22/J22,"") | O22: DISTRIBUIDOR FERTILIZANTES | P22: DISTRIBUIDOR BRUTUS 12000 | R22: 6 | S22: 6
D23: =IFERROR(__xludf.DUMMYFUNCTION("REGEXREPLACE(B23,""TRATOR - |COLHEITADEIRA |PULVERIZADOR |CAMINHAO-"","""")&"" + ""&REGEXREPLACE(C23,""PLANTADEIRA |PLATAFORMA |DISTRIBUIDOR |PULVERIZADOR "", """")")," + ") -> + | E23: =VLOOKUP(C23,'CUSTO OPERAÇÃO'!$P$1:$S$125,3,0) -> #N/A | F23: =VLOOKUP(C23,'CUSTO OPERAÇÃO'!$P$1:$S$125,4,0) -> #N/A | G23: 85 | H23: =(E23*F23*(G23/100))/10 -> #N/A | I23: =VLOOKUP(B23,'CUSTO OPERAÇÃO'!$P$1:$Q$125,2,0) -> #N/A | J23: =1/H23 -> #N/A | K23: =I23/H23 -> #N/A | L23: =K23*7.5 -> #N/A | M23: =IFERROR(L23/J23,"") | O23: DISTRIBUIDOR FERTILIZANTES | P23: DISTRIBUIDOR ADUBADORA HERCULES 10000 | R23: 30 | S23: 8
D24: =IFERROR(__xludf.DUMMYFUNCTION("REGEXREPLACE(B24,""TRATOR - |COLHEITADEIRA |PULVERIZADOR |CAMINHAO-"","""")&"" + ""&REGEXREPLACE(C24,""PLANTADEIRA |PLATAFORMA |DISTRIBUIDOR |PULVERIZADOR "", """")")," + ") -> + | E24: =VLOOKUP(C24,'CUSTO OPERAÇÃO'!$P$1:$S$125,3,0) -> #N/A | F24: =VLOOKUP(C24,'CUSTO OPERAÇÃO'!$P$1:$S$125,4,0) -> #N/A | G24: 85 | H24: =(E24*F24*(G24/100))/10 -> #N/A | I24: =VLOOKUP(B24,'CUSTO OPERAÇÃO'!$P$1:$Q$125,2,0) -> #N/A | J24: =1/H24 -> #N/A | K24: =I24/H24 -> #N/A | L24: =K24*7.5 -> #N/A | M24: =IFERROR(L24/J24,"") | O24: DISTRIBUIDOR FERTILIZANTES | P24: DISTRIBUIDOR JAN 20000 | R24: 15 | S24: 8
D25: =IFERROR(__xludf.DUMMYFUNCTION("REGEXREPLACE(B25,""TRATOR - |COLHEITADEIRA |PULVERIZADOR |CAMINHAO-"","""")&"" + ""&REGEXREPLACE(C25,""PLANTADEIRA |PLATAFORMA |DISTRIBUIDOR |PULVERIZADOR "", """")")," + ") -> + | E25: =VLOOKUP(C25,'CUSTO OPERAÇÃO'!$P$1:$S$125,3,0) -> #N/A | F25: =VLOOKUP(C25,'CUSTO OPERAÇÃO'!$P$1:$S$125,4,0) -> #N/A | G25: 85 | H25: =(E25*F25*(G25/100))/10 -> #N/A | I25: =VLOOKUP(B25,'CUSTO OPERAÇÃO'!$P$1:$Q$125,2,0) -> #N/A | J25: =1/H25 -> #N/A | K25: =I25/H25 -> #N/A | L25: =K25*7.5 -> #N/A | M25: =IFERROR(L25/J25,"") | O25: DISTRIBUIDOR FERTILIZANTES | P25: KAMAQ 6000 | R25: 7 | S25: 8
D26: =IFERROR(__xludf.DUMMYFUNCTION("REGEXREPLACE(B26,""TRATOR - |COLHEITADEIRA |PULVERIZADOR |CAMINHAO-"","""")&"" + ""&REGEXREPLACE(C26,""PLANTADEIRA |PLATAFORMA |DISTRIBUIDOR |PULVERIZADOR "", """")")," + ") -> + | E26: =VLOOKUP(C26,'CUSTO OPERAÇÃO'!$P$1:$S$125,3,0) -> #N/A | F26: =VLOOKUP(C26,'CUSTO OPERAÇÃO'!$P$1:$S$125,4,0) -> #N/A | G26: 85 | H26: =(E26*F26*(G26/100))/10 -> #N/A | I26: =VLOOKUP(B26,'CUSTO OPERAÇÃO'!$P$1:$Q$125,2,0) -> #N/A | J26: =1/H26 -> #N/A | K26: =I26/H26 -> #N/A | L26: =K26*7.5 -> #N/A | M26: =IFERROR(L26/J26,"") | O26: EQUIPAMENTOS | P26: BALANÇA CAR. 120/240T/H
D27: =IFERROR(__xludf.DUMMYFUNCTION("REGEXREPLACE(B27,""TRATOR - |COLHEITADEIRA |PULVERIZADOR |CAMINHAO-"","""")&"" + ""&REGEXREPLACE(C27,""PLANTADEIRA |PLATAFORMA |DISTRIBUIDOR |PULVERIZADOR "", """")")," + ") -> + | E27: =VLOOKUP(C27,'CUSTO OPERAÇÃO'!$P$1:$S$125,3,0) -> #N/A | F27: =VLOOKUP(C27,'CUSTO OPERAÇÃO'!$P$1:$S$125,4,0) -> #N/A | G27: 85 | H27: =(E27*F27*(G27/100))/10 -> #N/A | I27: =VLOOKUP(B27,'CUSTO OPERAÇÃO'!$P$1:$Q$125,2,0) -> #N/A | J27: =1/H27 -> #N/A | K27: =I27/H27 -> #N/A | L27: =K27*7.5 -> #N/A | M27: =IFERROR(L27/J27,"") | O27: EQUIPAMENTOS | P27: GUINDASTE HIDRAULICO GRM 14.000
D28: =IFERROR(__xludf.DUMMYFUNCTION("REGEXREPLACE(B28,""TRATOR - |COLHEITADEIRA |PULVERIZADOR |CAMINHAO-"","""")&"" + ""&REGEXREPLACE(C28,""PLANTADEIRA |PLATAFORMA |DISTRIBUIDOR |PULVERIZADOR "", """")")," + ") -> + | E28: =VLOOKUP(C28,'CUSTO OPERAÇÃO'!$P$1:$S$125,3,0) -> #N/A | F28: =VLOOKUP(C28,'CUSTO OPERAÇÃO'!$P$1:$S$125,4,0) -> #N/A | G28: 85 | H28: =(E28*F28*(G28/100))/10 -> #N/A | I28: =VLOOKUP(B28,'CUSTO OPERAÇÃO'!$P$1:$Q$125,2,0) -> #N/A | J28: =1/H28 -> #N/A | K28: =I28/H28 -> #N/A | L28: =K28*7.5 -> #N/A | M28: =IFERROR(L28/J28,"") | O28: EQUIPAMENTOS | P28: EQUIPAMENTOS
D29: =IFERROR(__xludf.DUMMYFUNCTION("REGEXREPLACE(B29,""TRATOR - |COLHEITADEIRA |PULVERIZADOR |CAMINHAO-"","""")&"" + ""&REGEXREPLACE(C29,""PLANTADEIRA |PLATAFORMA |DISTRIBUIDOR |PULVERIZADOR "", """")")," + ") -> + | E29: =VLOOKUP(C29,'CUSTO OPERAÇÃO'!$P$1:$S$125,3,0) -> #N/A | F29: =VLOOKUP(C29,'CUSTO OPERAÇÃO'!$P$1:$S$125,4,0) -> #N/A | G29: 85 | H29: =(E29*F29*(G29/100))/10 -> #N/A | I29: =VLOOKUP(B29,'CUSTO OPERAÇÃO'!$P$1:$Q$125,2,0) -> #N/A | J29: =1/H29 -> #N/A | K29: =I29/H29 -> #N/A | L29: =K29*7.5 -> #N/A | M29: =IFERROR(L29/J29,"") | O29: EQUIPAMENTOS | P29: HANGAR
D30: =IFERROR(__xludf.DUMMYFUNCTION("REGEXREPLACE(B30,""TRATOR - |COLHEITADEIRA |PULVERIZADOR |CAMINHAO-"","""")&"" + ""&REGEXREPLACE(C30,""PLANTADEIRA |PLATAFORMA |DISTRIBUIDOR |PULVERIZADOR "", """")")," + ") -> + | E30: =VLOOKUP(C30,'CUSTO OPERAÇÃO'!$P$1:$S$125,3,0) -> #N/A | F30: =VLOOKUP(C30,'CUSTO OPERAÇÃO'!$P$1:$S$125,4,0) -> #N/A | G30: 85 | H30: =(E30*F30*(G30/100))/10 -> #N/A | I30: =VLOOKUP(B30,'CUSTO OPERAÇÃO'!$P$1:$Q$125,2,0) -> #N/A | J30: =1/H30 -> #N/A | K30: =I30/H30 -> #N/A | L30: =K30*7.5 -> #N/A | M30: =IFERROR(L30/J30,"") | O30: EQUIPAMENTOS | P30: GERADOR GMG 500 KVA
O31: EQUIPAMENTOS | P31: LARANJA
O32: EQUIPAMENTOS | P32: IRRIGAÇÃO LARANJA
O33: EQUIPAMENTOS | P33: BALANÇA DE FLUXO
O34: EQUIPAMENTOS | P34: LÂMINA TRASEIRA STARA 5000
O35: EQUIPAMENTOS | P35: MIAC DOBLE IV
O36: EQUIPAMENTOS | P36: EMBUTIDORA SILO BOLSA - ESPORA
O37: EQUIPAMENTOS | P37: EXTRATORA SILO BOLSA
O38: EQUIPAMENTOS | P38: GRUPO GERADOR CAT 130KWA
O39: EQUIPAMENTOS | P39: GRUPO GERADOR CUMINS 130KWA
O40: EQUIPAMENTOS | P40: PRÉ-LIMPEZA 40 TON
...

Sheet DRE ORÇADA
B1: SOJA - 02 COQ | J1: SOJA - 02 COQ | L1: SOJA - 02 COQ | N1: SOJA - 02 COQ | P1: SOJA - 02 COQ
A2: ORÇAMENTO SAFRA 2026/2027 | B2: ='PORTIFÓLIO'!$J$3 -> FE-BRACHIARIA-26/27 | D2: ='PORTIFÓLIO'!$K$3 -> FE-SOJA IRRIGADO-26/27 | F2: ='PORTIFÓLIO'!$L$3 -> FE-SOJA SEQUEIRO-26/27 | H2: ='PORTIFÓLIO'!$M$3 -> FA-MILHO SEMENTE-27/27 | J2: ='PORTIFÓLIO'!$N$3 -> FA-SORGO SEQUEIRO-27/27 | L2: ='PORTIFÓLIO'!$O$3 -> FA-MILHO SEQUEIRO-26/27 | N2: ='PORTIFÓLIO'!$P$3 -> FA-SOJA SEQUEIRO-26/27 | P2: ='PORTIFÓLIO'!$Q$3 -> FA-SOJA-IRRIGADO-26/27 | R2: TOTAL
C3: R$/ Ha | E3: R$/ Ha | G3: R$/ Ha | I3: R$/ Ha | K3: R$/ Ha | M3: R$/ Ha | O3: R$/ Ha | Q3: R$/ Ha | S3: R$/ Ha
A4: ÁREA | B4: =SUMIF('ÁREA PLANTIO'!$C$2:$C$30,"*"&B2&"*",'ÁREA PLANTIO'!$E$2:$E$30)+SUMIF('ÁREA PLANTIO'!$H$2:$H$30,"*"&B2&"*",'ÁREA PLANTIO'!$E$2:$E$30) -> 490 | D4: =SUMIF('ÁREA PLANTIO'!$C$2:$C$30,"*"&D2&"*",'ÁREA PLANTIO'!$E$2:$E$30)+SUMIF('ÁREA PLANTIO'!$H$2:$H$30,"*"&D2&"*",'ÁREA PLANTIO'!$E$2:$E$30) -> 300 | F4: =SUMIF('ÁREA PLANTIO'!$C$2:$C$30,"*"&F2&"*",'ÁREA PLANTIO'!$E$2:$E$30)+SUMIF('ÁREA PLANTIO'!$H$2:$H$30,"*"&F2&"*",'ÁREA PLANTIO'!$E$2:$E$30) -> 220 | H4: =SUMIF('ÁREA PLANTIO'!$C$2:$C$30,"*"&H2&"*",'ÁREA PLANTIO'!$E$2:$E$30)+SUMIF('ÁREA PLANTIO'!$H$2:$H$30,"*"&H2&"*",'ÁREA PLANTIO'!$E$2:$E$30) -> 200 | J4: =SUMIF('ÁREA PLANTIO'!$C$2:$C$30,"*"&J2&"*",'ÁREA PLANTIO'!$E$2:$E$30)+SUMIF('ÁREA PLANTIO'!$H$2:$H$30,"*"&J2&"*",'ÁREA PLANTIO'!$E$2:$E$30) -> 376 | L4: =SUMIF('ÁREA PLANTIO'!$C$2:$C$30,"*"&L2&"*",'ÁREA PLANTIO'!$E$2:$E$30)+SUMIF('ÁREA PLANTIO'!$H$2:$H$30,"*"&L2&"*",'ÁREA PLANTIO'!$E$2:$E$30) -> 220 | N4: =SUMIF('ÁREA PLANTIO'!$C$2:$C$30,"*"&N2&"*",'ÁREA PLANTIO'!$E$2:$E$30)+SUMIF('ÁREA PLANTIO'!$H$2:$H$30,"*"&N2&"*",'ÁREA PLANTIO'!$E$2:$E$30) -> 1218 | P4: =SUMIF('ÁREA PLANTIO'!$C$2:$C$30,"*"&P2&"*",'ÁREA PLANTIO'!$E$2:$E$30)+SUMIF('ÁREA PLANTIO'!$H$2:$H$30,"*"&P2&"*",'ÁREA PLANTIO'!$E$2:$E$30) -> 320 | R4: =SUM(P4,N4,L4,J4,B4,D4,F4,H4) -> 3344
A5: PRODUÇÃO TOTAL | B5: =SUMIF('ÁREA PLANTIO'!$C$2:$C$30,"*"&B2&"*",'ÁREA PLANTIO'!$F$2:$F$30)+SUMIF('ÁREA PLANTIO'!$H$2:$H$30,"*"&B2&"*",'ÁREA PLANTIO'!$J$2:$J$30) -> 28550 | D5: =SUMIF('ÁREA PLANTIO'!$C$2:$C$30,"*"&D2&"*",'ÁREA PLANTIO'!$F$2:$F$30)+SUMIF('ÁREA PLANTIO'!$H$2:$H$30,"*"&D2&"*",'ÁREA PLANTIO'!$J$2:$J$30) -> 18900 | F5: =SUMIF('ÁREA PLANTIO'!$C$2:$C$30,"*"&F2&"*",'ÁREA PLANTIO'!$F$2:$F$30)+SUMIF('ÁREA PLANTIO'!$H$2:$H$30,"*"&F2&"*",'ÁREA PLANTIO'!$J$2:$J$30) -> 11000 | H5: =SUMIF('ÁREA PLANTIO'!$C$2:$C$30,"*"&H2&"*",'ÁREA PLANTIO'!$F$2:$F$30)+SUMIF('ÁREA PLANTIO'!$H$2:$H$30,"*"&H2&"*",'ÁREA PLANTIO'!$J$2:$J$30) -> 40000 | J5: =SUMIF('ÁREA PLANTIO'!$C$2:$C$30,"*"&J2&"*",'ÁREA PLANTIO'!$F$2:$F$30)+SUMIF('ÁREA PLANTIO'!$H$2:$H$30,"*"&J2&"*",'ÁREA PLANTIO'!$J$2:$J$30) -> 22560 | L5: =SUMIF('ÁREA PLANTIO'!$C$2:$C$30,"*"&L2&"*",'ÁREA PLANTIO'!$F$2:$F$30)+SUMIF('ÁREA PLANTIO'!$H$2:$H$30,"*"&L2&"*",'ÁREA PLANTIO'!$J$2:$J$30) -> 39600 | N5: =SUMIF('ÁREA PLANTIO'!$C$2:$C$30,"*"&N2&"*",'ÁREA PLANTIO'!$F$2:$F$30)+SUMIF('ÁREA PLANTIO'!$H$2:$H$30,"*"&N2&"*",'ÁREA PLANTIO'!$J$2:$J$30) -> 85260 | P5: =SUMIF('ÁREA PLANTIO'!$C$2:$C$30,"*"&P2&"*",'ÁREA PLANTIO'!$F$2:$F$30)+SUMIF('ÁREA PLANTIO'!$H$2:$H$30,"*"&P2&"*",'ÁREA PLANTIO'!$J$2:$J$30) -> 22400
A6: PRODUÇÃO P/HA | B6: =B5/B4 -> 58.265306 | D6: =IFERROR(D5/D4,"") -> 63 | F6: =IFERROR(F5/F4,"") -> 50 | H6: =IFERROR(H5/H4,"") -> 200 | J6: =IFERROR(J5/J4,"") -> 60 | L6: =IFERROR(L5/L4,"") -> 180 | N6: =IFERROR(N5/N4,"") -> 70 | P6: =IFERROR(P5/P4,"") -> 70
A7: PREÇO MÉDIO | B7: 200 | D7: 110 | F7: 110 | H7: 60 | J7: 48 | L7: 60 | N7: 110 | P7: 110 | S7: =R7/$R$4 -> 0
A8: RECEITA ARRENDAMENTO | S8: =R8/$R$4 -> 0
A9: RECEITA BRUTA | B9: =B5*B7 -> 5710000 | C9: =IFERROR(B9/B4,"") -> 11653.061 | D9: =D5*D7 -> 2079000 | E9: =IFERROR(D9/D4,"") -> 6930 | F9: =F5*F7 -> 1210000 | G9: =IFERROR(F9/F4,"") -> 5500 | H9: =H5*H7 -> 2400000 | I9: =IFERROR(H9/H4,"") -> 12000 | J9: =J5*J7 -> 1082880 | K9: =IFERROR(J9/J4,"") -> 2880 | L9: =L5*L7 -> 2376000 | M9: =IFERROR(L9/L4,"") -> 10800 | N9: =N5*N7 -> 9378600 | O9: =IFERROR(N9/N4,"") -> 7700 | P9: =P5*P7 -> 2464000 | Q9: =IFERROR(P9/P4,"") -> 7700 | R9: =SUM(P9,N9,L9,J9,H9,D9,B9) -> 25490480 | S9: =IFERROR(R9/R4,"") -> 7622.7512
A10: SAÍDAS TOTAIS | B10: =SUM(B11,B465,B546,B555,B557) -> 356781.39 | C10: =B10/B4 -> 728.12528 | D10: =SUM(D11,D465,D546,D555,D557) -> 436954.42 | E10: =IFERROR(D10/D4,"") -> 1456.5147 | F10: =SUM(F11,F465,F546,F555,F557) -> 312894.8 | G10: =IFERROR(F10/F4,"") -> 1422.2491 | H10: =SUM(H11,H465,H546,H555,H557) -> 42925.506 | I10: =IFERROR(H10/H4,"") -> 214.62753 | J10: =SUM(J11,J465,J546,J555,J557) -> 123127.98 | K10: =IFERROR(J10/J4,"") -> 327.46803 | L10: =SUM(L11,L465,L546,L555,L557) -> 292129.39 | M10: =IFERROR(L10/L4,"") -> 1327.8609 | N10: =SUM(N11,N465,N546,N555,N557) -> 1814506.5 | O10: =IFERROR(N10/N4,"") -> 1489.7426 | P10: =SUM(P11,P465,P546,P555,P557) -> 496103.82 | Q10: =IFERROR(P10/P4,"") -> 1550.3244 | R10: =SUM(P10,N10,L10,J10,H10,D10,B10) -> 3562529 | S10: =R10/$R$4 -> 1065.3496
A11: CUSTOS DIRETOS | B11: =SUM(B12,B421,B458,B459,B460,B461,B462) -> 356781.39 | C11: =B11/$B$4 -> 728.12528 | D11: =SUM(D12,D421,D458,D459,D460,D461,D462) -> 436954.42 | E11: =D11/$D$4 -> 1456.5147 | F11: =SUM(F12,F421,F458,F459,F460,F461,F462) -> 312894.8 | G11: =F11/$F$4 -> 1422.2491 | H11: =SUM(H12,H421,H458,H459,H460,H461,H462) -> 42925.506 | I11: =IFERROR(H11/$H$4,"") -> 214.62753 | J11: =SUM(J12,J421,J458,J459,J460,J461,J462) -> 123127.98 | K11: =J11/$J$4 -> 327.46803 | L11: =SUM(L12,L421,L458,L459,L460,L461,L462) -> 292129.39 | M11: 4221 | N11: =SUM(N12,N421,N458,N459,N460,N461,N462) -> 1814506.5 | O11: 4221 | P11: =SUM(P12,P421,P458,P459,P460,P461,P462) -> 496103.82 | Q11: 4221 | R11: =SUM(P11,N11,L11,J11,H11,D11,B11) -> 3562529 | S11: =R11/$R$4 -> 1065.3496
A12: CUSTOS INSUMOS | B12: =B13+B32+B104+B175+B256+B293+B322+B340 -> 323903.69 | C12: =IFERROR(B12/$B$4,"") -> 661.02794 | D12: =D13+D32+D104+D175+D256+D293+D322+D340 -> 334976.77 | E12: =IFERROR(D12/$D$4,"") -> 1116.5892 | F12: =F13+F32+F104+F175+F256+F293+F322+F340 -> 238111.19 | G12: =IFERROR(F12/$F$4,"") -> 1082.3236 | H12: =H13+H32+H104+H175+H256+H293+H322+H340 -> 42925.506 | I12: =IFERROR(H12/$H$4,"") -> 214.62753 | J12: =J13+J32+J104+J175+J256+J293+J322+J340 -> 123127.98 | K12: =IFERROR(J12/$J$4,"") -> 327.46803 | L12: =L13+L32+L104+L175+L256+L293+L322+L340 -> 193459.39 | M12: =IFERROR(L12/$L$4,"") -> 879.36086 | N12: =N13+N32+N104+N175+N256+N293+N322+N340 -> 1400477.2 | O12: =IFERROR(N12/$N$4,"") -> 1149.8171 | P12: =P13+P32+P104+P175+P256+P293+P322+P340 -> 387327.66 | Q12: =IFERROR(P12/$P$4,"") -> 1210.3989 | R12: =SUM(P12,N12,L12,J12,H12,D12,B12) -> 2806198.2 | S12: =IFERROR(R12/$R$4,"") -> 839.17411
A13: FERTILIZANTES | B13: =SUM(B14:B31) -> 0 | C13: =B13/$B$4 -> 0 | D13: =SUM(D14:D31) -> 0 | E13: =D13/$D$4 -> 0 | F13: =SUM(F14:F31) -> 0 | G13: =F13/$F$4 -> 0 | H13: =SUM(H14:H31) -> 0 | I13: =H13/$H$4 -> 0 | J13: =SUM(J14:J31) -> 0 | K13: =J13/$J$4 -> 0 | L13: =SUM(L14:L31) -> 0 | M13: =L13/$L$4 -> 0 | N13: =SUM(N14:N31) -> 0 | O13: =N13/$N$4 -> 0 | P13: =SUM(P14:P31) -> 0 | Q13: =P13/$P$4 -> 0 | R13: =SUM(P13,N13,L13,J13,H13,D13,B13) -> 0 | S13: =R13/$R$4 -> 0
A14: =IFERROR(__xludf.DUMMYFUNCTION("UNIQUE(FILTER('PORTIFÓLIO'!C:C, 'PORTIFÓLIO'!B:B=""fertilizantes""))"),"I-ACTIVE") -> I-ACTIVE | B14: {=IFERROR( SUM( IF( 'PORTIFÓLIO'!$C$4:$C$564=$A14, N(INDEX('PORTIFÓLIO'!$J$4:$Q$564,,MATCH(B$2,'PORTIFÓLIO'!$J$3:$Q$3,0))) * N('PORTIFÓLIO'!$S$4:$S$564), 0 ) ), 0)} -> 0 | C14: =B14/$B$4 -> 0 | D14: {=IFERROR( SUM( IF( 'PORTIFÓLIO'!$C$4:$C$564=$A14, N(INDEX('PORTIFÓLIO'!$J$4:$Q$564,,MATCH(D$2,'PORTIFÓLIO'!$J$3:$Q$3,0))) * N('PORTIFÓLIO'!$S$4:$S$564), 0 ) ), 0)} -> 0 | E14: =D14/$D$4 -> 0 | F14: {=IFERROR( SUM( IF( 'PORTIFÓLIO'!$C$4:$C$564=$A14, N(INDEX('PORTIFÓLIO'!$J$4:$Q$564,,MATCH(F$2,'PORTIFÓLIO'!$J$3:$Q$3,0))) * N('PORTIFÓLIO'!$S$4:$S$564), 0 ) ), 0)} -> 0 | G14: =F14/$F$4 -> 0 | H14: {=IFERROR( SUM( IF( 'PORTIFÓLIO'!$C$4:$C$564=$A14, N(INDEX('PORTIFÓLIO'!$J$4:$Q$564,,MATCH(H$2,'PORTIFÓLIO'!$J$3:$Q$3,0))) * N('PORTIFÓLIO'!$S$4:$S$564), 0 ) ), 0)} -> 0 | I14: =H14/$H$4 -> 0 | J14: {=IFERROR( SUM( IF( 'PORTIFÓLIO'!$C$4:$C$564=$A14, N(INDEX('PORTIFÓLIO'!$J$4:$Q$564,,MATCH(J$2,'PORTIFÓLIO'!$J$3:$Q$3,0))) * N('PORTIFÓLIO'!$S$4:$S$564), 0 ) ), 0)} -> 0 | K14: =J14/$J$4 -> 0 | L14: {=IFERROR( SUM( IF( 'PORTIFÓLIO'!$C$4:$C$564=$A14, N(INDEX('PORTIFÓLIO'!$J$4:$Q$564,,MATCH(L$2,'PORTIFÓLIO'!$J$3:$Q$3,0))) * N('PORTIFÓLIO'!$S$4:$S$564), 0 ) ), 0)} -> 0 | M14: =L14/$L$4 -> 0 | N14: {=IFERROR( SUM( IF( 'PORTIFÓLIO'!$C$4:$C$564=$A14, N(INDEX('PORTIFÓLIO'!$J$4:$Q$564,,MATCH(N$2,'PORTIFÓLIO'!$J$3:$Q$3,0))) * N('PORTIFÓLIO'!$S$4:$S$564), 0 ) ), 0)} -> 0 | O14: =N14/$N$4 -> 0 | P14: {=IFERROR( SUM( IF( 'PORTIFÓLIO'!$C$4:$C$564=$A14, N(INDEX('PORTIFÓLIO'!$J$4:$Q$564,,MATCH(P$2,'PORTIFÓLIO'!$J$3:$Q$3,0))) * N('PORTIFÓLIO'!$S$4:$S$564), 0 ) ), 0)} -> 0 | Q14: =P14/$P$4 -> 0 | R14: =SUM(P14,N14,L14,J14,H14,D14,B14) -> 0 | S14: =R14/$R$4 -> 0
