Workbook
Name HERBICIDA: LISTA!$B$2:$B$1000
Name FUNGICIDA: LISTA!$A$2:$A$1000
Name TS: LISTA!$D$2:$D$1000
Name TL01_IMPRESSAO: 'TL01'!$A$1:$L$226
Name CORRETIVOS: LISTA!$I$2:$I$1000
Name FERTILIZANTES: LISTA!$H$2:$H$1000
Name INSETICIDA: LISTA!$C$2:$C$1000
Name SEMENTE: LISTA!$F$2:$F$1000

Sheet DEMANDA DE COMPRAS
A1: DEMANDA DE COMPRAS DE INSUMOS — SAFRA 2026/2027
A2: A COMPRAR = MÁX(0; Demanda − Estoque). Demanda e preço vêm da aba PORTIFÓLIO; edite o ESTOQUE na PORTIFÓLIO (coluna T) que esta lista atualiza sozinha.
A3: TOTAL A COMPRAR (R$) | C3: ITENS A COMPRAR | E3: ITENS SEM PREÇO | G3: VALOR EM ESTOQUE (R$)
A4: =SUM(I6:I82) | C4: =COUNTIF(G6:G82,">0") | E4: =SUMPRODUCT((G6:G82>0)*(H6:H82<=0)) | G4: =SUMPRODUCT(F6:F82,H6:H82)
A5: CLASSE | B5: FORNECEDOR | C5: PRODUTO | D5: UN | E5: DEMANDA | F5: ESTOQUE | G5: A COMPRAR | H5: PREÇO UNIT. | I5: VALOR TOTAL | J5: STATUS | L5: RESUMO POR CLASSE
A6: ='PORTIFÓLIO'!B7 | B6: ='PORTIFÓLIO'!A7 | C6: ='PORTIFÓLIO'!C7 | D6: ='PORTIFÓLIO'!F7 | E6: ='PORTIFÓLIO'!R7 | F6: ='PORTIFÓLIO'!T7 | G6: =MAX(0,E6-F6) | H6: ='PORTIFÓLIO'!S7 | I6: =G6*H6 | J6: =IF(G6>0,IF(H6<=0,"⚠ SEM PREÇO","COMPRAR"),IF(E6>0,"OK - ESTOQUE","SEM DEMANDA")) | L6: ADJUVANTE | M6: =SUMIF($A$6:$A$82,L6,$I$6:$I$82)
A7: ='PORTIFÓLIO'!B8 | B7: ='PORTIFÓLIO'!A8 | C7: ='PORTIFÓLIO'!C8 | D7: ='PORTIFÓLIO'!F8 | E7: ='PORTIFÓLIO'!R8 | F7: ='PORTIFÓLIO'!T8 | G7: =MAX(0,E7-F7) | H7: ='PORTIFÓLIO'!S8 | I7: =G7*H7 | J7: =IF(G7>0,IF(H7<=0,"⚠ SEM PREÇO","COMPRAR"),IF(E7>0,"OK - ESTOQUE","SEM DEMANDA")) | L7: BIOLÓGICOS | M7: =SUMIF($A$6:$A$82,L7,$I$6:$I$82)
A8: ='PORTIFÓLIO'!B4 | B8: ='PORTIFÓLIO'!A4 | C8: ='PORTIFÓLIO'!C4 | D8: ='PORTIFÓLIO'!F4 | E8: ='PORTIFÓLIO'!R4 | F8: ='PORTIFÓLIO'!T4 | G8: =MAX(0,E8-F8) | H8: ='PORTIFÓLIO'!S4 | I8: =G8*H8 | J8: =IF(G8>0,IF(H8<=0,"⚠ SEM PREÇO","COMPRAR"),IF(E8>0,"OK - ESTOQUE","SEM DEMANDA")) | L8: CORRETIVOS | M8: =SUMIF($A$6:$A$82,L8,$I$6:$I$82)
A9: ='PORTIFÓLIO'!B360 | B9: ='PORTIFÓLIO'!A360 | C9: ='PORTIFÓLIO'!C360 | D9: ='PORTIFÓLIO'!F360 | E9: ='PORTIFÓLIO'!R360 | F9: ='PORTIFÓLIO'!T360 | G9: =MAX(0,E9-F9) | H9: ='PORTIFÓLIO'!S360 | I9: =G9*H9 | J9: =IF(G9>0,IF(H9<=0,"⚠ SEM PREÇO","COMPRAR"),IF(E9>0,"OK - ESTOQUE","SEM DEMANDA")) | L9: FERTILIZANTES | M9: =SUMIF($A$6:$A$82,L9,$I$6:$I$82)
A10: ='PORTIFÓLIO'!B368 | B10: ='PORTIFÓLIO'!A368 | C10: ='PORTIFÓLIO'!C368 | D10: ='PORTIFÓLIO'!F368 | E10: ='PORTIFÓLIO'!R368 | F10: ='PORTIFÓLIO'!T368 | G10: =MAX(0,E10-F10) | H10: ='PORTIFÓLIO'!S368 | I10: =G10*H10 | J10: =IF(G10>0,IF(H10<=0,"⚠ SEM PREÇO","COMPRAR"),IF(E10>0,"OK - ESTOQUE","SEM DEMANDA")) | L10: FUNGICIDA | M10: =SUMIF($A$6:$A$82,L10,$I$6:$I$82)
A11: ='PORTIFÓLIO'!B361 | B11: ='PORTIFÓLIO'!A361 | C11: ='PORTIFÓLIO'!C361 | D11: ='PORTIFÓLIO'!F361 | E11: ='PORTIFÓLIO'!R361 | F11: ='PORTIFÓLIO'!T361 | G11: =MAX(0,E11-F11) | H11: ='PORTIFÓLIO'!S361 | I11: =G11*H11 | J11: =IF(G11>0,IF(H11<=0,"⚠ SEM PREÇO","COMPRAR"),IF(E11>0,"OK - ESTOQUE","SEM DEMANDA")) | L11: HERBICIDA | M11: =SUMIF($A$6:$A$82,L11,$I$6:$I$82)
A12: ='PORTIFÓLIO'!B22 | B12: ='PORTIFÓLIO'!A22 | C12: ='PORTIFÓLIO'!C22 | D12: ='PORTIFÓLIO'!F22 | E12: ='PORTIFÓLIO'!R22 | F12: ='PORTIFÓLIO'!T22 | G12: =MAX(0,E12-F12) | H12: ='PORTIFÓLIO'!S22 | I12: =G12*H12 | J12: =IF(G12>0,IF(H12<=0,"⚠ SEM PREÇO","COMPRAR"),IF(E12>0,"OK - ESTOQUE","SEM DEMANDA")) | L12: INSETICIDA | M12: =SUMIF($A$6:$A$82,L12,$I$6:$I$82)
A13: ='PORTIFÓLIO'!B38 | B13: ='PORTIFÓLIO'!A38 | C13: ='PORTIFÓLIO'!C38 | D13: ='PORTIFÓLIO'!F38 | E13: ='PORTIFÓLIO'!R38 | F13: ='PORTIFÓLIO'!T38 | G13: =MAX(0,E13-F13) | H13: ='PORTIFÓLIO'!S38 | I13: =G13*H13 | J13: =IF(G13>0,IF(H13<=0,"⚠ SEM PREÇO","COMPRAR"),IF(E13>0,"OK - ESTOQUE","SEM DEMANDA")) | L13: NUTRIÇÃO | M13: =SUMIF($A$6:$A$82,L13,$I$6:$I$82)
A14: ='PORTIFÓLIO'!B36 | B14: ='PORTIFÓLIO'!A36 | C14: ='PORTIFÓLIO'!C36 | D14: ='PORTIFÓLIO'!F36 | E14: ='PORTIFÓLIO'!R36 | F14: ='PORTIFÓLIO'!T36 | G14: =MAX(0,E14-F14) | H14: ='PORTIFÓLIO'!S36 | I14: =G14*H14 | J14: =IF(G14>0,IF(H14<=0,"⚠ SEM PREÇO","COMPRAR"),IF(E14>0,"OK - ESTOQUE","SEM DEMANDA")) | L14: SEMENTE | M14: =SUMIF($A$6:$A$82,L14,$I$6:$I$82)
A15: ='PORTIFÓLIO'!B28 | B15: ='PORTIFÓLIO'!A28 | C15: ='PORTIFÓLIO'!C28 | D15: ='PORTIFÓLIO'!F28 | E15: ='PORTIFÓLIO'!R28 | F15: ='PORTIFÓLIO'!T28 | G15: =MAX(0,E15-F15) | H15: ='PORTIFÓLIO'!S28 | I15: =G15*H15 | J15: =IF(G15>0,IF(H15<=0,"⚠ SEM PREÇO","COMPRAR"),IF(E15>0,"OK - ESTOQUE","SEM DEMANDA")) | L15: TS | M15: =SUMIF($A$6:$A$82,L15,$I$6:$I$82)
A16: ='PORTIFÓLIO'!B26 | B16: ='PORTIFÓLIO'!A26 | C16: ='PORTIFÓLIO'!C26 | D16: ='PORTIFÓLIO'!F26 | E16: ='PORTIFÓLIO'!R26 | F16: ='PORTIFÓLIO'!T26 | G16: =MAX(0,E16-F16) | H16: ='PORTIFÓLIO'!S26 | I16: =G16*H16 | J16: =IF(G16>0,IF(H16<=0,"⚠ SEM PREÇO","COMPRAR"),IF(E16>0,"OK - ESTOQUE","SEM DEMANDA")) | L16: TOTAL | M16: =SUM(M6:M15)
A17: ='PORTIFÓLIO'!B30 | B17: ='PORTIFÓLIO'!A30 | C17: ='PORTIFÓLIO'!C30 | D17: ='PORTIFÓLIO'!F30 | E17: ='PORTIFÓLIO'!R30 | F17: ='PORTIFÓLIO'!T30 | G17: =MAX(0,E17-F17) | H17: ='PORTIFÓLIO'!S30 | I17: =G17*H17 | J17: =IF(G17>0,IF(H17<=0,"⚠ SEM PREÇO","COMPRAR"),IF(E17>0,"OK - ESTOQUE","SEM DEMANDA"))
A18: ='PORTIFÓLIO'!B33 | B18: ='PORTIFÓLIO'!A33 | C18: ='PORTIFÓLIO'!C33 | D18: ='PORTIFÓLIO'!F33 | E18: ='PORTIFÓLIO'!R33 | F18: ='PORTIFÓLIO'!T33 | G18: =MAX(0,E18-F18) | H18: ='PORTIFÓLIO'!S33 | I18: =G18*H18 | J18: =IF(G18>0,IF(H18<=0,"⚠ SEM PREÇO","COMPRAR"),IF(E18>0,"OK - ESTOQUE","SEM DEMANDA"))
A19: ='PORTIFÓLIO'!B35 | B19: ='PORTIFÓLIO'!A35 | C19: ='PORTIFÓLIO'!C35 | D19: ='PORTIFÓLIO'!F35 | E19: ='PORTIFÓLIO'!R35 | F19: ='PORTIFÓLIO'!T35 | G19: =MAX(0,E19-F19) | H19: ='PORTIFÓLIO'!S35 | I19: =G19*H19 | J19: =IF(G19>0,IF(H19<=0,"⚠ SEM PREÇO","COMPRAR"),IF(E19>0,"OK - ESTOQUE","SEM DEMANDA"))
A20: ='PORTIFÓLIO'!B32 | B20: ='PORTIFÓLIO'!A32 | C20: ='PORTIFÓLIO'!C32 | D20: ='PORTIFÓLIO'!F32 | E20: ='PORTIFÓLIO'!R32 | F20: ='PORTIFÓLIO'!T32 | G20: =MAX(0,E20-F20) | H20: ='PORTIFÓLIO'!S32 | I20: =G20*H20 | J20: =IF(G20>0,IF(H20<=0,"⚠ SEM PREÇO","COMPRAR"),IF(E20>0,"OK - ESTOQUE","SEM DEMANDA"))
A21: ='PORTIFÓLIO'!B59 | B21: ='PORTIFÓLIO'!A59 | C21: ='PORTIFÓLIO'!C59 | D21: ='PORTIFÓLIO'!F59 | E21: ='PORTIFÓLIO'!R59 | F21: ='PORTIFÓLIO'!T59 | G21: =MAX(0,E21-F21) | H21: ='PORTIFÓLIO'!S59 | I21: =G21*H21 | J21: =IF(G21>0,IF(H21<=0,"⚠ SEM PREÇO","COMPRAR"),IF(E21>0,"OK - ESTOQUE","SEM DEMANDA"))
A22: ='PORTIFÓLIO'!B40 | B22: ='PORTIFÓLIO'!A40 | C22: ='PORTIFÓLIO'!C40 | D22: ='PORTIFÓLIO'!F40 | E22: ='PORTIFÓLIO'!R40 | F22: ='PORTIFÓLIO'!T40 | G22: =MAX(0,E22-F22) | H22: ='PORTIFÓLIO'!S40 | I22: =G22*H22 | J22: =IF(G22>0,IF(H22<=0,"⚠ SEM PREÇO","COMPRAR"),IF(E22>0,"OK - ESTOQUE","SEM DEMANDA"))
A23: ='PORTIFÓLIO'!B43 | B23: ='PORTIFÓLIO'!A43 | C23: ='PORTIFÓLIO'!C43 | D23: ='PORTIFÓLIO'!F43 | E23: ='PORTIFÓLIO'!R43 | F23: ='PORTIFÓLIO'!T43 | G23: =MAX(0,E23-F23) | H23: ='PORTIFÓLIO'!S43 | I23: =G23*H23 | J23: =IF(G23>0,IF(H23<=0,"⚠ SEM PREÇO","COMPRAR"),IF(E23>0,"OK - ESTOQUE","SEM DEMANDA"))
A24: ='PORTIFÓLIO'!B93 | B24: ='PORTIFÓLIO'!A93 | C24: ='PORTIFÓLIO'!C93 | D24: ='PORTIFÓLIO'!F93 | E24: ='PORTIFÓLIO'!R93 | F24: ='PORTIFÓLIO'!T93 | G24: =MAX(0,E24-F24) | H24: ='PORTIFÓLIO'!S93 | I24: =G24*H24 | J24: =IF(G24>0,IF(H24<=0,"⚠ SEM PREÇO","COMPRAR"),IF(E24>0,"OK - ESTOQUE","SEM DEMANDA"))
A25: ='PORTIFÓLIO'!B65 | B25: ='PORTIFÓLIO'!A65 | C25: ='PORTIFÓLIO'!C65 | D25: ='PORTIFÓLIO'!F65 | E25: ='PORTIFÓLIO'!R65 | F25: ='PORTIFÓLIO'!T65 | G25: =MAX(0,E25-F25) | H25: ='PORTIFÓLIO'!S65 | I25: =G25*H25 | J25: =IF(G25>0,IF(H25<=0,"⚠ SEM PREÇO","COMPRAR"),IF(E25>0,"OK - ESTOQUE","SEM DEMANDA"))
A26: ='PORTIFÓLIO'!B95 | B26: ='PORTIFÓLIO'!A95 | C26: ='PORTIFÓLIO'!C95 | D26: ='PORTIFÓLIO'!F95 | E26: ='PORTIFÓLIO'!R95 | F26: ='PORTIFÓLIO'!T95 | G26: =MAX(0,E26-F26) | H26: ='PORTIFÓLIO'!S95 | I26: =G26*H26 | J26: =IF(G26>0,IF(H26<=0,"⚠ SEM PREÇO","COMPRAR"),IF(E26>0,"OK - ESTOQUE","SEM DEMANDA"))
A27: ='PORTIFÓLIO'!B85 | B27: ='PORTIFÓLIO'!A85 | C27: ='PORTIFÓLIO'!C85 | D27: ='PORTIFÓLIO'!F85 | E27: ='PORTIFÓLIO'!R85 | F27: ='PORTIFÓLIO'!T85 | G27: =MAX(0,E27-F27) | H27: ='PORTIFÓLIO'!S85 | I27: =G27*H27 | J27: =IF(G27>0,IF(H27<=0,"⚠ SEM PREÇO","COMPRAR"),IF(E27>0,"OK - ESTOQUE","SEM DEMANDA"))
A28: ='PORTIFÓLIO'!B71 | B28: ='PORTIFÓLIO'!A71 | C28: ='PORTIFÓLIO'!C71 | D28: ='PORTIFÓLIO'!F71 | E28: ='PORTIFÓLIO'!R71 | F28: ='PORTIFÓLIO'!T71 | G28: =MAX(0,E28-F28) | H28: ='PORTIFÓLIO'!S71 | I28: =G28*H28 | J28: =IF(G28>0,IF(H28<=0,"⚠ SEM PREÇO","COMPRAR"),IF(E28>0,"OK - ESTOQUE","SEM DEMANDA"))
A29: ='PORTIFÓLIO'!B52 | B29: ='PORTIFÓLIO'!A52 | C29: ='PORTIFÓLIO'!C52 | D29: ='PORTIFÓLIO'!F52 | E29: ='PORTIFÓLIO'!R52 | F29: ='PORTIFÓLIO'!T52 | G29: =MAX(0,E29-F29) | H29: ='PORTIFÓLIO'!S52 | I29: =G29*H29 | J29: =IF(G29>0,IF(H29<=0,"⚠ SEM PREÇO","COMPRAR"),IF(E29>0,"OK - ESTOQUE","SEM DEMANDA"))
A30: ='PORTIFÓLIO'!B58 | B30: ='PORTIFÓLIO'!A58 | C30: ='PORTIFÓLIO'!C58 | D30: ='PORTIFÓLIO'!F58 | E30: ='PORTIFÓLIO'!R58 | F30: ='PORTIFÓLIO'!T58 | G30: =MAX(0,E30-F30) | H30: ='PORTIFÓLIO'!S58 | I30: =G30*H30 | J30: =IF(G30>0,IF(H30<=0,"⚠ SEM PREÇO","COMPRAR"),IF(E30>0,"OK - ESTOQUE","SEM DEMANDA"))
A31: ='PORTIFÓLIO'!B99 | B31: ='PORTIFÓLIO'!A99 | C31: ='PORTIFÓLIO'!C99 | D31: ='PORTIFÓLIO'!F99 | E31: ='PORTIFÓLIO'!R99 | F31: ='PORTIFÓLIO'!T99 | G31: =MAX(0,E31-F31) | H31: ='PORTIFÓLIO'!S99 | I31: =G31*H31 | J31: =IF(G31>0,IF(H31<=0,"⚠ SEM PREÇO","COMPRAR"),IF(E31>0,"OK - ESTOQUE","SEM DEMANDA"))
A32: ='PORTIFÓLIO'!B53 | B32: ='PORTIFÓLIO'!A53 | C32: ='PORTIFÓLIO'!C53 | D32: ='PORTIFÓLIO'!F53 | E32: ='PORTIFÓLIO'!R53 | F32: ='PORTIFÓLIO'!T53 | G32: =MAX(0,E32-F32) | H32: ='PORTIFÓLIO'!S53 | I32: =G32*H32 | J32: =IF(G32>0,IF(H32<=0,"⚠ SEM PREÇO","COMPRAR"),IF(E32>0,"OK - ESTOQUE","SEM DEMANDA"))
A33: ='PORTIFÓLIO'!B76 | B33: ='PORTIFÓLIO'!A76 | C33: ='PORTIFÓLIO'!C76 | D33: ='PORTIFÓLIO'!F76 | E33: ='PORTIFÓLIO'!R76 | F33: ='PORTIFÓLIO'!T76 | G33: =MAX(0,E33-F33) | H33: ='PORTIFÓLIO'!S76 | I33: =G33*H33 | J33: =IF(G33>0,IF(H33<=0,"⚠ SEM PREÇO","COMPRAR"),IF(E33>0,"OK - ESTOQUE","SEM DEMANDA"))
A34: ='PORTIFÓLIO'!B106 | B34: ='PORTIFÓLIO'!A106 | C34: ='PORTIFÓLIO'!C106 | D34: ='PORTIFÓLIO'!F106 | E34: ='PORTIFÓLIO'!R106 | F34: ='PORTIFÓLIO'!T106 | G34: =MAX(0,E34-F34) | H34: ='PORTIFÓLIO'!S106 | I34: =G34*H34 | J34: =IF(G34>0,IF(H34<=0,"⚠ SEM PREÇO","COMPRAR"),IF(E34>0,"OK - ESTOQUE","SEM DEMANDA"))
A35: ='PORTIFÓLIO'!B108 | B35: ='PORTIFÓLIO'!A108 | C35: ='PORTIFÓLIO'!C108 | D35: ='PORTIFÓLIO'!F108 | E35: ='PORTIFÓLIO'!R108 | F35: ='PORTIFÓLIO'!T108 | G35: =MAX(0,E35-F35) | H35: ='PORTIFÓLIO'!S108 | I35: =G35*H35 | J35: =IF(G35>0,IF(H35<=0,"⚠ SEM PREÇO","COMPRAR"),IF(E35>0,"OK - ESTOQUE","SEM DEMANDA"))
A36: ='PORTIFÓLIO'!B137 | B36: ='PORTIFÓLIO'!A137 | C36: ='PORTIFÓLIO'!C137 | D36: ='PORTIFÓLIO'!F137 | E36: ='PORTIFÓLIO'!R137 | F36: ='PORTIFÓLIO'!T137 | G36: =MAX(0,E36-F36) | H36: ='PORTIFÓLIO'!S137 | I36: =G36*H36 | J36: =IF(G36>0,IF(H36<=0,"⚠ SEM PREÇO","COMPRAR"),IF(E36>0,"OK - ESTOQUE","SEM DEMANDA"))
A37: ='PORTIFÓLIO'!B161 | B37: ='PORTIFÓLIO'!A161 | C37: ='PORTIFÓLIO'!C161 | D37: ='PORTIFÓLIO'!F161 | E37: ='PORTIFÓLIO'!R161 | F37: ='PORTIFÓLIO'!T161 | G37: =MAX(0,E37-F37) | H37: ='PORTIFÓLIO'!S161 | I37: =G37*H37 | J37: =IF(G37>0,IF(H37<=0,"⚠ SEM PREÇO","COMPRAR"),IF(E37>0,"OK - ESTOQUE","SEM DEMANDA"))
A38: ='PORTIFÓLIO'!B165 | B38: ='PORTIFÓLIO'!A165 | C38: ='PORTIFÓLIO'!C165 | D38: ='PORTIFÓLIO'!F165 | E38: ='PORTIFÓLIO'!R165 | F38: ='PORTIFÓLIO'!T165 | G38: =MAX(0,E38-F38) | H38: ='PORTIFÓLIO'!S165 | I38: =G38*H38 | J38: =IF(G38>0,IF(H38<=0,"⚠ SEM PREÇO","COMPRAR"),IF(E38>0,"OK - ESTOQUE","SEM DEMANDA"))
A39: ='PORTIFÓLIO'!B138 | B39: ='PORTIFÓLIO'!A138 | C39: ='PORTIFÓLIO'!C138 | D39: ='PORTIFÓLIO'!F138 | E39: ='PORTIFÓLIO'!R138 | F39: ='PORTIFÓLIO'!T138 | G39: =MAX(0,E39-F39) | H39: ='PORTIFÓLIO'!S138 | I39: =G39*H39 | J39: =IF(G39>0,IF(H39<=0,"⚠ SEM PREÇO","COMPRAR"),IF(E39>0,"OK - ESTOQUE","SEM DEMANDA"))
A40: ='PORTIFÓLIO'!B149 | B40: ='PORTIFÓLIO'!A149 | C40: ='PORTIFÓLIO'!C149 | D40: ='PORTIFÓLIO'!F149 | E40: ='PORTIFÓLIO'!R149 | F40: ='PORTIFÓLIO'!T149 | G40: =MAX(0,E40-F40) | H40: ='PORTIFÓLIO'!S149 | I40: =G40*H40 | J40: =IF(G40>0,IF(H40<=0,"⚠ SEM PREÇO","COMPRAR"),IF(E40>0,"OK - ESTOQUE","SEM DEMANDA"))
...

Sheet LISTA
A1: FUNGICIDA | B1: HERBICIDA | C1: INSETICIDA | D1: TS | E1: BIOLÓGICOS | F1: SEMENTE | G1: ADJUVANTE | H1: FERTILIZANTES | I1: CORRETIVOS | J1: NUTRIÇÃO | K1: MÁQUINAS | L1: EMPEENDIMENTO | M1: ÁREAS | N1: HECTARES
A2: =IFERROR(__xludf.DUMMYFUNCTION("UNIQUE(FILTER('PORTIFÓLIO'!C:C, 'PORTIFÓLIO'!B:B=""FUNGICIDA""))"),"ACROSS") | B2: =IFERROR(__xludf.DUMMYFUNCTION("UNIQUE(FILTER('PORTIFÓLIO'!C:C, 'PORTIFÓLIO'!B:B=""HERBICIDA""))"),"AMINOL 806") | C2: =IFERROR(__xludf.DUMMYFUNCTION("UNIQUE(FILTER('PORTIFÓLIO'!C:C, 'PORTIFÓLIO'!B:B=""INSETICIDA""))"),"GALIL SC") | D2: =IFERROR(__xludf.DUMMYFUNCTION("UNIQUE(FILTER('PORTIFÓLIO'!C:C, 'PORTIFÓLIO'!B:B=""TS""))"),"ENDOFUSE") | E2: =IFERROR(__xludf.DUMMYFUNCTION("UNIQUE(FILTER('PORTIFÓLIO'!C:C, 'PORTIFÓLIO'!B:B=""biológicos""))"),"UTRISHA N") | F2: =IFERROR(__xludf.DUMMYFUNCTION("UNIQUE(FILTER('PORTIFÓLIO'!C:C, 'PORTIFÓLIO'!B:B=""SEMENTE""))"),"FEIJÃO") | G2: =IFERROR(__xludf.DUMMYFUNCTION("UNIQUE(FILTER('PORTIFÓLIO'!C:C, 'PORTIFÓLIO'!B:B=""ADJUVANTE""))"),"RUMBA") | H2: =IFERROR(__xludf.DUMMYFUNCTION("UNIQUE(FILTER('PORTIFÓLIO'!C:C, 'PORTIFÓLIO'!B:B=""fertilizantes""))"),"I-ACTIVE") | I2: =IFERROR(__xludf.DUMMYFUNCTION("UNIQUE(FILTER('PORTIFÓLIO'!C:C, 'PORTIFÓLIO'!B:B=""corretivos""))"),"CALCÁRIO DOLOMITICO") | J2: =IFERROR(__xludf.DUMMYFUNCTION("UNIQUE(FILTER('PORTIFÓLIO'!C:C, 'PORTIFÓLIO'!B:B=""NUTRIÇÃO""))"),"RADIFARM") | K2: =IFERROR(__xludf.DUMMYFUNCTION("UNIQUE(FILTER('PORTIFÓLIO'!C:C, 'PORTIFÓLIO'!B:B=""MÁQUINAS""))"),"CASE STEIGER 420 + HORSCH MAESTRO DUO 36.50") | L2: FA-SOJA SEQUEIRO-26/27 | M2: ÁREA 1 | N2: 273
A3: =IFERROR(__xludf.DUMMYFUNCTION("""COMPUTED_VALUE"""),"AZIMUT") | B3: =IFERROR(__xludf.DUMMYFUNCTION("""COMPUTED_VALUE"""),"APRESA") | C3: =IFERROR(__xludf.DUMMYFUNCTION("""COMPUTED_VALUE"""),"MAGNUM") | D3: =IFERROR(__xludf.DUMMYFUNCTION("""COMPUTED_VALUE"""),"ENDOMAXX") | E3: =IFERROR(__xludf.DUMMYFUNCTION("""COMPUTED_VALUE"""),"PRESENCE FULL") | F3: =IFERROR(__xludf.DUMMYFUNCTION("""COMPUTED_VALUE"""),"SEMENTE TRIGO") | G3: =IFERROR(__xludf.DUMMYFUNCTION("""COMPUTED_VALUE"""),"ASSIST") | H3: =IFERROR(__xludf.DUMMYFUNCTION("""COMPUTED_VALUE"""),"MAP") | I3: =IFERROR(__xludf.DUMMYFUNCTION("""COMPUTED_VALUE"""),"GESSO AGRICOLA") | J3: =IFERROR(__xludf.DUMMYFUNCTION("""COMPUTED_VALUE"""),"MEGAFOL") | K3: =IFERROR(__xludf.DUMMYFUNCTION("""COMPUTED_VALUE"""),"CASE MAGNUM 340 + - CASE ASM 1213") | L3: FA-SOJA-IRRIGADO-26/27 | M3: ESTEVÃO | N3: 103
A4: =IFERROR(__xludf.DUMMYFUNCTION("""COMPUTED_VALUE"""),"BLINDADO TOV") | B4: =IFERROR(__xludf.DUMMYFUNCTION("""COMPUTED_VALUE"""),"ARADDO") | C4: =IFERROR(__xludf.DUMMYFUNCTION("""COMPUTED_VALUE"""),"PLETHORA BR") | D4: =IFERROR(__xludf.DUMMYFUNCTION("""COMPUTED_VALUE"""),"RIZOLIQ LLI") | E4: =IFERROR(__xludf.DUMMYFUNCTION("""COMPUTED_VALUE"""),"Now Lock") | F4: =IFERROR(__xludf.DUMMYFUNCTION("""COMPUTED_VALUE"""),"SEMENTE MILHO") | G4: =IFERROR(__xludf.DUMMYFUNCTION("""COMPUTED_VALUE"""),"MEES") | H4: =IFERROR(__xludf.DUMMYFUNCTION("""COMPUTED_VALUE"""),"KCL 60%") | J4: =IFERROR(__xludf.DUMMYFUNCTION("""COMPUTED_VALUE"""),"OCTABORATO") | K4: =IFERROR(__xludf.DUMMYFUNCTION("""COMPUTED_VALUE"""),"CR 8.90 NEW HOLLAND + 880 CF45") | L4: FA-MILHO SEQUEIRO-26/27 | M4: ÁREA 2 | N4: 110
A5: =IFERROR(__xludf.DUMMYFUNCTION("""COMPUTED_VALUE"""),"ABACUS HC") | B5: =IFERROR(__xludf.DUMMYFUNCTION("""COMPUTED_VALUE"""),"CHEVAL") | C5: =IFERROR(__xludf.DUMMYFUNCTION("""COMPUTED_VALUE"""),"RIMON SUPRA") | D5: =IFERROR(__xludf.DUMMYFUNCTION("""COMPUTED_VALUE"""),"PROVILAR") | E5: =IFERROR(__xludf.DUMMYFUNCTION("""COMPUTED_VALUE"""),"Now Guard") | F5: =IFERROR(__xludf.DUMMYFUNCTION("""COMPUTED_VALUE"""),"MG540PWU") | G5: =IFERROR(__xludf.DUMMYFUNCTION("""COMPUTED_VALUE"""),"AUREO") | H5: =IFERROR(__xludf.DUMMYFUNCTION("""COMPUTED_VALUE"""),"05-37-00") | J5: =IFERROR(__xludf.DUMMYFUNCTION("""COMPUTED_VALUE"""),"BOP") | K5: =IFERROR(__xludf.DUMMYFUNCTION("""COMPUTED_VALUE"""),"COLHETADEIRA - NH-CR9060 + 740 CF30 AGRIDREPER") | L5: FA-SORGO SEQUEIRO-27/27 | M5: ÁREA 2 B | N5: 47
A6: =IFERROR(__xludf.DUMMYFUNCTION("""COMPUTED_VALUE"""),"BELYAN") | B6: =IFERROR(__xludf.DUMMYFUNCTION("""COMPUTED_VALUE"""),"POQUER") | C6: =IFERROR(__xludf.DUMMYFUNCTION("""COMPUTED_VALUE"""),"SQUAD") | D6: =IFERROR(__xludf.DUMMYFUNCTION("""COMPUTED_VALUE"""),"REVERB") | E6: =IFERROR(__xludf.DUMMYFUNCTION("""COMPUTED_VALUE"""),"Now Force") | F6: =IFERROR(__xludf.DUMMYFUNCTION("""COMPUTED_VALUE"""),"MG711PWU") | G6: =IFERROR(__xludf.DUMMYFUNCTION("""COMPUTED_VALUE"""),"JOINT ULTRA") | H6: =IFERROR(__xludf.DUMMYFUNCTION("""COMPUTED_VALUE"""),"10-46-00 + S") | J6: =IFERROR(__xludf.DUMMYFUNCTION("""COMPUTED_VALUE"""),"METAL NUTRE") | K6: =IFERROR(__xludf.DUMMYFUNCTION("""COMPUTED_VALUE"""),"COLHETADEIRA CR7.80 + MACDON 35F") | L6: FA-MILHO SEMENTE-27/27 | M6: ÁREA 3 | N6: 60
A7: =IFERROR(__xludf.DUMMYFUNCTION("""COMPUTED_VALUE"""),"BLAVITY") | B7: =IFERROR(__xludf.DUMMYFUNCTION("""COMPUTED_VALUE"""),"PREMERLIN 600 EC") | C7: =IFERROR(__xludf.DUMMYFUNCTION("""COMPUTED_VALUE"""),"TRIVOR") | D7: =IFERROR(__xludf.DUMMYFUNCTION("""COMPUTED_VALUE"""),"ARVATICO") | E7: =IFERROR(__xludf.DUMMYFUNCTION("""COMPUTED_VALUE"""),"Now Raze") | F7: =IFERROR(__xludf.DUMMYFUNCTION("""COMPUTED_VALUE"""),"MG616PWU") | G7: =IFERROR(__xludf.DUMMYFUNCTION("""COMPUTED_VALUE"""),"ADGREEN") | H7: =IFERROR(__xludf.DUMMYFUNCTION("""COMPUTED_VALUE"""),"08-42-00") | J7: =IFERROR(__xludf.DUMMYFUNCTION("""COMPUTED_VALUE"""),"MONIC") | K7: =IFERROR(__xludf.DUMMYFUNCTION("""COMPUTED_VALUE"""),"TRATOR-JD 7500 + BRUTUS 12000") | L7: FE-SOJA IRRIGADO-26/27 | M7: CAPOEIRINHA | N7: 312
A8: =IFERROR(__xludf.DUMMYFUNCTION("""COMPUTED_VALUE"""),"CANTUS") | B8: =IFERROR(__xludf.DUMMYFUNCTION("""COMPUTED_VALUE"""),"AMPLO") | C8: =IFERROR(__xludf.DUMMYFUNCTION("""COMPUTED_VALUE"""),"EFFICON") | D8: =IFERROR(__xludf.DUMMYFUNCTION("""COMPUTED_VALUE"""),"VERANGO PRIME") | E8: =IFERROR(__xludf.DUMMYFUNCTION("""COMPUTED_VALUE"""),"Now Bolt") | F8: =IFERROR(__xludf.DUMMYFUNCTION("""COMPUTED_VALUE"""),"P3707PWU") | G8: =IFERROR(__xludf.DUMMYFUNCTION("""COMPUTED_VALUE"""),"ENERGIC") | H8: =IFERROR(__xludf.DUMMYFUNCTION("""COMPUTED_VALUE"""),"SSP 21") | J8: =IFERROR(__xludf.DUMMYFUNCTION("""COMPUTED_VALUE"""),"AP MAGNÉSIO") | K8: =IFERROR(__xludf.DUMMYFUNCTION("""COMPUTED_VALUE"""),"TRATOR-JD 7500 + ADUBADORA HERCULES 10000") | L8: FE-BRACHIARIA-26/27 | M8: RONCADOR | N8: 313
A9: =IFERROR(__xludf.DUMMYFUNCTION("""COMPUTED_VALUE"""),"KEYRA") | B9: =IFERROR(__xludf.DUMMYFUNCTION("""COMPUTED_VALUE"""),"BASAGRAN 600") | C9: =IFERROR(__xludf.DUMMYFUNCTION("""COMPUTED_VALUE"""),"NOMOLT 150") | D9: =IFERROR(__xludf.DUMMYFUNCTION("""COMPUTED_VALUE"""),"FIPRONIL NORTOX MAX") | E9: =IFERROR(__xludf.DUMMYFUNCTION("""COMPUTED_VALUE"""),"Now Active") | F9: =IFERROR(__xludf.DUMMYFUNCTION("""COMPUTED_VALUE"""),"P39209PWU") | G9: =IFERROR(__xludf.DUMMYFUNCTION("""COMPUTED_VALUE"""),"EXTRAVON") | H9: =IFERROR(__xludf.DUMMYFUNCTION("""COMPUTED_VALUE"""),"03-15-07 +14%CO") | J9: =IFERROR(__xludf.DUMMYFUNCTION("""COMPUTED_VALUE"""),"GRANO KMG") | K9: =IFERROR(__xludf.DUMMYFUNCTION("""COMPUTED_VALUE"""),"VOLVO NH380 + CAÇAMBA 430SC") | L9: FE-SOJA SEQUEIRO-26/27 | M9: RONCADOR 2 | N9: 0
A10: =IFERROR(__xludf.DUMMYFUNCTION("""COMPUTED_VALUE"""),"MELYRA") | B10: =IFERROR(__xludf.DUMMYFUNCTION("""COMPUTED_VALUE"""),"FINALE") | C10: =IFERROR(__xludf.DUMMYFUNCTION("""COMPUTED_VALUE"""),"PIRATE") | D10: =IFERROR(__xludf.DUMMYFUNCTION("""COMPUTED_VALUE"""),"MAXIM ADVANCED") | E10: =IFERROR(__xludf.DUMMYFUNCTION("""COMPUTED_VALUE"""),"Now React") | F10: =IFERROR(__xludf.DUMMYFUNCTION("""COMPUTED_VALUE"""),"P40537PWU") | G10: =IFERROR(__xludf.DUMMYFUNCTION("""COMPUTED_VALUE"""),"OCHIMA") | H10: =IFERROR(__xludf.DUMMYFUNCTION("""COMPUTED_VALUE"""),"URÉIA") | J10: =IFERROR(__xludf.DUMMYFUNCTION("""COMPUTED_VALUE"""),"AP MANGANÊS") | K10: =IFERROR(__xludf.DUMMYFUNCTION("""COMPUTED_VALUE"""),"CASE MAGNUM 340 + SUBSOLADOR 11 ASTES") | L10: FE-SORGO IRRIGADO-26/27 | M10: P200 | N10: 200
A11: =IFERROR(__xludf.DUMMYFUNCTION("""COMPUTED_VALUE"""),"ORKESTRA SC") | B11: =IFERROR(__xludf.DUMMYFUNCTION("""COMPUTED_VALUE"""),"HEAT") | C11: =IFERROR(__xludf.DUMMYFUNCTION("""COMPUTED_VALUE"""),"BELT") | D11: =IFERROR(__xludf.DUMMYFUNCTION("""COMPUTED_VALUE"""),"MAXIM XL") | E11: =IFERROR(__xludf.DUMMYFUNCTION("""COMPUTED_VALUE"""),"Now Cover") | F11: =IFERROR(__xludf.DUMMYFUNCTION("""COMPUTED_VALUE"""),"FS650PWU") | H11: =IFERROR(__xludf.DUMMYFUNCTION("""COMPUTED_VALUE"""),"SULFATO DE AMÔNIO") | J11: =IFERROR(__xludf.DUMMYFUNCTION("""COMPUTED_VALUE"""),"AMINOS Mn") | K11: =IFERROR(__xludf.DUMMYFUNCTION("""COMPUTED_VALUE"""),"PULVERIZADOR- JD4730 + PULVERIZADOR- JD4730") | L11: FE-SORGO SEQUEIRO-26/27 | M11: P120 | N11: 120
A12: =IFERROR(__xludf.DUMMYFUNCTION("""COMPUTED_VALUE"""),"SPOT SC") | B12: =IFERROR(__xludf.DUMMYFUNCTION("""COMPUTED_VALUE"""),"LIBERTY") | C12: =IFERROR(__xludf.DUMMYFUNCTION("""COMPUTED_VALUE"""),"BULLDOCK 125 SC") | D12: =IFERROR(__xludf.DUMMYFUNCTION("""COMPUTED_VALUE"""),"VICTRATO") | E12: =IFERROR(__xludf.DUMMYFUNCTION("""COMPUTED_VALUE"""),"Now Pulse") | F12: =IFERROR(__xludf.DUMMYFUNCTION("""COMPUTED_VALUE"""),"SEMENTE SOJA CV") | H12: =IFERROR(__xludf.DUMMYFUNCTION("""COMPUTED_VALUE"""),"BOROGRAN") | J12: =IFERROR(__xludf.DUMMYFUNCTION("""COMPUTED_VALUE"""),"MICROBOX") | K12: =IFERROR(__xludf.DUMMYFUNCTION("""COMPUTED_VALUE"""),"AIR TRATOR AT-502B + AIR TRATOR AT-502B") | M12: BARRO BRANCO | N12: 220
A13: =IFERROR(__xludf.DUMMYFUNCTION("""COMPUTED_VALUE"""),"ATTILA") | B13: =IFERROR(__xludf.DUMMYFUNCTION("""COMPUTED_VALUE"""),"PROWL H2O") | C13: =IFERROR(__xludf.DUMMYFUNCTION("""COMPUTED_VALUE"""),"CERTERO") | D13: =IFERROR(__xludf.DUMMYFUNCTION("""COMPUTED_VALUE"""),"SPECTRO") | E13: =IFERROR(__xludf.DUMMYFUNCTION("""COMPUTED_VALUE"""),"Now Sprint") | F13: =IFERROR(__xludf.DUMMYFUNCTION("""COMPUTED_VALUE"""),"OLIMPO") | H13: =IFERROR(__xludf.DUMMYFUNCTION("""COMPUTED_VALUE"""),"SUPER DUO") | J13: =IFERROR(__xludf.DUMMYFUNCTION("""COMPUTED_VALUE"""),"ACRESECENT ALGA") | K13: =IFERROR(__xludf.DUMMYFUNCTION("""COMPUTED_VALUE"""),"COLHETADEIRA - NH-CR9060 + MILHO BRAVA 11") | M13: P 01 | N13: 60
A14: =IFERROR(__xludf.DUMMYFUNCTION("""COMPUTED_VALUE"""),"FOX SUPRA") | B14: =IFERROR(__xludf.DUMMYFUNCTION("""COMPUTED_VALUE"""),"ADENGO") | C14: =IFERROR(__xludf.DUMMYFUNCTION("""COMPUTED_VALUE"""),"CONNECT") | D14: =IFERROR(__xludf.DUMMYFUNCTION("""COMPUTED_VALUE"""),"STANDAK TOP") | E14: =IFERROR(__xludf.DUMMYFUNCTION("""COMPUTED_VALUE"""),"Bio Az") | F14: =IFERROR(__xludf.DUMMYFUNCTION("""COMPUTED_VALUE"""),"M8349") | H14: =IFERROR(__xludf.DUMMYFUNCTION("""COMPUTED_VALUE"""),"08-40-00 - 100M") | J14: =IFERROR(__xludf.DUMMYFUNCTION("""COMPUTED_VALUE"""),"RAIZ F") | K14: =IFERROR(__xludf.DUMMYFUNCTION("""COMPUTED_VALUE"""),"NH T7.260 + JAN 20000") | M14: P 02 | N14: 80
A15: =IFERROR(__xludf.DUMMYFUNCTION("""COMPUTED_VALUE"""),"FOX XPRO") | B15: =IFERROR(__xludf.DUMMYFUNCTION("""COMPUTED_VALUE"""),"ROUNDUP WG") | C15: =IFERROR(__xludf.DUMMYFUNCTION("""COMPUTED_VALUE"""),"CURBIX 200 SC") | D15: =IFERROR(__xludf.DUMMYFUNCTION("""COMPUTED_VALUE"""),"CRUISER ADVANCED") | E15: =IFERROR(__xludf.DUMMYFUNCTION("""COMPUTED_VALUE"""),"Bio ND") | F15: =IFERROR(__xludf.DUMMYFUNCTION("""COMPUTED_VALUE"""),"CORDIUS C2795 CE") | H15: =IFERROR(__xludf.DUMMYFUNCTION("""COMPUTED_VALUE"""),"AURUS 500") | J15: =IFERROR(__xludf.DUMMYFUNCTION("""COMPUTED_VALUE"""),"ACRESCENTE SOLUS F") | K15: =IFERROR(__xludf.DUMMYFUNCTION("""COMPUTED_VALUE"""),"NH T8.355 + - JD2122") | M15: P 03 | N15: 120
A16: =IFERROR(__xludf.DUMMYFUNCTION("""COMPUTED_VALUE"""),"NATIVO") | B16: =IFERROR(__xludf.DUMMYFUNCTION("""COMPUTED_VALUE"""),"SOBERAN") | C16: =IFERROR(__xludf.DUMMYFUNCTION("""COMPUTED_VALUE"""),"OBERON") | D16: =IFERROR(__xludf.DUMMYFUNCTION("""COMPUTED_VALUE"""),"PLUST") | E16: =IFERROR(__xludf.DUMMYFUNCTION("""COMPUTED_VALUE"""),"Tec Catp Pro") | F16: =IFERROR(__xludf.DUMMYFUNCTION("""COMPUTED_VALUE"""),"HERA I2X") | H16: =IFERROR(__xludf.DUMMYFUNCTION("""COMPUTED_VALUE"""),"00-01-00+Cu2 Mn8 Zn7 ") | J16: =IFERROR(__xludf.DUMMYFUNCTION("""COMPUTED_VALUE"""),"SALUT") | K16: =IFERROR(__xludf.DUMMYFUNCTION("""COMPUTED_VALUE"""),"COLHETADEIRA - CASE 2388 + CASE 30PES") | M16: P 04 | N16: 130
A17: =IFERROR(__xludf.DUMMYFUNCTION("""COMPUTED_VALUE"""),"NATIVO PLUS") | B17: =IFERROR(__xludf.DUMMYFUNCTION("""COMPUTED_VALUE"""),"2,4-D 806+PICLORAM 64") | C17: =IFERROR(__xludf.DUMMYFUNCTION("""COMPUTED_VALUE"""),"ACETAMIPRID CCAB 200 SP") | D17: =IFERROR(__xludf.DUMMYFUNCTION("""COMPUTED_VALUE"""),"SOMBRERO") | E17: =IFERROR(__xludf.DUMMYFUNCTION("""COMPUTED_VALUE"""),"Bio Elipso") | F17: =IFERROR(__xludf.DUMMYFUNCTION("""COMPUTED_VALUE"""),"SPARTA 8.0") | J17: =IFERROR(__xludf.DUMMYFUNCTION("""COMPUTED_VALUE"""),"MATRIZ D") | K17: =IFERROR(__xludf.DUMMYFUNCTION("""COMPUTED_VALUE"""),"JACTO UNIPORT 2000 + JACTO UNIPORT 2000") | M17: P 05 | N17: 120
A18: =IFERROR(__xludf.DUMMYFUNCTION("""COMPUTED_VALUE"""),"SPHERE MAX") | B18: =IFERROR(__xludf.DUMMYFUNCTION("""COMPUTED_VALUE"""),"FOMESAFEN CCAB 250 SL") | C18: =IFERROR(__xludf.DUMMYFUNCTION("""COMPUTED_VALUE"""),"DIFLUBENZURON CCAB 480 SC") | D18: =IFERROR(__xludf.DUMMYFUNCTION("""COMPUTED_VALUE"""),"CROPSTAR") | E18: =IFERROR(__xludf.DUMMYFUNCTION("""COMPUTED_VALUE"""),"Tec Bug") | F18: =IFERROR(__xludf.DUMMYFUNCTION("""COMPUTED_VALUE"""),"CORDIUS C2795 CE 7.9") | J18: =IFERROR(__xludf.DUMMYFUNCTION("""COMPUTED_VALUE"""),"BRAVERO") | K18: =IFERROR(__xludf.DUMMYFUNCTION("""COMPUTED_VALUE"""),"NH T7.260 + CASE 2213") | M18: P 06 | N18: 40
A19: =IFERROR(__xludf.DUMMYFUNCTION("""COMPUTED_VALUE"""),"AZOXISTROBIN 200 + CIPROCONAZOL 80 SC CCAB") | B19: =IFERROR(__xludf.DUMMYFUNCTION("""COMPUTED_VALUE"""),"GLUFOSINATO CCAB 200 SL") | C19: =IFERROR(__xludf.DUMMYFUNCTION("""COMPUTED_VALUE"""),"FIPRONIL 800 WG CCAB") | D19: =IFERROR(__xludf.DUMMYFUNCTION("""COMPUTED_VALUE"""),"DERMACOR") | E19: =IFERROR(__xludf.DUMMYFUNCTION("""COMPUTED_VALUE"""),"Solu Shield") | F19: =IFERROR(__xludf.DUMMYFUNCTION("""COMPUTED_VALUE"""),"IMPETO") | J19: =IFERROR(__xludf.DUMMYFUNCTION("""COMPUTED_VALUE"""),"Glyfort") | K19: =IFERROR(__xludf.DUMMYFUNCTION("""COMPUTED_VALUE""")," + ") | M19: T01 | N19: 220
A20: =IFERROR(__xludf.DUMMYFUNCTION("""COMPUTED_VALUE"""),"MANCOZEB CCAB 750 WG") | B20: =IFERROR(__xludf.DUMMYFUNCTION("""COMPUTED_VALUE"""),"MESOTRIONA CCAB 480 SC") | C20: =IFERROR(__xludf.DUMMYFUNCTION("""COMPUTED_VALUE"""),"INDOXACARB CCAB 150 SC") | D20: =IFERROR(__xludf.DUMMYFUNCTION("""COMPUTED_VALUE"""),"OPTERASEED") | E20: =IFERROR(__xludf.DUMMYFUNCTION("""COMPUTED_VALUE"""),"Solu Strong") | F20: =IFERROR(__xludf.DUMMYFUNCTION("""COMPUTED_VALUE"""),"NEO 790") | J20: =IFERROR(__xludf.DUMMYFUNCTION("""COMPUTED_VALUE"""),"Fergsum") | M20: T02 | N20: 220
A21: =IFERROR(__xludf.DUMMYFUNCTION("""COMPUTED_VALUE"""),"APROACH POWER") | B21: =IFERROR(__xludf.DUMMYFUNCTION("""COMPUTED_VALUE"""),"TRICLOPIR CCAB 480 EC") | C21: =IFERROR(__xludf.DUMMYFUNCTION("""COMPUTED_VALUE"""),"EXALT") | D21: =IFERROR(__xludf.DUMMYFUNCTION("""COMPUTED_VALUE"""),"AVICTA 500 FS") | E21: =IFERROR(__xludf.DUMMYFUNCTION("""COMPUTED_VALUE"""),"Solu Leaf") | F21: =IFERROR(__xludf.DUMMYFUNCTION("""COMPUTED_VALUE"""),"APORÉ 7.3") | J21: =IFERROR(__xludf.DUMMYFUNCTION("""COMPUTED_VALUE"""),"Spander")
A22: =IFERROR(__xludf.DUMMYFUNCTION("""COMPUTED_VALUE"""),"APROACH PREMIUM") | B22: =IFERROR(__xludf.DUMMYFUNCTION("""COMPUTED_VALUE"""),"ACCENT") | C22: =IFERROR(__xludf.DUMMYFUNCTION("""COMPUTED_VALUE"""),"EXPEDITION") | D22: =IFERROR(__xludf.DUMMYFUNCTION("""COMPUTED_VALUE"""),"CRUISER 350 FS") | E22: =IFERROR(__xludf.DUMMYFUNCTION("""COMPUTED_VALUE"""),"Bio Hidric") | F22: =IFERROR(__xludf.DUMMYFUNCTION("""COMPUTED_VALUE"""),"GUAPÓ 7.7") | J22: =IFERROR(__xludf.DUMMYFUNCTION("""COMPUTED_VALUE"""),"Halattus")
A23: =IFERROR(__xludf.DUMMYFUNCTION("""COMPUTED_VALUE"""),"BIM 750 BR") | B23: =IFERROR(__xludf.DUMMYFUNCTION("""COMPUTED_VALUE"""),"CLASSIC") | C23: =IFERROR(__xludf.DUMMYFUNCTION("""COMPUTED_VALUE"""),"INTREPID 240 SC") | D23: =IFERROR(__xludf.DUMMYFUNCTION("""COMPUTED_VALUE"""),"FORTENZA 600 FS") | E23: =IFERROR(__xludf.DUMMYFUNCTION("""COMPUTED_VALUE"""),"Bio Bokashi") | F23: =IFERROR(__xludf.DUMMYFUNCTION("""COMPUTED_VALUE"""),"MITICA 7.7") | J23: =IFERROR(__xludf.DUMMYFUNCTION("""COMPUTED_VALUE"""),"Sallvare Complex")
A24: =IFERROR(__xludf.DUMMYFUNCTION("""COMPUTED_VALUE"""),"BIM MAX") | B24: =IFERROR(__xludf.DUMMYFUNCTION("""COMPUTED_VALUE"""),"CLINCHER") | C24: =IFERROR(__xludf.DUMMYFUNCTION("""COMPUTED_VALUE"""),"INTREPID EDGE") | D24: =IFERROR(__xludf.DUMMYFUNCTION("""COMPUTED_VALUE"""),"ILEVO") | E24: =IFERROR(__xludf.DUMMYFUNCTION("""COMPUTED_VALUE"""),"Bio Oil") | F24: =IFERROR(__xludf.DUMMYFUNCTION("""COMPUTED_VALUE"""),"TMG MURICI I2X 7.6") | J24: =IFERROR(__xludf.DUMMYFUNCTION("""COMPUTED_VALUE"""),"Zinctaus Complex")
A25: =IFERROR(__xludf.DUMMYFUNCTION("""COMPUTED_VALUE"""),"ORANIS") | B25: =IFERROR(__xludf.DUMMYFUNCTION("""COMPUTED_VALUE"""),"ELEVORE") | C25: =IFERROR(__xludf.DUMMYFUNCTION("""COMPUTED_VALUE"""),"LANNATE BR") | D25: =IFERROR(__xludf.DUMMYFUNCTION("""COMPUTED_VALUE"""),"PERMIT STAR") | E25: =IFERROR(__xludf.DUMMYFUNCTION("""COMPUTED_VALUE"""),"Carbon Pro") | F25: =IFERROR(__xludf.DUMMYFUNCTION("""COMPUTED_VALUE"""),"DOMÍNIO 8.4") | J25: =IFERROR(__xludf.DUMMYFUNCTION("""COMPUTED_VALUE"""),"Emezine Complex")
A26: =IFERROR(__xludf.DUMMYFUNCTION("""COMPUTED_VALUE"""),"VESSARYA") | B26: =IFERROR(__xludf.DUMMYFUNCTION("""COMPUTED_VALUE"""),"ENLIST COLEX-D") | C26: =IFERROR(__xludf.DUMMYFUNCTION("""COMPUTED_VALUE"""),"ACETAMIPRID 250 G/KG + BIFENTHRIN 250G/KG WG") | E26: =IFERROR(__xludf.DUMMYFUNCTION("""COMPUTED_VALUE"""),"Essencial Mg") | F26: =IFERROR(__xludf.DUMMYFUNCTION("""COMPUTED_VALUE"""),"LENDA") | J26: =IFERROR(__xludf.DUMMYFUNCTION("""COMPUTED_VALUE"""),"Boratus Complex")
A27: =IFERROR(__xludf.DUMMYFUNCTION("""COMPUTED_VALUE"""),"CHARRUA 430 SC") | B27: =IFERROR(__xludf.DUMMYFUNCTION("""COMPUTED_VALUE"""),"GAPPER") | C27: =IFERROR(__xludf.DUMMYFUNCTION("""COMPUTED_VALUE"""),"BAKANA 400 SC") | E27: =IFERROR(__xludf.DUMMYFUNCTION("""COMPUTED_VALUE"""),"Expelir") | F27: =IFERROR(__xludf.DUMMYFUNCTION("""COMPUTED_VALUE"""),"BRASMAX HERA") | J27: =IFERROR(__xludf.DUMMYFUNCTION("""COMPUTED_VALUE"""),"Magmill Complex")
A28: =IFERROR(__xludf.DUMMYFUNCTION("""COMPUTED_VALUE"""),"SEVARE 250 EC") | B28: =IFERROR(__xludf.DUMMYFUNCTION("""COMPUTED_VALUE"""),"PACTO") | C28: =IFERROR(__xludf.DUMMYFUNCTION("""COMPUTED_VALUE"""),"KRATON 100 EC") | E28: =IFERROR(__xludf.DUMMYFUNCTION("""COMPUTED_VALUE"""),"Primafert") | F28: =IFERROR(__xludf.DUMMYFUNCTION("""COMPUTED_VALUE"""),"BRASMAX OLIMPO") | J28: =IFERROR(__xludf.DUMMYFUNCTION("""COMPUTED_VALUE"""),"Brave K")
A29: =IFERROR(__xludf.DUMMYFUNCTION("""COMPUTED_VALUE"""),"VENCER DUO") | B29: =IFERROR(__xludf.DUMMYFUNCTION("""COMPUTED_VALUE"""),"PAXEO") | C29: =IFERROR(__xludf.DUMMYFUNCTION("""COMPUTED_VALUE"""),"TAURA 200 EC") | E29: =IFERROR(__xludf.DUMMYFUNCTION("""COMPUTED_VALUE"""),"Reserva") | F29: =IFERROR(__xludf.DUMMYFUNCTION("""COMPUTED_VALUE"""),"S6525 I2X") | J29: =IFERROR(__xludf.DUMMYFUNCTION("""COMPUTED_VALUE"""),"Brave Max Up")
A30: =IFERROR(__xludf.DUMMYFUNCTION("""COMPUTED_VALUE"""),"ONSUVA") | B30: =IFERROR(__xludf.DUMMYFUNCTION("""COMPUTED_VALUE"""),"SPIDER 840 WG") | C30: =IFERROR(__xludf.DUMMYFUNCTION("""COMPUTED_VALUE"""),"BENEVIA") | E30: =IFERROR(__xludf.DUMMYFUNCTION("""COMPUTED_VALUE"""),"Tec Catp Pro Kit On-farm") | F30: =IFERROR(__xludf.DUMMYFUNCTION("""COMPUTED_VALUE"""),"TMG ITAÚBA I2X") | J30: =IFERROR(__xludf.DUMMYFUNCTION("""COMPUTED_VALUE"""),"MAX RAIZ")
A31: =IFERROR(__xludf.DUMMYFUNCTION("""COMPUTED_VALUE"""),"BOSCALID NORTOX 500 WG") | B31: =IFERROR(__xludf.DUMMYFUNCTION("""COMPUTED_VALUE"""),"VERDICT ULTRA") | C31: =IFERROR(__xludf.DUMMYFUNCTION("""COMPUTED_VALUE"""),"HERO") | E31: =IFERROR(__xludf.DUMMYFUNCTION("""COMPUTED_VALUE"""),"Tec Bug Kit On-farm") | J31: =IFERROR(__xludf.DUMMYFUNCTION("""COMPUTED_VALUE"""),"Polyamine")
A32: =IFERROR(__xludf.DUMMYFUNCTION("""COMPUTED_VALUE"""),"DIFENOCONAZOL NORTOX 250 SC") | B32: =IFERROR(__xludf.DUMMYFUNCTION("""COMPUTED_VALUE"""),"BLOWOUT") | C32: =IFERROR(__xludf.DUMMYFUNCTION("""COMPUTED_VALUE"""),"MALATHION UL") | E32: =IFERROR(__xludf.DUMMYFUNCTION("""COMPUTED_VALUE"""),"Solu Shield Kit On-farm") | F32: =IFERROR(__xludf.DUMMYFUNCTION("""COMPUTED_VALUE"""),"SEMENTE SOJA RR") | J32: =IFERROR(__xludf.DUMMYFUNCTION("""COMPUTED_VALUE"""),"Sulfato de Magnésio")
A33: =IFERROR(__xludf.DUMMYFUNCTION("""COMPUTED_VALUE"""),"FLUAZINAM NORTOX 500 SC") | B33: =IFERROR(__xludf.DUMMYFUNCTION("""COMPUTED_VALUE"""),"CLETODIM 240 EC BRILLIANCE") | C33: =IFERROR(__xludf.DUMMYFUNCTION("""COMPUTED_VALUE"""),"MUSTANG 350 EC") | E33: =IFERROR(__xludf.DUMMYFUNCTION("""COMPUTED_VALUE"""),"Solu Strong Kit On-farm") | F33: =IFERROR(__xludf.DUMMYFUNCTION("""COMPUTED_VALUE"""),"BRACHIARIA RUZIZIENCES") | J33: =IFERROR(__xludf.DUMMYFUNCTION("""COMPUTED_VALUE"""),"Map Purificado")
A34: =IFERROR(__xludf.DUMMYFUNCTION("""COMPUTED_VALUE"""),"FLUTRIAFOL NORTOX") | B34: =IFERROR(__xludf.DUMMYFUNCTION("""COMPUTED_VALUE"""),"GLUFOS-WYN 880") | C34: =IFERROR(__xludf.DUMMYFUNCTION("""COMPUTED_VALUE"""),"PREMIO") | E34: =IFERROR(__xludf.DUMMYFUNCTION("""COMPUTED_VALUE"""),"Solu Leaf Kit On-farm") | F34: =IFERROR(__xludf.DUMMYFUNCTION("""COMPUTED_VALUE"""),"CAPIM MIAGE") | J34: =IFERROR(__xludf.DUMMYFUNCTION("""COMPUTED_VALUE"""),"MANGAN 10")
A35: =IFERROR(__xludf.DUMMYFUNCTION("""COMPUTED_VALUE"""),"PROPICONAZOLE NORTOX 500 EC") | B35: =IFERROR(__xludf.DUMMYFUNCTION("""COMPUTED_VALUE"""),"GINETE 212 SL") | C35: =IFERROR(__xludf.DUMMYFUNCTION("""COMPUTED_VALUE"""),"TALISMAN") | E35: =IFERROR(__xludf.DUMMYFUNCTION("""COMPUTED_VALUE"""),"Bio Hidric Kit On-farm") | F35: =IFERROR(__xludf.DUMMYFUNCTION("""COMPUTED_VALUE"""),"TMG INGÁ I2X 6.9") | J35: =IFERROR(__xludf.DUMMYFUNCTION("""COMPUTED_VALUE"""),"NHT ZINCO")
A36: =IFERROR(__xludf.DUMMYFUNCTION("""COMPUTED_VALUE"""),"PROTECTION NORTOX") | B36: =IFERROR(__xludf.DUMMYFUNCTION("""COMPUTED_VALUE"""),"AURORA 400 EC") | C36: =IFERROR(__xludf.DUMMYFUNCTION("""COMPUTED_VALUE"""),"TALSTAR 400") | E36: =IFERROR(__xludf.DUMMYFUNCTION("""COMPUTED_VALUE"""),"Bio Bokashi Kit On-farm") | F36: =IFERROR(__xludf.DUMMYFUNCTION("""COMPUTED_VALUE"""),"TMG 2383 IPRO 8.3") | J36: =IFERROR(__xludf.DUMMYFUNCTION("""COMPUTED_VALUE"""),"KELLUS CUPPER")
A37: =IFERROR(__xludf.DUMMYFUNCTION("""COMPUTED_VALUE"""),"TEBUCO 430 SC NORTOX") | B37: =IFERROR(__xludf.DUMMYFUNCTION("""COMPUTED_VALUE"""),"AZUGRO") | C37: =IFERROR(__xludf.DUMMYFUNCTION("""COMPUTED_VALUE"""),"VERIMARK") | E37: =IFERROR(__xludf.DUMMYFUNCTION("""COMPUTED_VALUE"""),"Tec White Kit On-farm") | F37: =IFERROR(__xludf.DUMMYFUNCTION("""COMPUTED_VALUE"""),"BRACHIARIA BASICA") | J37: =IFERROR(__xludf.DUMMYFUNCTION("""COMPUTED_VALUE"""),"MOLIBIDENIO 16")
A38: =IFERROR(__xludf.DUMMYFUNCTION("""COMPUTED_VALUE"""),"TEBUCO A NORTOX") | B38: =IFERROR(__xludf.DUMMYFUNCTION("""COMPUTED_VALUE"""),"BORAL") | C38: =IFERROR(__xludf.DUMMYFUNCTION("""COMPUTED_VALUE"""),"ABAMECTIN 72 EC NORTOX") | E38: =IFERROR(__xludf.DUMMYFUNCTION("""COMPUTED_VALUE"""),"Bio Solubilize Kit On-farm") | F38: =IFERROR(__xludf.DUMMYFUNCTION("""COMPUTED_VALUE"""),"GH 2478 IPRO 8.1") | J38: =IFERROR(__xludf.DUMMYFUNCTION("""COMPUTED_VALUE"""),"ZINCO 10")
A39: =IFERROR(__xludf.DUMMYFUNCTION("""COMPUTED_VALUE"""),"TIOFANATO NORTOX") | B39: =IFERROR(__xludf.DUMMYFUNCTION("""COMPUTED_VALUE"""),"REATOR 360 CS") | C39: =IFERROR(__xludf.DUMMYFUNCTION("""COMPUTED_VALUE"""),"CIPERMETRINA NORTOX") | E39: =IFERROR(__xludf.DUMMYFUNCTION("""COMPUTED_VALUE"""),"Bio Release Kit On-farm") | F39: =IFERROR(__xludf.DUMMYFUNCTION("""COMPUTED_VALUE"""),"HO COCARI I2X 8.2") | J39: =IFERROR(__xludf.DUMMYFUNCTION("""COMPUTED_VALUE"""),"Potenza NiCoMo")
A40: =IFERROR(__xludf.DUMMYFUNCTION("""COMPUTED_VALUE"""),"ACADEMIC") | B40: =IFERROR(__xludf.DUMMYFUNCTION("""COMPUTED_VALUE"""),"STONE") | C40: =IFERROR(__xludf.DUMMYFUNCTION("""COMPUTED_VALUE"""),"CLORANTRANILIPROLE NORTOX 400 SC") | E40: =IFERROR(__xludf.DUMMYFUNCTION("""COMPUTED_VALUE"""),"Bio Raiz Plus Kit On-farm") | F40: =IFERROR(__xludf.DUMMYFUNCTION("""COMPUTED_VALUE"""),"SEMENTE DE SORGO")
...

Sheet CUSTO OPERAÇÃO
A1: Column 11 | B1: MÁQUINA | C1: IMPLEMENTO | D1: CONJUNTO | E1: LARGURA | F1: VELOCIDADE | G1: EFICIÊNCIA | H1: ha/h | I1: L/h | J1: HM/ha | K1: L/ha | L1: CUSTO HM/HA | M1: HORA MAQ./HA | O1: GRUPO | P1: MAQUINA | Q1: CONSUMO HORA | R1: LARGURA OPERAÇÃO | S1: VELOCIDADE
A2: MÁQUINAS | B2: TRATOR - CASE STEIGER 420 | C2: PLANTADEIRA HORSCH MAESTRO DUO 36.50 | D2: =IFERROR(__xludf.DUMMYFUNCTION("REGEXREPLACE(B2,""TRATOR - |COLHEITADEIRA |PULVERIZADOR |CAMINHAO-"","""")&"" + ""&REGEXREPLACE(C2,""PLANTADEIRA |PLATAFORMA |DISTRIBUIDOR |PULVERIZADOR "", """")"),"CASE STEIGER 420 + HORSCH MAESTRO DUO 36.50") | E2: =VLOOKUP(C2,'CUSTO OPERAÇÃO'!$P$1:$S$125,3,0) | F2: =VLOOKUP(C2,'CUSTO OPERAÇÃO'!$P$1:$S$125,4,0) | G2: 85 | H2: =(E2*F2*(G2/100))/10 | I2: =VLOOKUP(B2,'CUSTO OPERAÇÃO'!$P$1:$Q$125,2,0) | J2: =1/H2 | K2: =I2/H2 | L2: =K2*7.5 | M2: =IFERROR(L2/J2,"") | O2: AVIÃO AGRICOLA | P2: AIR TRATOR AT-502B | Q2: 120 | R2: 30 | S2: 200
A3: MÁQUINAS | B3: TRATOR - CASE MAGNUM 340 | C3: PLANTADEIRA - CASE ASM 1213 | D3: =IFERROR(__xludf.DUMMYFUNCTION("REGEXREPLACE(B3,""TRATOR - |COLHEITADEIRA |PULVERIZADOR |CAMINHAO-"","""")&"" + ""&REGEXREPLACE(C3,""PLANTADEIRA |PLATAFORMA |DISTRIBUIDOR |PULVERIZADOR "", """")"),"CASE MAGNUM 340 + - CASE ASM 1213") | E3: =VLOOKUP(C3,'CUSTO OPERAÇÃO'!$P$1:$S$125,3,0) | F3: =VLOOKUP(C3,'CUSTO OPERAÇÃO'!$P$1:$S$125,4,0) | G3: 85 | H3: =(E3*F3*(G3/100))/10 | I3: =VLOOKUP(B3,'CUSTO OPERAÇÃO'!$P$1:$Q$125,2,0) | J3: =1/H3 | K3: =I3/H3 | L3: =K3*7.5 | M3: =IFERROR(L3/J3,"")
A4: MÁQUINAS | B4: COLHEITADEIRA CR 8.90 NEW HOLLAND | C4: PLATAFORMA 880 CF45 | D4: =IFERROR(__xludf.DUMMYFUNCTION("REGEXREPLACE(B4,""TRATOR - |COLHEITADEIRA |PULVERIZADOR |CAMINHAO-"","""")&"" + ""&REGEXREPLACE(C4,""PLANTADEIRA |PLATAFORMA |DISTRIBUIDOR |PULVERIZADOR "", """")"),"CR 8.90 NEW HOLLAND + 880 CF45") | E4: =VLOOKUP(C4,'CUSTO OPERAÇÃO'!$P$1:$S$125,3,0) | F4: =VLOOKUP(C4,'CUSTO OPERAÇÃO'!$P$1:$S$125,4,0) | G4: 85 | H4: =(E4*F4*(G4/100))/10 | I4: =VLOOKUP(B4,'CUSTO OPERAÇÃO'!$P$1:$Q$125,2,0) | J4: =1/H4 | K4: =I4/H4 | L4: =K4*7.5 | M4: =IFERROR(L4/J4,"")
A5: MÁQUINAS | B5: COLHETADEIRA - NH-CR9060 | C5: PLATAFORMA 740 CF30 AGRIDREPER | D5: =IFERROR(__xludf.DUMMYFUNCTION("REGEXREPLACE(B5,""TRATOR - |COLHEITADEIRA |PULVERIZADOR |CAMINHAO-"","""")&"" + ""&REGEXREPLACE(C5,""PLANTADEIRA |PLATAFORMA |DISTRIBUIDOR |PULVERIZADOR "", """")"),"COLHETADEIRA - NH-CR9060 + 740 CF30 AGRIDREPER") | E5: =VLOOKUP(C5,'CUSTO OPERAÇÃO'!$P$1:$S$125,3,0) | F5: =VLOOKUP(C5,'CUSTO OPERAÇÃO'!$P$1:$S$125,4,0) | G5: 85 | H5: =(E5*F5*(G5/100))/10 | I5: =VLOOKUP(B5,'CUSTO OPERAÇÃO'!$P$1:$Q$125,2,0) | J5: =1/H5 | K5: =I5/H5 | L5: =K5*7.5 | M5: =IFERROR(L5/J5,"") | O5: CAMINHÕES | P5: CAMINHAO-VOLVO VM260 | Q5: 20 | R5: 1 | S5: 40
A6: MÁQUINAS | B6: COLHETADEIRA CR7.80 | C6: PLATAFORMA MACDON 35F | D6: =IFERROR(__xludf.DUMMYFUNCTION("REGEXREPLACE(B6,""TRATOR - |COLHEITADEIRA |PULVERIZADOR |CAMINHAO-"","""")&"" + ""&REGEXREPLACE(C6,""PLANTADEIRA |PLATAFORMA |DISTRIBUIDOR |PULVERIZADOR "", """")"),"COLHETADEIRA CR7.80 + MACDON 35F") | E6: =VLOOKUP(C6,'CUSTO OPERAÇÃO'!$P$1:$S$125,3,0) | F6: =VLOOKUP(C6,'CUSTO OPERAÇÃO'!$P$1:$S$125,4,0) | G6: 85 | H6: =(E6*F6*(G6/100))/10 | I6: =VLOOKUP(B6,'CUSTO OPERAÇÃO'!$P$1:$Q$125,2,0) | J6: =1/H6 | K6: =I6/H6 | L6: =K6*7.5 | M6: =IFERROR(L6/J6,"") | O6: CAMINHÕES | P6: CAMINHAO-VOLVO NH380 | Q6: 20
A7: MÁQUINAS | B7: TRATOR-JD 7500 | C7: DISTRIBUIDOR BRUTUS 12000 | D7: =IFERROR(__xludf.DUMMYFUNCTION("REGEXREPLACE(B7,""TRATOR - |COLHEITADEIRA |PULVERIZADOR |CAMINHAO-"","""")&"" + ""&REGEXREPLACE(C7,""PLANTADEIRA |PLATAFORMA |DISTRIBUIDOR |PULVERIZADOR "", """")"),"TRATOR-JD 7500 + BRUTUS 12000") | E7: =VLOOKUP(C7,'CUSTO OPERAÇÃO'!$P$1:$S$125,3,0) | F7: =VLOOKUP(C7,'CUSTO OPERAÇÃO'!$P$1:$S$125,4,0) | G7: 85 | H7: =(E7*F7*(G7/100))/10 | I7: =VLOOKUP(B7,'CUSTO OPERAÇÃO'!$P$1:$Q$125,2,0) | J7: =1/H7 | K7: =I7/H7 | L7: =K7*7.5 | M7: =IFERROR(L7/J7,"") | O7: CAMINHÕES | P7: CAMINHAO-WV 7.100 | Q7: 20
A8: MÁQUINAS | B8: TRATOR-JD 7500 | C8: DISTRIBUIDOR ADUBADORA HERCULES 10000 | D8: =IFERROR(__xludf.DUMMYFUNCTION("REGEXREPLACE(B8,""TRATOR - |COLHEITADEIRA |PULVERIZADOR |CAMINHAO-"","""")&"" + ""&REGEXREPLACE(C8,""PLANTADEIRA |PLATAFORMA |DISTRIBUIDOR |PULVERIZADOR "", """")"),"TRATOR-JD 7500 + ADUBADORA HERCULES 10000") | E8: =VLOOKUP(C8,'CUSTO OPERAÇÃO'!$P$1:$S$125,3,0) | F8: =VLOOKUP(C8,'CUSTO OPERAÇÃO'!$P$1:$S$125,4,0) | G8: 85 | H8: =(E8*F8*(G8/100))/10 | I8: =VLOOKUP(B8,'CUSTO OPERAÇÃO'!$P$1:$Q$125,2,0) | J8: =1/H8 | K8: =I8/H8 | L8: =K8*7.5 | M8: =IFERROR(L8/J8,"") | O8: CAMINHÕES | P8: CAMINHAO-MB 1313 | Q8: 20
A9: MÁQUINAS | B9: CAMINHAO-VOLVO NH380 | C9: CAÇAMBA 430SC | D9: =IFERROR(__xludf.DUMMYFUNCTION("REGEXREPLACE(B9,""TRATOR - |COLHEITADEIRA |PULVERIZADOR |CAMINHAO-"","""")&"" + ""&REGEXREPLACE(C9,""PLANTADEIRA |PLATAFORMA |DISTRIBUIDOR |PULVERIZADOR "", """")"),"VOLVO NH380 + CAÇAMBA 430SC") | E9: 430 | F9: =VLOOKUP(C9,'CUSTO OPERAÇÃO'!$P$1:$S$125,4,0) | G9: 85 | H9: =(E9*F9*(G9/100))/10 | I9: =VLOOKUP(B9,'CUSTO OPERAÇÃO'!$P$1:$Q$125,2,0) | J9: =1/H9 | K9: =I9/H9 | L9: =K9*7.5 | M9: =IFERROR(L9/J9,"") | O9: CAMINHÕES | P9: CAMINHÃO MB 1620 | Q9: 20
A10: MÁQUINAS | B10: TRATOR - CASE MAGNUM 340 | C10: SUBSOLADOR 11 ASTES | D10: =IFERROR(__xludf.DUMMYFUNCTION("REGEXREPLACE(B10,""TRATOR - |COLHEITADEIRA |PULVERIZADOR |CAMINHAO-"","""")&"" + ""&REGEXREPLACE(C10,""PLANTADEIRA |PLATAFORMA |DISTRIBUIDOR |PULVERIZADOR "", """")"),"CASE MAGNUM 340 + SUBSOLADOR 11 ASTES") | E10: =VLOOKUP(C10,'CUSTO OPERAÇÃO'!$P$1:$S$125,3,0) | F10: 4.5 | G10: 85 | H10: =(E10*F10*(G10/100))/10 | I10: =VLOOKUP(B10,'CUSTO OPERAÇÃO'!$P$1:$Q$125,2,0) | J10: =1/H10 | K10: =I10/H10 | L10: =K10*7.5 | M10: =IFERROR(L10/J10,"") | O10: CARRETA AGRÍCOLA | P10: CAÇAMBA 430SC | R10: 400 | S10: 20
A11: MÁQUINAS | B11: PULVERIZADOR- JD4730 | C11: PULVERIZADOR- JD4730 | D11: =IFERROR(__xludf.DUMMYFUNCTION("REGEXREPLACE(B11,""TRATOR - |COLHEITADEIRA |PULVERIZADOR |CAMINHAO-"","""")&"" + ""&REGEXREPLACE(C11,""PLANTADEIRA |PLATAFORMA |DISTRIBUIDOR |PULVERIZADOR "", """")"),"PULVERIZADOR- JD4730 + PULVERIZADOR- JD4730") | E11: =VLOOKUP(C11,'CUSTO OPERAÇÃO'!$P$1:$S$125,3,0) | F11: =VLOOKUP(C11,'CUSTO OPERAÇÃO'!$P$1:$S$125,4,0) | G11: 85 | H11: =(E11*F11*(G11/100))/10 | I11: =VLOOKUP(B11,'CUSTO OPERAÇÃO'!$P$1:$Q$125,2,0) | J11: =1/H11 | K11: =I11/H11 | L11: =K11*7.5 | M11: =IFERROR(L11/J11,"")
A12: MÁQUINAS | B12: AIR TRATOR AT-502B | C12: AIR TRATOR AT-502B | D12: =IFERROR(__xludf.DUMMYFUNCTION("REGEXREPLACE(B12,""TRATOR - |COLHEITADEIRA |PULVERIZADOR |CAMINHAO-"","""")&"" + ""&REGEXREPLACE(C12,""PLANTADEIRA |PLATAFORMA |DISTRIBUIDOR |PULVERIZADOR "", """")"),"AIR TRATOR AT-502B + AIR TRATOR AT-502B") | E12: =VLOOKUP(C12,'CUSTO OPERAÇÃO'!$P$1:$S$125,3,0) | F12: =VLOOKUP(C12,'CUSTO OPERAÇÃO'!$P$1:$S$125,4,0) | G12: 25 | H12: =(E12*F12*(G12/100))/10 | I12: 135 | J12: =1/H12 | K12: =I12/H12 | L12: =K12*7.5 | M12: 5000 | O12: CAMINHÕES | P12: CAMINHÃO-VOLVO FH 540 | Q12: 20
A13: MÁQUINAS | B13: COLHETADEIRA - NH-CR9060 | C13: PLATAFORMA MILHO BRAVA 11 | D13: =IFERROR(__xludf.DUMMYFUNCTION("REGEXREPLACE(B13,""TRATOR - |COLHEITADEIRA |PULVERIZADOR |CAMINHAO-"","""")&"" + ""&REGEXREPLACE(C13,""PLANTADEIRA |PLATAFORMA |DISTRIBUIDOR |PULVERIZADOR "", """")"),"COLHETADEIRA - NH-CR9060 + MILHO BRAVA 11") | E13: =VLOOKUP(C13,'CUSTO OPERAÇÃO'!$P$1:$S$125,3,0) | F13: =VLOOKUP(C13,'CUSTO OPERAÇÃO'!$P$1:$S$125,4,0) | G13: 85 | H13: =(E13*F13*(G13/100))/10 | I13: =VLOOKUP(B13,'CUSTO OPERAÇÃO'!$P$1:$Q$125,2,0) | J13: =1/H13 | K13: =I13/H13 | L13: =K13*7.5 | M13: =IFERROR(L13/J13,"") | O13: CARRETA AGRÍCOLA | P13: TRANSBORDO SANTAL
A14: MÁQUINAS | B14: TRATOR - NH T7.260 | C14: DISTRIBUIDOR JAN 20000 | D14: =IFERROR(__xludf.DUMMYFUNCTION("REGEXREPLACE(B14,""TRATOR - |COLHEITADEIRA |PULVERIZADOR |CAMINHAO-"","""")&"" + ""&REGEXREPLACE(C14,""PLANTADEIRA |PLATAFORMA |DISTRIBUIDOR |PULVERIZADOR "", """")"),"NH T7.260 + JAN 20000") | E14: =VLOOKUP(C14,'CUSTO OPERAÇÃO'!$P$1:$S$125,3,0) | F14: =VLOOKUP(C14,'CUSTO OPERAÇÃO'!$P$1:$S$125,4,0) | G14: 85 | H14: =(E14*F14*(G14/100))/10 | I14: =VLOOKUP(B14,'CUSTO OPERAÇÃO'!$P$1:$Q$125,2,0) | J14: =1/H14 | K14: =I14/H14 | L14: =K14*7.5 | M14: =IFERROR(L14/J14,"") | O14: CARRETA AGRÍCOLA | P14: REBOQUE 3000 KG- FA
A15: MÁQUINAS | B15: TRATOR - NH T8.355 | C15: PLANTADEIRA - JD2122 | D15: =IFERROR(__xludf.DUMMYFUNCTION("REGEXREPLACE(B15,""TRATOR - |COLHEITADEIRA |PULVERIZADOR |CAMINHAO-"","""")&"" + ""&REGEXREPLACE(C15,""PLANTADEIRA |PLATAFORMA |DISTRIBUIDOR |PULVERIZADOR "", """")"),"NH T8.355 + - JD2122") | E15: =VLOOKUP(C15,'CUSTO OPERAÇÃO'!$P$1:$S$125,3,0) | F15: =VLOOKUP(C15,'CUSTO OPERAÇÃO'!$P$1:$S$125,4,0) | G15: 85 | H15: =(E15*F15*(G15/100))/10 | I15: =VLOOKUP(B15,'CUSTO OPERAÇÃO'!$P$1:$Q$125,2,0) | J15: =1/H15 | K15: =I15/H15 | L15: =K15*7.5 | M15: =IFERROR(L15/J15,"") | O15: CARRETA AGRÍCOLA | P15: CARRETO ADUBO 20000
A16: MÁQUINAS | B16: COLHETADEIRA - CASE 2388 | C16: PLATAFORMA CASE 30PES | D16: =IFERROR(__xludf.DUMMYFUNCTION("REGEXREPLACE(B16,""TRATOR - |COLHEITADEIRA |PULVERIZADOR |CAMINHAO-"","""")&"" + ""&REGEXREPLACE(C16,""PLANTADEIRA |PLATAFORMA |DISTRIBUIDOR |PULVERIZADOR "", """")"),"COLHETADEIRA - CASE 2388 + CASE 30PES") | E16: =VLOOKUP(C16,'CUSTO OPERAÇÃO'!$P$1:$S$125,3,0) | F16: =VLOOKUP(C16,'CUSTO OPERAÇÃO'!$P$1:$S$125,4,0) | G16: 85 | H16: =(E16*F16*(G16/100))/10 | I16: =VLOOKUP(B16,'CUSTO OPERAÇÃO'!$P$1:$Q$125,2,0) | J16: =1/H16 | K16: =I16/H16 | L16: =K16*7.5 | M16: =IFERROR(L16/J16,"") | O16: CARRETA AGRÍCOLA | P16: CARRETO ADUBO ESPORA
A17: MÁQUINAS | B17: JACTO UNIPORT 2000 | C17: JACTO UNIPORT 2000 | D17: =IFERROR(__xludf.DUMMYFUNCTION("REGEXREPLACE(B17,""TRATOR - |COLHEITADEIRA |PULVERIZADOR |CAMINHAO-"","""")&"" + ""&REGEXREPLACE(C17,""PLANTADEIRA |PLATAFORMA |DISTRIBUIDOR |PULVERIZADOR "", """")"),"JACTO UNIPORT 2000 + JACTO UNIPORT 2000") | E17: =VLOOKUP(C17,'CUSTO OPERAÇÃO'!$P$1:$S$125,3,0) | F17: =VLOOKUP(C17,'CUSTO OPERAÇÃO'!$P$1:$S$125,4,0) | G17: 85 | H17: =(E17*F17*(G17/100))/10 | I17: =VLOOKUP(B17,'CUSTO OPERAÇÃO'!$P$1:$Q$125,2,0) | J17: =1/H17 | K17: =I17/H17 | L17: =K17*7.5 | M17: =IFERROR(L17/J17,"") | O17: CARRETA AGRÍCOLA | P17: CARRETA PLATAFORMACR7.8
A18: MÁQUINAS | B18: TRATOR - NH T7.260 | C18: PLANTADEIRA CASE 2213 | D18: =IFERROR(__xludf.DUMMYFUNCTION("REGEXREPLACE(B18,""TRATOR - |COLHEITADEIRA |PULVERIZADOR |CAMINHAO-"","""")&"" + ""&REGEXREPLACE(C18,""PLANTADEIRA |PLATAFORMA |DISTRIBUIDOR |PULVERIZADOR "", """")"),"NH T7.260 + CASE 2213") | E18: =VLOOKUP(C18,'CUSTO OPERAÇÃO'!$P$1:$S$125,3,0) | F18: =VLOOKUP(C18,'CUSTO OPERAÇÃO'!$P$1:$S$125,4,0) | G18: 85 | H18: =(E18*F18*(G18/100))/10 | I18: =VLOOKUP(B18,'CUSTO OPERAÇÃO'!$P$1:$Q$125,2,0) | J18: =1/H18 | K18: =I18/H18 | L18: =K18*7.5 | M18: =IFERROR(L18/J18,"") | O18: COLHEDORAS | P18: COLHETADEIRA - NH-CR9060 | Q18: 40
D19: =IFERROR(__xludf.DUMMYFUNCTION("REGEXREPLACE(B19,""TRATOR - |COLHEITADEIRA |PULVERIZADOR |CAMINHAO-"","""")&"" + ""&REGEXREPLACE(C19,""PLANTADEIRA |PLATAFORMA |DISTRIBUIDOR |PULVERIZADOR "", """")")," + ") | E19: =VLOOKUP(C19,'CUSTO OPERAÇÃO'!$P$1:$S$125,3,0) | F19: =VLOOKUP(C19,'CUSTO OPERAÇÃO'!$P$1:$S$125,4,0) | G19: 85 | H19: =(E19*F19*(G19/100))/10 | I19: =VLOOKUP(B19,'CUSTO OPERAÇÃO'!$P$1:$Q$125,2,0) | J19: =1/H19 | K19: =I19/H19 | L19: =K19*7.5 | M19: =IFERROR(L19/J19,"") | O19: COLHEDORAS | P19: COLHETADEIRA - CASE 2388 | Q19: 30
D20: =IFERROR(__xludf.DUMMYFUNCTION("REGEXREPLACE(B20,""TRATOR - |COLHEITADEIRA |PULVERIZADOR |CAMINHAO-"","""")&"" + ""&REGEXREPLACE(C20,""PLANTADEIRA |PLATAFORMA |DISTRIBUIDOR |PULVERIZADOR "", """")")," + ") | E20: =VLOOKUP(C20,'CUSTO OPERAÇÃO'!$P$1:$S$125,3,0) | F20: =VLOOKUP(C20,'CUSTO OPERAÇÃO'!$P$1:$S$125,4,0) | G20: 85 | H20: =(E20*F20*(G20/100))/10 | I20: =VLOOKUP(B20,'CUSTO OPERAÇÃO'!$P$1:$Q$125,2,0) | J20: =1/H20 | K20: =I20/H20 | L20: =K20*7.5 | M20: =IFERROR(L20/J20,"") | O20: COLHEDORAS | P20: COLHEITADEIRA CR 8.90 NEW HOLLAND | Q20: 50
D21: =IFERROR(__xludf.DUMMYFUNCTION("REGEXREPLACE(B21,""TRATOR - |COLHEITADEIRA |PULVERIZADOR |CAMINHAO-"","""")&"" + ""&REGEXREPLACE(C21,""PLANTADEIRA |PLATAFORMA |DISTRIBUIDOR |PULVERIZADOR "", """")")," + ") | E21: =VLOOKUP(C21,'CUSTO OPERAÇÃO'!$P$1:$S$125,3,0) | F21: =VLOOKUP(C21,'CUSTO OPERAÇÃO'!$P$1:$S$125,4,0) | G21: 85 | H21: =(E21*F21*(G21/100))/10 | I21: =VLOOKUP(B21,'CUSTO OPERAÇÃO'!$P$1:$Q$125,2,0) | J21: =1/H21 | K21: =I21/H21 | L21: =K21*7.5 | M21: =IFERROR(L21/J21,"") | O21: COLHEDORAS | P21: COLHETADEIRA CR7.80 | Q21: 40
D22: =IFERROR(__xludf.DUMMYFUNCTION("REGEXREPLACE(B22,""TRATOR - |COLHEITADEIRA |PULVERIZADOR |CAMINHAO-"","""")&"" + ""&REGEXREPLACE(C22,""PLANTADEIRA |PLATAFORMA |DISTRIBUIDOR |PULVERIZADOR "", """")")," + ") | E22: =VLOOKUP(C22,'CUSTO OPERAÇÃO'!$P$1:$S$125,3,0) | F22: =VLOOKUP(C22,'CUSTO OPERAÇÃO'!$P$1:$S$125,4,0) | G22: 85 | H22: =(E22*F22*(G22/100))/10 | I22: =VLOOKUP(B22,'CUSTO OPERAÇÃO'!$P$1:$Q$125,2,0) | J22: =1/H22 | K22: =I22/H22 | L22: =K22*7.5 | M22: =IFERROR(L22/J22,"") | O22: DISTRIBUIDOR FERTILIZANTES | P22: DISTRIBUIDOR BRUTUS 12000 | R22: 6 | S22: 6
D23: =IFERROR(__xludf.DUMMYFUNCTION("REGEXREPLACE(B23,""TRATOR - |COLHEITADEIRA |PULVERIZADOR |CAMINHAO-"","""")&"" + ""&REGEXREPLACE(C23,""PLANTADEIRA |PLATAFORMA |DISTRIBUIDOR |PULVERIZADOR "", """")")," + ") | E23: =VLOOKUP(C23,'CUSTO OPERAÇÃO'!$P$1:$S$125,3,0) | F23: =VLOOKUP(C23,'CUSTO OPERAÇÃO'!$P$1:$S$125,4,0) | G23: 85 | H23: =(E23*F23*(G23/100))/10 | I23: =VLOOKUP(B23,'CUSTO OPERAÇÃO'!$P$1:$Q$125,2,0) | J23: =1/H23 | K23: =I23/H23 | L23: =K23*7.5 | M23: =IFERROR(L23/J23,"") | O23: DISTRIBUIDOR FERTILIZANTES | P23: DISTRIBUIDOR ADUBADORA HERCULES 10000 | R23: 30 | S23: 8
D24: =IFERROR(__xludf.DUMMYFUNCTION("REGEXREPLACE(B24,""TRATOR - |COLHEITADEIRA |PULVERIZADOR |CAMINHAO-"","""")&"" + ""&REGEXREPLACE(C24,""PLANTADEIRA |PLATAFORMA |DISTRIBUIDOR |PULVERIZADOR "", """")")," + ") | E24: =VLOOKUP(C24,'CUSTO OPERAÇÃO'!$P$1:$S$125,3,0) | F24: =VLOOKUP(C24,'CUSTO OPERAÇÃO'!$P$1:$S$125,4,0) | G24: 85 | H24: =(E24*F24*(G24/100))/10 | I24: =VLOOKUP(B24,'CUSTO OPERAÇÃO'!$P$1:$Q$125,2,0) | J24: =1/H24 | K24: =I24/H24 | L24: =K24*7.5 | M24: =IFERROR(L24/J24,"") | O24: DISTRIBUIDOR FERTILIZANTES | P24: DISTRIBUIDOR JAN 20000 | R24: 15 | S24: 8
D25: =IFERROR(__xludf.DUMMYFUNCTION("REGEXREPLACE(B25,""TRATOR - |COLHEITADEIRA |PULVERIZADOR |CAMINHAO-"","""")&"" + ""&REGEXREPLACE(C25,""PLANTADEIRA |PLATAFORMA |DISTRIBUIDOR |PULVERIZADOR "", """")")," + ") | E25: =VLOOKUP(C25,'CUSTO OPERAÇÃO'!$P$1:$S$125,3,0) | F25: =VLOOKUP(C25,'CUSTO OPERAÇÃO'!$P$1:$S$125,4,0) | G25: 85 | H25: =(E25*F25*(G25/100))/10 | I25: =VLOOKUP(B25,'CUSTO OPERAÇÃO'!$P$1:$Q$125,2,0) | J25: =1/H25 | K25: =I25/H25 | L25: =K25*7.5 | M25: =IFERROR(L25/J25,"") | O25: DISTRIBUIDOR FERTILIZANTES | P25: KAMAQ 6000 | R25: 7 | S25: 8
D26: =IFERROR(__xludf.DUMMYFUNCTION("REGEXREPLACE(B26,""TRATOR - |COLHEITADEIRA |PULVERIZADOR |CAMINHAO-"","""")&"" + ""&REGEXREPLACE(C26,""PLANTADEIRA |PLATAFORMA |DISTRIBUIDOR |PULVERIZADOR "", """")")," + ") | E26: =VLOOKUP(C26,'CUSTO OPERAÇÃO'!$P$1:$S$125,3,0) | F26: =VLOOKUP(C26,'CUSTO OPERAÇÃO'!$P$1:$S$125,4,0) | G26: 85 | H26: =(E26*F26*(G26/100))/10 | I26: =VLOOKUP(B26,'CUSTO OPERAÇÃO'!$P$1:$Q$125,2,0) | J26: =1/H26 | K26: =I26/H26 | L26: =K26*7.5 | M26: =IFERROR(L26/J26,"") | O26: EQUIPAMENTOS | P26: BALANÇA CAR. 120/240T/H
D27: =IFERROR(__xludf.DUMMYFUNCTION("REGEXREPLACE(B27,""TRATOR - |COLHEITADEIRA |PULVERIZADOR |CAMINHAO-"","""")&"" + ""&REGEXREPLACE(C27,""PLANTADEIRA |PLATAFORMA |DISTRIBUIDOR |PULVERIZADOR "", """")")," + ") | E27: =VLOOKUP(C27,'CUSTO OPERAÇÃO'!$P$1:$S$125,3,0) | F27: =VLOOKUP(C27,'CUSTO OPERAÇÃO'!$P$1:$S$125,4,0) | G27: 85 | H27: =(E27*F27*(G27/100))/10 | I27: =VLOOKUP(B27,'CUSTO OPERAÇÃO'!$P$1:$Q$125,2,0) | J27: =1/H27 | K27: =I27/H27 | L27: =K27*7.5 | M27: =IFERROR(L27/J27,"") | O27: EQUIPAMENTOS | P27: GUINDASTE HIDRAULICO GRM 14.000
D28: =IFERROR(__xludf.DUMMYFUNCTION("REGEXREPLACE(B28,""TRATOR - |COLHEITADEIRA |PULVERIZADOR |CAMINHAO-"","""")&"" + ""&REGEXREPLACE(C28,""PLANTADEIRA |PLATAFORMA |DISTRIBUIDOR |PULVERIZADOR "", """")")," + ") | E28: =VLOOKUP(C28,'CUSTO OPERAÇÃO'!$P$1:$S$125,3,0) | F28: =VLOOKUP(C28,'CUSTO OPERAÇÃO'!$P$1:$S$125,4,0) | G28: 85 | H28: =(E28*F28*(G28/100))/10 | I28: =VLOOKUP(B28,'CUSTO OPERAÇÃO'!$P$1:$Q$125,2,0) | J28: =1/H28 | K28: =I28/H28 | L28: =K28*7.5 | M28: =IFERROR(L28/J28,"") | O28: EQUIPAMENTOS | P28: EQUIPAMENTOS
D29: =IFERROR(__xludf.DUMMYFUNCTION("REGEXREPLACE(B29,""TRATOR - |COLHEITADEIRA |PULVERIZADOR |CAMINHAO-"","""")&"" + ""&REGEXREPLACE(C29,""PLANTADEIRA |PLATAFORMA |DISTRIBUIDOR |PULVERIZADOR "", """")")," + ") | E29: =VLOOKUP(C29,'CUSTO OPERAÇÃO'!$P$1:$S$125,3,0) | F29: =VLOOKUP(C29,'CUSTO OPERAÇÃO'!$P$1:$S$125,4,0) | G29: 85 | H29: =(E29*F29*(G29/100))/10 | I29: =VLOOKUP(B29,'CUSTO OPERAÇÃO'!$P$1:$Q$125,2,0) | J29: =1/H29 | K29: =I29/H29 | L29: =K29*7.5 | M29: =IFERROR(L29/J29,"") | O29: EQUIPAMENTOS | P29: HANGAR
D30: =IFERROR(__xludf.DUMMYFUNCTION("REGEXREPLACE(B30,""TRATOR - |COLHEITADEIRA |PULVERIZADOR |CAMINHAO-"","""")&"" + ""&REGEXREPLACE(C30,""PLANTADEIRA |PLATAFORMA |DISTRIBUIDOR |PULVERIZADOR "", """")")," + ") | E30: =VLOOKUP(C30,'CUSTO OPERAÇÃO'!$P$1:$S$125,3,0) | F30: =VLOOKUP(C30,'CUSTO OPERAÇÃO'!$P$1:$S$125,4,0) | G30: 85 | H30: =(E30*F30*(G30/100))/10 | I30: =VLOOKUP(B30,'CUSTO OPERAÇÃO'!$P$1:$Q$125,2,0) | J30: =1/H30 | K30: =I30/H30 | L30: =K30*7.5 | M30: =IFERROR(L30/J30,"") | O30: EQUIPAMENTOS | P30: GERADOR GMG 500 KVA
O31: EQUIPAMENTOS | P31: LARANJA
O32: EQUIPAMENTOS | P32: IRRIGAÇÃO LARANJA
O33: EQUIPAMENTOS | P33: BALANÇA DE FLUXO
O34: EQUIPAMENTOS | P34: LÂMINA TRASEIRA STARA 5000
O35: EQUIPAMENTOS | P35: MIAC DOBLE IV
O36: EQUIPAMENTOS | P36: EMBUTIDORA SILO BOLSA - ESPORA
O37: EQUIPAMENTOS | P37: EXTRATORA SILO BOLSA
O38: EQUIPAMENTOS | P38: GRUPO GERADOR CAT 130KWA
O39: EQUIPAMENTOS | P39: GRUPO GERADOR CUMINS 130KWA
O40: EQUIPAMENTOS | P40: PRÉ-LIMPEZA 40 TON
...

Sheet DRE ORÇADA
B1: SOJA - 02 COQ | J1: SOJA - 02 COQ | L1: SOJA - 02 COQ | N1: SOJA - 02 COQ | P1: SOJA - 02 COQ
A2: ORÇAMENTO SAFRA 2026/2027 | B2: ='PORTIFÓLIO'!$J$3 | D2: ='PORTIFÓLIO'!$K$3 | F2: ='PORTIFÓLIO'!$L$3 | H2: ='PORTIFÓLIO'!$M$3 | J2: ='PORTIFÓLIO'!$N$3 | L2: ='PORTIFÓLIO'!$O$3 | N2: ='PORTIFÓLIO'!$P$3 | P2: ='PORTIFÓLIO'!$Q$3 | R2: TOTAL
C3: R$/ Ha | E3: R$/ Ha | G3: R$/ Ha | I3: R$/ Ha | K3: R$/ Ha | M3: R$/ Ha | O3: R$/ Ha | Q3: R$/ Ha | S3: R$/ Ha
A4: ÁREA | B4: =SUMIF('ÁREA PLANTIO'!$C$2:$C$30,"*"&B2&"*",'ÁREA PLANTIO'!$E$2:$E$30)+SUMIF('ÁREA PLANTIO'!$H$2:$H$30,"*"&B2&"*",'ÁREA PLANTIO'!$E$2:$E$30) | D4: =SUMIF('ÁREA PLANTIO'!$C$2:$C$30,"*"&D2&"*",'ÁREA PLANTIO'!$E$2:$E$30)+SUMIF('ÁREA PLANTIO'!$H$2:$H$30,"*"&D2&"*",'ÁREA PLANTIO'!$E$2:$E$30) | F4: =SUMIF('ÁREA PLANTIO'!$C$2:$C$30,"*"&F2&"*",'ÁREA PLANTIO'!$E$2:$E$30)+SUMIF('ÁREA PLANTIO'!$H$2:$H$30,"*"&F2&"*",'ÁREA PLANTIO'!$E$2:$E$30) | H4: =SUMIF('ÁREA PLANTIO'!$C$2:$C$30,"*"&H2&"*",'ÁREA PLANTIO'!$E$2:$E$30)+SUMIF('ÁREA PLANTIO'!$H$2:$H$30,"*"&H2&"*",'ÁREA PLANTIO'!$E$2:$E$30) | J4: =SUMIF('ÁREA PLANTIO'!$C$2:$C$30,"*"&J2&"*",'ÁREA PLANTIO'!$E$2:$E$30)+SUMIF('ÁREA PLANTIO'!$H$2:$H$30,"*"&J2&"*",'ÁREA PLANTIO'!$E$2:$E$30) | L4: =SUMIF('ÁREA PLANTIO'!$C$2:$C$30,"*"&L2&"*",'ÁREA PLANTIO'!$E$2:$E$30)+SUMIF('ÁREA PLANTIO'!$H$2:$H$30,"*"&L2&"*",'ÁREA PLANTIO'!$E$2:$E$30) | N4: =SUMIF('ÁREA PLANTIO'!$C$2:$C$30,"*"&N2&"*",'ÁREA PLANTIO'!$E$2:$E$30)+SUMIF('ÁREA PLANTIO'!$H$2:$H$30,"*"&N2&"*",'ÁREA PLANTIO'!$E$2:$E$30) | P4: =SUMIF('ÁREA PLANTIO'!$C$2:$C$30,"*"&P2&"*",'ÁREA PLANTIO'!$E$2:$E$30)+SUMIF('ÁREA PLANTIO'!$H$2:$H$30,"*"&P2&"*",'ÁREA PLANTIO'!$E$2:$E$30) | R4: =SUM(P4,N4,L4,J4,B4,D4,F4,H4)
A5: PRODUÇÃO TOTAL | B5: =SUMIF('ÁREA PLANTIO'!$C$2:$C$30,"*"&B2&"*",'ÁREA PLANTIO'!$F$2:$F$30)+SUMIF('ÁREA PLANTIO'!$H$2:$H$30,"*"&B2&"*",'ÁREA PLANTIO'!$J$2:$J$30) | D5: =SUMIF('ÁREA PLANTIO'!$C$2:$C$30,"*"&D2&"*",'ÁREA PLANTIO'!$F$2:$F$30)+SUMIF('ÁREA PLANTIO'!$H$2:$H$30,"*"&D2&"*",'ÁREA PLANTIO'!$J$2:$J$30) | F5: =SUMIF('ÁREA PLANTIO'!$C$2:$C$30,"*"&F2&"*",'ÁREA PLANTIO'!$F$2:$F$30)+SUMIF('ÁREA PLANTIO'!$H$2:$H$30,"*"&F2&"*",'ÁREA PLANTIO'!$J$2:$J$30) | H5: =SUMIF('ÁREA PLANTIO'!$C$2:$C$30,"*"&H2&"*",'ÁREA PLANTIO'!$F$2:$F$30)+SUMIF('ÁREA PLANTIO'!$H$2:$H$30,"*"&H2&"*",'ÁREA PLANTIO'!$J$2:$J$30) | J5: =SUMIF('ÁREA PLANTIO'!$C$2:$C$30,"*"&J2&"*",'ÁREA PLANTIO'!$F$2:$F$30)+SUMIF('ÁREA PLANTIO'!$H$2:$H$30,"*"&J2&"*",'ÁREA PLANTIO'!$J$2:$J$30) | L5: =SUMIF('ÁREA PLANTIO'!$C$2:$C$30,"*"&L2&"*",'ÁREA PLANTIO'!$F$2:$F$30)+SUMIF('ÁREA PLANTIO'!$H$2:$H$30,"*"&L2&"*",'ÁREA PLANTIO'!$J$2:$J$30) | N5: =SUMIF('ÁREA PLANTIO'!$C$2:$C$30,"*"&N2&"*",'ÁREA PLANTIO'!$F$2:$F$30)+SUMIF('ÁREA PLANTIO'!$H$2:$H$30,"*"&N2&"*",'ÁREA PLANTIO'!$J$2:$J$30) | P5: =SUMIF('ÁREA PLANTIO'!$C$2:$C$30,"*"&P2&"*",'ÁREA PLANTIO'!$F$2:$F$30)+SUMIF('ÁREA PLANTIO'!$H$2:$H$30,"*"&P2&"*",'ÁREA PLANTIO'!$J$2:$J$30)
A6: PRODUÇÃO P/HA | B6: =B5/B4 | D6: =IFERROR(D5/D4,"") | F6: =IFERROR(F5/F4,"") | H6: =IFERROR(H5/H4,"") | J6: =IFERROR(J5/J4,"") | L6: =IFERROR(L5/L4,"") | N6: =IFERROR(N5/N4,"") | P6: =IFERROR(P5/P4,"")
A7: PREÇO MÉDIO | B7: 200 | D7: 110 | F7: 110 | H7: 60 | J7: 48 | L7: 60 | N7: 110 | P7: 110 | S7: =R7/$R$4
A8: RECEITA ARRENDAMENTO | S8: =R8/$R$4
A9: RECEITA BRUTA | B9: =B5*B7 | C9: =IFERROR(B9/B4,"") | D9: =D5*D7 | E9: =IFERROR(D9/D4,"") | F9: =F5*F7 | G9: =IFERROR(F9/F4,"") | H9: =H5*H7 | I9: =IFERROR(H9/H4,"") | J9: =J5*J7 | K9: =IFERROR(J9/J4,"") | L9: =L5*L7 | M9: =IFERROR(L9/L4,"") | N9: =N5*N7 | O9: =IFERROR(N9/N4,"") | P9: =P5*P7 | Q9: =IFERROR(P9/P4,"") | R9: =SUM(P9,N9,L9,J9,H9,D9,B9) | S9: =IFERROR(R9/R4,"")
A10: SAÍDAS TOTAIS | B10: =SUM(B11,B465,B546,B555,B557) | C10: =B10/B4 | D10: =SUM(D11,D465,D546,D555,D557) | E10: =IFERROR(D10/D4,"") | F10: =SUM(F11,F465,F546,F555,F557) | G10: =IFERROR(F10/F4,"") | H10: =SUM(H11,H465,H546,H555,H557) | I10: =IFERROR(H10/H4,"") | J10: =SUM(J11,J465,J546,J555,J557) | K10: =IFERROR(J10/J4,"") | L10: =SUM(L11,L465,L546,L555,L557) | M10: =IFERROR(L10/L4,"") | N10: =SUM(N11,N465,N546,N555,N557) | O10: =IFERROR(N10/N4,"") | P10: =SUM(P11,P465,P546,P555,P557) | Q10: =IFERROR(P10/P4,"") | R10: =SUM(P10,N10,L10,J10,H10,D10,B10) | S10: =R10/$R$4
A11: CUSTOS DIRETOS | B11: =SUM(B12,B421,B458,B459,B460,B461,B462) | C11: =B11/$B$4 | D11: =SUM(D12,D421,D458,D459,D460,D461,D462) | E11: =D11/$D$4 | F11: =SUM(F12,F421,F458,F459,F460,F461,F462) | G11: =F11/$F$4 | H11: =SUM(H12,H421,H458,H459,H460,H461,H462) | I11: =IFERROR(H11/$H$4,"") | J11: =SUM(J12,J421,J458,J459,J460,J461,J462) | K11: =J11/$J$4 | L11: =SUM(L12,L421,L458,L459,L460,L461,L462) | M11: 4221 | N11: =SUM(N12,N421,N458,N459,N460,N461,N462) | O11: 4221 | P11: =SUM(P12,P421,P458,P459,P460,P461,P462) | Q11: 4221 | R11: =SUM(P11,N11,L11,J11,H11,D11,B11) | S11: =R11/$R$4
A12: CUSTOS INSUMOS | B12: =B13+B32+B104+B175+B256+B293+B322+B340 | C12: =IFERROR(B12/$B$4,"") | D12: =D13+D32+D104+D175+D256+D293+D322+D340 | E12: =IFERROR(D12/$D$4,"") | F12: =F13+F32+F104+F175+F256+F293+F322+F340 | G12: =IFERROR(F12/$F$4,"") | H12: =H13+H32+H104+H175+H256+H293+H322+H340 | I12: =IFERROR(H12/$H$4,"") | J12: =J13+J32+J104+J175+J256+J293+J322+J340 | K12: =IFERROR(J12/$J$4,"") | L12: =L13+L32+L104+L175+L256+L293+L322+L340 | M12: =IFERROR(L12/$L$4,"") | N12: =N13+N32+N104+N175+N256+N293+N322+N340 | O12: =IFERROR(N12/$N$4,"") | P12: =P13+P32+P104+P175+P256+P293+P322+P340 | Q12: =IFERROR(P12/$P$4,"") | R12: =SUM(P12,N12,L12,J12,H12,D12,B12) | S12: =IFERROR(R12/$R$4,"")
